Workbook

Sheet Hoja1
A1: Entidad | B1: Fuente
A2: PRESENTE | B2: reglamento de crédito
A3: Cotrafa | B3: https://www.cotrafa.com.co/portafolio-de-credito
A4: Banco Davivienda | B4: https://www.davivienda.com/wps/portal/personas/nuevo/personas/tasasytarifas/!ut/p/z1/jZBNb4JAEIZ_DdedYReHtbdtg7akKsZY6F4MGIokLGsAy98vml6a1I1zm-R55uMFDRnoNv-uq3yobZs3U_-p6RAs3979iBIVCeKoXgPiUn74GCKkN0DIbbCOn_lqt5gLVCvcvaj5xt8sOehHfLxTCh_zHYB2j09B3xDXBy4AF-Ev4FgSg64Lw8ajYcgE0fUwpJBLCmh2zVi1hZAV6K78KruyY5duiv40DOf-yUMPx3FklbVVU7KjNR7-p5xsP0D2l4Sz2e8zrBOTyv4Hlats8Q!!/dz/d5/L2dBISEvZ0FBIS9nQSEh/
A5: Banco de Occidente | B5: https://www.bancodeoccidente.com.co/wps/wcm/connect/banco-de-occidente/c24390e8-b984-44de-b427-e59ff152a22c/tasas-personas-2022.pdf?MOD=AJPERES&CVID=o7LgirB
A6: Confiar | B6: https://www.confiar.coop/personas/productos/credito/credito-para-comprar-vivienda/
A7: Banco Caja Social S.A. | B7: https://www.bancocajasocial.com/portalserver/tasas-precios-y-comisiones | I7: Tasas-Credito-Vivienda.pdf
A8: Bancolombia | B8: https://www.bancolombia.com/personas/creditos/consumo/
A9: AV Villas | B9: https://www.avvillas.com.co/wps/portal/avvillas/banco/banca-personal/tasas-tarifas-personas/
A10: Scotiabank Colpatria S.A. | B10: https://www.scotiabankcolpatria.com/tasas-y-tarifas
A11: Itaú | B11: https://banco.itau.co/web/personas/informacion-de-interes/tasas-y-tarifas
A12: Banco de Bogotá | B12: https://www.bancodebogota.com/wps/portal/banco-de-bogota/bogota/productos/para-ti/tasas-y-tarifas/tasas-2023
A13: Cooperativa Financiera de Antioquia | B13: https://www.cfa.com.co/tasas-de-colocacion/
A14: JFK Cooperativa Financiera | B14: https://www.jfk.com.co/credito/tasas
A15: Pichincha | B15: https://www.bancopichincha.com.co/web/corporativo/tasas-y-tarifas
A16: Banco Popular | B16: https://www.bancopopular.com.co/wps/portal/bancopopular/inicio/informacion-interes/tasas
A17: Banco Serfinanza S.A. | B17: https://bancoserfinanza.com/wp-content/uploads/2023/01/TASAS.pdf
A18: Financiera Juriscoop C.F. | B18: https://financierajuriscoop.com.co/tasas-y-tarifas
A19: Coopetraban | B19: https://www.coopetraban.com.co/tasas-de-interes-para-credito/ | K19: =EFFECT(1.05%,12) -> 0.010550679

Sheet Cartera Créditos - E (4)
B1: INFORME DE TASAS DE CARTELERA POR MODALIDAD DE CRÉDITO
B2: Tasas efectivas anuales
D3: =TODAY() -> 46043
A5: NOMBRE ENTIDAD | B5: VIVIENDA en Pesos (T.E.A.) | F5: CONSUMO (T.E.A.)
B6: VIS | D6: NO VIS | F6: LIBRE INVERSION | H6: VEHICULO | J6: TARJETA | L6: COMPRA CARTERA | O6: CREDITOS ROTATIVOS | R6: =EFFECT(1.25%*12,12) -> 0.16075452
A7: Entidad Bancaria | B7: Tasa | C7: Ranking | D7: Tasa | E7: Ranking | F7: Tasa | G7: Ranking | H7: Tasa | I7: Ranking | J7: Tasa | K7: Ranking | L7: Tasa desde | M7: Tasa hasta | N7: Ranking | O7: Tasa | P7: Ranking
A8: PRESENTE | B8: 11.01 | C8: =IFERROR(_xlfn.RANK.EQ(B8,$B$8:$B$18,1),0) -> 2 | D8: 11.83 | E8: =IFERROR(_xlfn.RANK.EQ(D8,$D$8:$D$18,1),0) -> 1 | F8: 28.02 | G8: =IFERROR(_xlfn.RANK.EQ(F8,$F$8:$F$18,1),0) -> 9 | H8: 15.95 | I8: =IFERROR(_xlfn.RANK.EQ(H8,$H$8:$H$18,1),0) -> 3 | J8: 29.93 | K8: =IFERROR(_xlfn.RANK.EQ(J8,$J$8:$J$18,1),0) -> 11 | L8: 15.52 | N8: =IFERROR(_xlfn.RANK.EQ(L8,$L$8:$L$18,1),0) -> 6 | O8: 27.87 | P8: =IFERROR(_xlfn.RANK.EQ(O8,$O$8:$O$18,1),0) -> 6 | R8: =VLOOKUP(A31,Hoja1!A2:B18,2,0) -> reglamento de crédito
A9: Banco Davivienda | B9: 12.6 | C9: =IFERROR(_xlfn.RANK.EQ(B9,$B$8:$B$18,1),0) -> 5 | D9: 12.5 | E9: =IFERROR(_xlfn.RANK.EQ(D9,$D$8:$D$18,1),0) -> 4 | F9: 21.55 | G9: =IFERROR(_xlfn.RANK.EQ(F9,$F$8:$F$18,1),0) -> 6 | H9: 12.01 | I9: =IFERROR(_xlfn.RANK.EQ(H9,$H$8:$H$18,1),0) -> 1 | J9: 28.93 | K9: =IFERROR(_xlfn.RANK.EQ(J9,$J$8:$J$18,1),0) -> 3 | L9: 15.38 | M9: N/A | N9: =IFERROR(_xlfn.RANK.EQ(L9,$L$8:$L$18,1),0) -> 4 | O9: 27.87 | P9: =IFERROR(_xlfn.RANK.EQ(O9,$O$8:$O$18,1),0) -> 6 | R9: =VLOOKUP(A9,Hoja1!$A$3:$B$19,2,0) -> https://www.davivienda.com/wps/portal/personas/nuevo/personas/tasasytarifas/!ut/p/z1/jZBNb4JAEIZ_DdedYReHtbdtg7akKsZY6F4MGIokLGsAy98vml6a1I1zm-R55uMFDRnoNv-uq3yobZs3U_-p6RAs3979iBIVCeKoXgPiUn74GCKkN0DIbbCOn_lqt5gLVCvcvaj5xt8sOehHfLxTCh_zHYB2j09B3xDXBy4AF-Ev4FgSg64Lw8ajYcgE0fUwpJBLCmh2zVi1hZAV6K78KruyY5duiv40DOf-yUMPx3FklbVVU7KjNR7-p5xsP0D2l4Sz2e8zrBOTyv4Hlats8Q!!/dz/d5/L2dBISEvZ0FBIS9nQSEh/
A10: Banco de Occidente | B10: 10.76 | C10: =IFERROR(_xlfn.RANK.EQ(B10,$B$8:$B$18,1),0) -> 1 | D10: 16.01 | E10: =IFERROR(_xlfn.RANK.EQ(D10,$D$8:$D$18,1),0) -> 7 | F10: 18.02 | G10: =IFERROR(_xlfn.RANK.EQ(F10,$F$8:$F$18,1),0) -> 4 | H10: 16.14 | I10: =IFERROR(_xlfn.RANK.EQ(H10,$H$8:$H$18,1),0) -> 5 | J10: 29.06 | K10: =IFERROR(_xlfn.RANK.EQ(J10,$J$8:$J$18,1),0) -> 6 | L10: 15.12 | M10: 24.86 | N10: =IFERROR(_xlfn.RANK.EQ(L10,$L$8:$L$18,1),0) -> 2 | O10: 18.02 | P10: =IFERROR(_xlfn.RANK.EQ(O10,$O$8:$O$18,1),0) -> 1 | R10: =VLOOKUP(A10,Hoja1!$A$3:$B$19,2,0) -> https://www.bancodeoccidente.com.co/wps/wcm/connect/banco-de-occidente/c24390e8-b984-44de-b427-e59ff152a22c/tasas-personas-2022.pdf?MOD=AJPERES&CVID=o7LgirB
A11: Banco Caja Social S.A. | B11: 14.85 | C11: =IFERROR(_xlfn.RANK.EQ(B11,$B$8:$B$18,1),0) -> 8 | D11: 16.1 | E11: =IFERROR(_xlfn.RANK.EQ(D11,$D$8:$D$18,1),0) -> 8 | F11: 13.1 | G11: =IFERROR(_xlfn.RANK.EQ(F11,$F$8:$F$18,1),0) -> 1 | H11: 16.07 | I11: =IFERROR(_xlfn.RANK.EQ(H11,$H$8:$H$18,1),0) -> 4 | J11: 27.12 | K11: =IFERROR(_xlfn.RANK.EQ(J11,$J$8:$J$18,1),0) -> 2 | L11: 15.39 | M11: N/A | N11: =IFERROR(_xlfn.RANK.EQ(L11,$L$8:$L$18,1),0) -> 5 | O11: 26.08 | P11: =IFERROR(_xlfn.RANK.EQ(O11,$O$8:$O$18,1),0) -> 3 | R11: =VLOOKUP(A11,Hoja1!$A$3:$B$19,2,0) -> https://www.bancocajasocial.com/portalserver/tasas-precios-y-comisiones
A12: Bancolombia | B12: 12 | C12: =IFERROR(_xlfn.RANK.EQ(B12,$B$8:$B$18,1),0) -> 3 | D12: 12 | E12: =IFERROR(_xlfn.RANK.EQ(D12,$D$8:$D$18,1),0) -> 2 | F12: 19.55 | G12: =IFERROR(_xlfn.RANK.EQ(F12,$F$8:$F$18,1),0) -> 5 | H12: 15.66 | I12: =IFERROR(_xlfn.RANK.EQ(H12,$H$8:$H$18,1),0) -> 2 | J12: 26.99 | K12: =IFERROR(_xlfn.RANK.EQ(J12,$J$8:$J$18,1),0) -> 1 | L12: 13.08 | M12: 24.36 | N12: =IFERROR(_xlfn.RANK.EQ(L12,$L$8:$L$18,1),0) -> 1 | O12: 26.38 | P12: =IFERROR(_xlfn.RANK.EQ(O12,$O$8:$O$18,1),0) -> 4 | R12: =VLOOKUP(A12,Hoja1!$A$3:$B$19,2,0) -> https://www.bancolombia.com/personas/creditos/consumo/
A13: AV Villas | B13: 13.8 | C13: =IFERROR(_xlfn.RANK.EQ(B13,$B$8:$B$18,1),0) -> 7 | D13: 15.1 | E13: =IFERROR(_xlfn.RANK.EQ(D13,$D$8:$D$18,1),0) -> 6 | F13: 17.6 | G13: =IFERROR(_xlfn.RANK.EQ(F13,$F$8:$F$18,1),0) -> 3 | H13: N/A | I13: =IFERROR(_xlfn.RANK.EQ(H13,$H$8:$H$18,1),0) -> 0 | J13: 28.95 | K13: =IFERROR(_xlfn.RANK.EQ(J13,$J$8:$J$18,1),0) -> 5 | L13: 15.2 | M13: 24.36 | N13: =IFERROR(_xlfn.RANK.EQ(L13,$L$8:$L$18,1),0) -> 3 | O13: N/A | P13: =IFERROR(_xlfn.RANK.EQ(O13,$O$8:$O$18,1),0) -> 0 | R13: =VLOOKUP(A13,Hoja1!$A$3:$B$19,2,0) -> https://www.avvillas.com.co/wps/portal/avvillas/banco/banca-personal/tasas-tarifas-personas/
A14: Scotiabank Colpatria S.A. | B14: 12.35 | C14: =IFERROR(_xlfn.RANK.EQ(B14,$B$8:$B$18,1),0) -> 4 | D14: 12.45 | E14: =IFERROR(_xlfn.RANK.EQ(D14,$D$8:$D$18,1),0) -> 3 | F14: N/A | G14: =IFERROR(_xlfn.RANK.EQ(F14,$F$8:$F$18,1),0) -> 0 | H14: N/A | I14: =IFERROR(_xlfn.RANK.EQ(H14,$H$8:$H$18,1),0) -> 0 | J14: 29.18 | K14: =IFERROR(_xlfn.RANK.EQ(J14,$J$8:$J$18,1),0) -> 7 | L14: N/A | M14: N/A | N14: =IFERROR(_xlfn.RANK.EQ(L14,$L$8:$L$18,1),0) -> 0 | O14: 28.16 | P14: =IFERROR(_xlfn.RANK.EQ(O14,$O$8:$O$18,1),0) -> 9 | R14: =VLOOKUP(A14,Hoja1!$A$3:$B$19,2,0) -> https://www.scotiabankcolpatria.com/tasas-y-tarifas
A15: Itaú | B15: 13.14 | C15: =IFERROR(_xlfn.RANK.EQ(B15,$B$8:$B$18,1),0) -> 6 | D15: 13.46 | E15: =IFERROR(_xlfn.RANK.EQ(D15,$D$8:$D$18,1),0) -> 5 | F15: 21.69 | G15: =IFERROR(_xlfn.RANK.EQ(F15,$F$8:$F$18,1),0) -> 7 | H15: 21.69 | I15: =IFERROR(_xlfn.RANK.EQ(H15,$H$8:$H$18,1),0) -> 6 | J15: 29.18 | K15: =IFERROR(_xlfn.RANK.EQ(J15,$J$8:$J$18,1),0) -> 7 | L15: 20.98 | M15: N/A | N15: =IFERROR(_xlfn.RANK.EQ(L15,$L$8:$L$18,1),0) -> 8 | O15: 27.57 | P15: =IFERROR(_xlfn.RANK.EQ(O15,$O$8:$O$18,1),0) -> 5 | R15: =VLOOKUP(A15,Hoja1!$A$3:$B$19,2,0) -> https://banco.itau.co/web/personas/informacion-de-interes/tasas-y-tarifas
A16: Banco de Bogotá | B16: 15.7 | C16: =IFERROR(_xlfn.RANK.EQ(B16,$B$8:$B$18,1),0) -> 9 | D16: 17.4 | E16: =IFERROR(_xlfn.RANK.EQ(D16,$D$8:$D$18,1),0) -> 9 | F16: 16.35 | G16: =IFERROR(_xlfn.RANK.EQ(F16,$F$8:$F$18,1),0) -> 2 | H16: 22.71 | I16: =IFERROR(_xlfn.RANK.EQ(H16,$H$8:$H$18,1),0) -> 8 | J16: 29.18 | K16: =IFERROR(_xlfn.RANK.EQ(J16,$J$8:$J$18,1),0) -> 7 | L16: 24.33 | M16: N/A | N16: =IFERROR(_xlfn.RANK.EQ(L16,$L$8:$L$18,1),0) -> 9 | O16: 28.07 | P16: =IFERROR(_xlfn.RANK.EQ(O16,$O$8:$O$18,1),0) -> 8 | R16: =VLOOKUP(A16,Hoja1!$A$3:$B$19,2,0) -> https://www.bancodebogota.com/wps/portal/banco-de-bogota/bogota/productos/para-ti/tasas-y-tarifas/tasas-2023
A17: Banco Serfinanza S.A. | B17: N/A | C17: =IFERROR(_xlfn.RANK.EQ(B17,$B$8:$B$18,1),0) -> 0 | D17: N/A | E17: =IFERROR(_xlfn.RANK.EQ(D17,$D$8:$D$18,1),0) -> 0 | F17: 25.19 | G17: =IFERROR(_xlfn.RANK.EQ(F17,$F$8:$F$18,1),0) -> 8 | H17: 22.28 | I17: =IFERROR(_xlfn.RANK.EQ(H17,$H$8:$H$18,1),0) -> 7 | J17: 28.93 | K17: =IFERROR(_xlfn.RANK.EQ(J17,$J$8:$J$18,1),0) -> 3 | L17: 20.84 | M17: N/A | N17: =IFERROR(_xlfn.RANK.EQ(L17,$L$8:$L$18,1),0) -> 7 | O17: 23.73 | P17: =IFERROR(_xlfn.RANK.EQ(O17,$O$8:$O$18,1),0) -> 2 | R17: https://bancoserfinanza.com/servicio-al-cliente/tasas/
A18: Banco Popular | B18: 17.05 | C18: =IFERROR(_xlfn.RANK.EQ(B18,$B$8:$B$18,1),0) -> 10 | D18: 17.55 | E18: =IFERROR(_xlfn.RANK.EQ(D18,$D$8:$D$18,1),0) -> 10 | F18: 28.12 | G18: =IFERROR(_xlfn.RANK.EQ(F18,$F$8:$F$18,1),0) -> 10 | H18: N/A | I18: =IFERROR(_xlfn.RANK.EQ(H18,$H$8:$H$18,1),0) -> 0 | J18: 29.18 | K18: =IFERROR(_xlfn.RANK.EQ(J18,$J$8:$J$18,1),0) -> 7 | L18: 28.12 | M18: N/A | N18: =IFERROR(_xlfn.RANK.EQ(L18,$L$8:$L$18,1),0) -> 10 | O18: N/A | P18: =IFERROR(_xlfn.RANK.EQ(O18,$O$8:$O$18,1),0) -> 0 | R18: =VLOOKUP(A18,Hoja1!$A$3:$B$19,2,0) -> https://www.bancopopular.com.co/wps/portal/bancopopular/inicio/informacion-interes/tasas
A19: Cooperativas Financieras | B19: Tasa | C19: Ranking | D19: Tasa | E19: Ranking | F19: Tasa | G19: Ranking | H19: Tasa | I19: Ranking | J19: Tasa | K19: Ranking | L19: Tasa | N19: Ranking | O19: Tasa | P19: Ranking
A20: PRESENTE | B20: =B8 -> 11.01 | C20: =IFERROR(_xlfn.RANK.EQ(B20,$B$20:$B$25,1),0) -> 2 | D20: =D8 -> 11.83 | E20: =IFERROR(_xlfn.RANK.EQ(D20,$D$20:$D$25,1),0) -> 2 | F20: =F8 -> 28.02 | G20: =IFERROR(_xlfn.RANK.EQ(F20,$F$20:$F$25,1),0) -> 4 | H20: =H8 -> 15.95 | I20: =IFERROR(_xlfn.RANK.EQ(H20,$H$20:$H$25,1),0) -> 2 | J20: =J8 -> 29.93 | K20: =IFERROR(_xlfn.RANK.EQ(J20,$J$20:$J$25,1),0) -> 2 | L20: =L8 -> 15.52 | N20: =IFERROR(_xlfn.RANK.EQ(L20,$L$20:$L$25,1),0) -> 1 | O20: =O8 -> 27.87 | P20: =IFERROR(_xlfn.RANK.EQ(O20,$O$20:$O$25,1),0) -> 2
A21: Cotrafa | B21: 10.44 | C21: =IFERROR(_xlfn.RANK.EQ(B21,$B$20:$B$25,1),0) -> 1 | D21: 10.44 | E21: =IFERROR(_xlfn.RANK.EQ(D21,$D$20:$D$25,1),0) -> 1 | F21: 16.77 | G21: =IFERROR(_xlfn.RANK.EQ(F21,$F$20:$F$25,1),0) -> 1 | H21: N/A | I21: =IFERROR(_xlfn.RANK.EQ(H21,$H$20:$H$25,1),0) -> 0 | J21: N/A | K21: =IFERROR(_xlfn.RANK.EQ(J21,$J$20:$J$25,1),0) -> 0 | L21: N/A | M21: N/A | N21: =IFERROR(_xlfn.RANK.EQ(L21,$L$20:$L$25,1),0) -> 0 | O21: 28.02 | P21: =IFERROR(_xlfn.RANK.EQ(O21,$O$21:$O$25,1),0) -> 2 | R21: =VLOOKUP(A21,Hoja1!$A$3:$B$19,2,0) -> https://www.cotrafa.com.co/portafolio-de-credito
A22: Confiar | B22: 11.95 | C22: =IFERROR(_xlfn.RANK.EQ(B22,$B$20:$B$25,1),0) -> 3 | D22: 12.85 | E22: =IFERROR(_xlfn.RANK.EQ(D22,$D$20:$D$25,1),0) -> 3 | F22: 21.5 | G22: =IFERROR(_xlfn.RANK.EQ(F22,$F$20:$F$25,1),0) -> 3 | H22: N/A | I22: =IFERROR(_xlfn.RANK.EQ(H22,$H$20:$H$25,1),0) -> 0 | J22: 27.9 | K22: =IFERROR(_xlfn.RANK.EQ(J22,$J$20:$J$25,1),0) -> 1 | L22: 23.8 | M22: N/A | N22: =IFERROR(_xlfn.RANK.EQ(L22,$L$20:$L$25,1),0) -> 2 | O22: N/A | P22: =IFERROR(_xlfn.RANK.EQ(O22,$O$21:$O$25,1),0) -> 0 | R22: =VLOOKUP(A22,Hoja1!$A$3:$B$19,2,0) -> https://www.confiar.coop/personas/productos/credito/credito-para-comprar-vivienda/
A23: Coopetraban | B23: 15.53 | C23: =IFERROR(_xlfn.RANK.EQ(B23,$B$20:$B$25,1),0) -> 4 | D23: 15.53 | E23: =IFERROR(_xlfn.RANK.EQ(D23,$D$20:$D$25,1),0) -> 4 | F23: 20.98 | G23: =IFERROR(_xlfn.RANK.EQ(F23,$F$20:$F$25,1),0) -> 2 | H23: 15.53 | I23: =IFERROR(_xlfn.RANK.EQ(H23,$H$20:$H$25,1),0) -> 1 | J23: N/A | K23: =IFERROR(_xlfn.RANK.EQ(J23,$J$20:$J$25,1),0) -> 0 | L23: N/A | M23: N/A | N23: =IFERROR(_xlfn.RANK.EQ(L23,$L$20:$L$25,1),0) -> 0 | O23: 21.7 | P23: =IFERROR(_xlfn.RANK.EQ(O23,$O$21:$O$25,1),0) -> 1 | R23: =VLOOKUP(A23,Hoja1!$A$3:$B$19,2,0) -> https://www.coopetraban.com.co/tasas-de-interes-para-credito/
A24: Financiera Juriscoop C.F. | C24: =IFERROR(_xlfn.RANK.EQ(B24,$B$20:$B$25,1),0) -> 0 | E24: =IFERROR(_xlfn.RANK.EQ(D24,$D$20:$D$25,1),0) -> 0 | G24: =IFERROR(_xlfn.RANK.EQ(F24,$F$20:$F$25,1),0) -> 0 | I24: =IFERROR(_xlfn.RANK.EQ(H24,$H$20:$H$25,1),0) -> 0 | K24: =IFERROR(_xlfn.RANK.EQ(J24,$J$20:$J$25,1),0) -> 0 | N24: =IFERROR(_xlfn.RANK.EQ(L24,$L$20:$L$25,1),0) -> 0 | P24: =IFERROR(_xlfn.RANK.EQ(O24,$O$21:$O$25,1),0) -> 0 | R24: =VLOOKUP(A24,Hoja1!$A$3:$B$19,2,0) -> https://financierajuriscoop.com.co/tasas-y-tarifas
A25: JFK Cooperativa Financiera | C25: =IFERROR(_xlfn.RANK.EQ(B25,$B$20:$B$25,1),0) -> 0 | E25: =IFERROR(_xlfn.RANK.EQ(D25,$D$20:$D$25,1),0) -> 0 | G25: =IFERROR(_xlfn.RANK.EQ(F25,$F$20:$F$25,1),0) -> 0 | I25: =IFERROR(_xlfn.RANK.EQ(H25,$H$20:$H$25,1),0) -> 0 | K25: =IFERROR(_xlfn.RANK.EQ(J25,$J$20:$J$25,1),0) -> 0 | N25: =IFERROR(_xlfn.RANK.EQ(L25,$L$20:$L$25,1),0) -> 0 | P25: =IFERROR(_xlfn.RANK.EQ(O25,$O$21:$O$25,1),0) -> 0 | R25: =VLOOKUP(A25,Hoja1!$A$3:$B$19,2,0) -> https://www.jfk.com.co/credito/tasas
S26: 11.151274
A27: conversión Coopetraban | B27: =(1+1.21%)^(12/1)-1 -> 0.15526362 | R27: 0.116189 | S27: =EFFECT(R27,12) -> 0.12258056
A28: NOMBRE ENTIDAD | F28: CONSUMO (T.E.A.) | S28: 12.258056
F29: LIBRE INVERSION | H29: VEHICULO | J29: TARJETA | L29: COMPRA CARTERA | O29: CREDITOS ROTATIVOS
A30: Entidad Bancaria | F30: Tasa | G30: Ranking | H30: Tasa | I30: Ranking | J30: Tasa | K30: Ranking | L30: Tasa | N30: Ranking | O30: Tasa | P30: Ranking
A31: PRESENTE | F31: =VLOOKUP(A31,$A$5:$P$25,6,0)+F53 -> 30.52 | G31: =IFERROR(_xlfn.RANK.EQ(F31,$F$31:$F$42,1),0) -> 11 | H31: =VLOOKUP(A31,$A$5:$P$25,8,0)+H53 -> 18.45 | I31: =IFERROR(_xlfn.RANK.EQ(H31,$H$31:$H$42,1),0) -> 0 | J31: =VLOOKUP(A31,$A$5:$P$25,10,0)+J53 -> 32.43 | K31: =IFERROR(_xlfn.RANK.EQ(J31,$J$31:$J$42,1),0) -> 0 | L31: =VLOOKUP(A31,$A$5:$P$25,12,0)+L53 -> 18.02 | N31: =IFERROR(_xlfn.RANK.EQ(L31,$L$31:$L$42,1),0) -> 0 | O31: =VLOOKUP(A31,$A$5:$P$25,14,0)+O53 -> 6 | P31: =IFERROR(_xlfn.RANK.EQ(O31,$O$31:$O$50,1),0) -> 0
A32: Banco de Occidente | F32: =IFERROR(VLOOKUP(A32,$A$5:$P$25,6,0),0) -> 18.02 | G32: =IFERROR(_xlfn.RANK.EQ(F32,$F$31:$F$42,1),0) -> 5 | H32: =VLOOKUP(A32,$A$5:$P$25,8,0) -> 16.14 | I32: =IFERROR(_xlfn.RANK.EQ(H32,$H$31:$H$42,1),0) -> 0 | J32: =VLOOKUP(A32,$A$5:$P$25,10,0) -> 29.06 | K32: =IFERROR(_xlfn.RANK.EQ(J32,$J$31:$J$42,1),0) -> 0 | L32: =VLOOKUP(A32,$A$5:$P$25,12,0) -> 15.12 | N32: =IFERROR(_xlfn.RANK.EQ(L32,$L$31:$L$42,1),0) -> 0 | O32: =VLOOKUP(A32,$A$5:$P$25,14,0) -> 2 | P32: =IFERROR(_xlfn.RANK.EQ(O32,$O$31:$O$50,1),0) -> 0
A33: Banco Caja Social S.A. | F33: =IFERROR(VLOOKUP(A33,$A$5:$P$25,6,0),0) -> 13.1 | G33: =IFERROR(_xlfn.RANK.EQ(F33,$F$31:$F$42,1),0) -> 2 | H33: =VLOOKUP(A33,$A$5:$P$25,8,0) -> 16.07 | I33: =IFERROR(_xlfn.RANK.EQ(H33,$H$31:$H$42,1),0) -> 0 | J33: =VLOOKUP(A33,$A$5:$P$25,10,0) -> 27.12 | K33: =IFERROR(_xlfn.RANK.EQ(J33,$J$31:$J$42,1),0) -> 0 | L33: =VLOOKUP(A33,$A$5:$P$25,12,0) -> 15.39 | N33: =IFERROR(_xlfn.RANK.EQ(L33,$L$31:$L$42,1),0) -> 0 | O33: =VLOOKUP(A33,$A$5:$P$25,14,0) -> 5 | P33: =IFERROR(_xlfn.RANK.EQ(O33,$O$31:$O$50,1),0) -> 0
A34: Banco Davivienda | F34: =IFERROR(VLOOKUP(A34,$A$5:$P$25,6,0),0) -> 21.55 | G34: =IFERROR(_xlfn.RANK.EQ(F34,$F$31:$F$42,1),0) -> 7 | H34: =VLOOKUP(A34,$A$5:$P$25,8,0) -> 12.01 | I34: =IFERROR(_xlfn.RANK.EQ(H34,$H$31:$H$42,1),0) -> 0 | J34: =VLOOKUP(A34,$A$5:$P$25,10,0) -> 28.93 | K34: =IFERROR(_xlfn.RANK.EQ(J34,$J$31:$J$42,1),0) -> 0 | L34: =VLOOKUP(A34,$A$5:$P$25,12,0) -> 15.38 | N34: =IFERROR(_xlfn.RANK.EQ(L34,$L$31:$L$42,1),0) -> 0 | O34: =VLOOKUP(A34,$A$5:$P$25,14,0) -> 4 | P34: =IFERROR(_xlfn.RANK.EQ(O34,$O$31:$O$50,1),0) -> 0
A35: Bancolombia | F35: =IFERROR(VLOOKUP(A35,$A$5:$P$25,6,0),0) -> 19.55 | G35: =IFERROR(_xlfn.RANK.EQ(F35,$F$31:$F$42,1),0) -> 6 | H35: =VLOOKUP(A35,$A$5:$P$25,8,0) -> 15.66 | I35: =IFERROR(_xlfn.RANK.EQ(H35,$H$31:$H$42,1),0) -> 0 | J35: =VLOOKUP(A35,$A$5:$P$25,10,0) -> 26.99 | K35: =IFERROR(_xlfn.RANK.EQ(J35,$J$31:$J$42,1),0) -> 0 | L35: =VLOOKUP(A35,$A$5:$P$25,12,0) -> 13.08 | N35: =IFERROR(_xlfn.RANK.EQ(L35,$L$31:$L$42,1),0) -> 0 | O35: =VLOOKUP(A35,$A$5:$P$25,14,0) -> 1 | P35: =IFERROR(_xlfn.RANK.EQ(O35,$O$31:$O$50,1),0) -> 0
A36: AV Villas | F36: =IFERROR(VLOOKUP(A36,$A$5:$P$25,6,0),0) -> 17.6 | G36: =IFERROR(_xlfn.RANK.EQ(F36,$F$31:$F$42,1),0) -> 4 | H36: =VLOOKUP(A36,$A$5:$P$25,8,0) -> N/A | I36: =IFERROR(_xlfn.RANK.EQ(H36,$H$31:$H$42,1),0) -> 0 | J36: =VLOOKUP(A36,$A$5:$P$25,10,0) -> 28.95 | K36: =IFERROR(_xlfn.RANK.EQ(J36,$J$31:$J$42,1),0) -> 0 | L36: =VLOOKUP(A36,$A$5:$P$25,12,0) -> 15.2 | N36: =IFERROR(_xlfn.RANK.EQ(L36,$L$31:$L$42,1),0) -> 0 | O36: =VLOOKUP(A36,$A$5:$P$25,14,0) -> 3 | P36: =IFERROR(_xlfn.RANK.EQ(O36,$O$31:$O$50,1),0) -> 0
A37: Scotiabank Colpatria S.A. | F37: =IFERROR(VLOOKUP(A37,$A$5:$P$25,6,0),0) -> N/A | G37: =IFERROR(_xlfn.RANK.EQ(F37,$F$31:$F$42,1),0) -> 0 | H37: =VLOOKUP(A37,$A$5:$P$25,8,0) -> N/A | I37: =IFERROR(_xlfn.RANK.EQ(H37,$H$31:$H$42,1),0) -> 0 | J37: =VLOOKUP(A37,$A$5:$P$25,10,0) -> 29.18 | K37: =IFERROR(_xlfn.RANK.EQ(J37,$J$31:$J$42,1),0) -> 0 | L37: =VLOOKUP(A37,$A$5:$P$25,12,0) -> N/A | N37: =IFERROR(_xlfn.RANK.EQ(L37,$L$31:$L$42,1),0) -> 0 | O37: =VLOOKUP(A37,$A$5:$P$25,14,0) -> 0 | P37: =IFERROR(_xlfn.RANK.EQ(O37,$O$31:$O$50,1),0) -> 0
A38: Itaú | F38: =IFERROR(VLOOKUP(A38,$A$5:$P$25,6,0),0) -> 21.69 | G38: =IFERROR(_xlfn.RANK.EQ(F38,$F$31:$F$42,1),0) -> 8 | H38: =VLOOKUP(A38,$A$5:$P$25,8,0) -> 21.69 | I38: =IFERROR(_xlfn.RANK.EQ(H38,$H$31:$H$42,1),0) -> 0 | J38: =VLOOKUP(A38,$A$5:$P$25,10,0) -> 29.18 | K38: =IFERROR(_xlfn.RANK.EQ(J38,$J$31:$J$42,1),0) -> 0 | L38: =VLOOKUP(A38,$A$5:$P$25,12,0) -> 20.98 | N38: =IFERROR(_xlfn.RANK.EQ(L38,$L$31:$L$42,1),0) -> 0 | O38: =VLOOKUP(A38,$A$5:$P$25,14,0) -> 8 | P38: =IFERROR(_xlfn.RANK.EQ(O38,$O$31:$O$50,1),0) -> 0
A39: Banco de Bogotá | F39: =IFERROR(VLOOKUP(A39,$A$5:$P$25,6,0),0) -> 16.35 | G39: =IFERROR(_xlfn.RANK.EQ(F39,$F$31:$F$42,1),0) -> 3 | H39: =VLOOKUP(A39,$A$5:$P$25,8,0) -> 22.71 | I39: =IFERROR(_xlfn.RANK.EQ(H39,$H$31:$H$42,1),0) -> 0 | J39: =VLOOKUP(A39,$A$5:$P$25,10,0) -> 29.18 | K39: =IFERROR(_xlfn.RANK.EQ(J39,$J$31:$J$42,1),0) -> 0 | L39: =VLOOKUP(A39,$A$5:$P$25,12,0) -> 24.33 | N39: =IFERROR(_xlfn.RANK.EQ(L39,$L$31:$L$42,1),0) -> 0 | O39: =VLOOKUP(A39,$A$5:$P$25,14,0) -> 9 | P39: =IFERROR(_xlfn.RANK.EQ(O39,$O$31:$O$50,1),0) -> 0
A40: Pichincha | F40: =IFERROR(VLOOKUP(A40,$A$5:$P$25,6,0),0) -> 0 | G40: =IFERROR(_xlfn.RANK.EQ(F40,$F$31:$F$42,1),0) -> 1 | H40: =VLOOKUP(A40,$A$5:$P$25,8,0) -> #N/A | I40: =IFERROR(_xlfn.RANK.EQ(H40,$H$31:$H$42,1),0) -> 0 | J40: =VLOOKUP(A40,$A$5:$P$25,10,0) -> #N/A | K40: =IFERROR(_xlfn.RANK.EQ(J40,$J$31:$J$42,1),0) -> 0 | L40: =VLOOKUP(A40,$A$5:$P$25,12,0) -> #N/A | N40: =IFERROR(_xlfn.RANK.EQ(L40,$L$31:$L$42,1),0) -> 0 | O40: =VLOOKUP(A40,$A$5:$P$25,14,0) -> #N/A | P40: =IFERROR(_xlfn.RANK.EQ(O40,$O$31:$O$50,1),0) -> 0
A41: Banco Popular | F41: =IFERROR(VLOOKUP(A41,$A$5:$P$25,6,0),0) -> 28.12 | G41: =IFERROR(_xlfn.RANK.EQ(F41,$F$31:$F$42,1),0) -> 10 | H41: =VLOOKUP(A41,$A$5:$P$25,8,0) -> N/A | I41: =IFERROR(_xlfn.RANK.EQ(H41,$H$31:$H$42,1),0) -> 0 | J41: =VLOOKUP(A41,$A$5:$P$25,10,0) -> 29.18 | K41: =IFERROR(_xlfn.RANK.EQ(J41,$J$31:$J$42,1),0) -> 0 | L41: =VLOOKUP(A41,$A$5:$P$25,12,0) -> 28.12 | N41: =IFERROR(_xlfn.RANK.EQ(L41,$L$31:$L$42,1),0) -> 0 | O41: =VLOOKUP(A41,$A$5:$P$25,14,0) -> 10 | P41: =IFERROR(_xlfn.RANK.EQ(O41,$O$31:$O$50,1),0) -> 0
...

Sheet propuesta disminución
B1: INFORME DE TASAS DE CARTELERA POR MODALIDAD DE CRÉDITO
B2: Tasas efectivas anuales
D3: 45397
A5: NOMBRE ENTIDAD | B5: VIVIENDA en Pesos (T.E.A.) | F5: CONSUMO (T.E.A.)
B6: VIS | D6: NO VIS | F6: LIBRE INVERSION | H6: VEHICULO | J6: TARJETA | L6: COMPRA CARTERA | N6: CREDITOS ROTATIVOS
A7: Entidad Bancaria | B7: Tasa | C7: Ranking | D7: Tasa | E7: Ranking | F7: Tasa | G7: Ranking | H7: Tasa | I7: Ranking | J7: Tasa | K7: Ranking | L7: Tasa | M7: Ranking | N7: Tasa | O7: Ranking
A8: PRESENTE | B8: 12.7 | C8: =IFERROR(_xlfn.RANK.EQ(B8,$B$8:$B$19,1),0) -> 2 | D8: 13.83 | E8: =IFERROR(_xlfn.RANK.EQ(D8,$D$8:$D$19,1),0) -> 3 | F8: 26.68 | G8: =IFERROR(_xlfn.RANK.EQ(F8,$F$8:$F$19,1),0) -> 8 | H8: 18.3 | I8: =IFERROR(_xlfn.RANK.EQ(H8,$H$8:$H$19,1),0) -> 5 | J8: 32.77 | K8: =IFERROR(_xlfn.RANK.EQ(J8,$J$8:$J$19,1),0) -> 2 | L8: 19.52 | M8: =IFERROR(_xlfn.RANK.EQ(L8,$L$8:$L$19,1),0) -> 5 | N8: 32.77 | O8: =IFERROR(_xlfn.RANK.EQ(N8,$N$8:$N$19,1),0) -> 6 | P8: =VLOOKUP(A33,Hoja1!A2:B18,2,0) -> reglamento de crédito
A9: Banco Davivienda | B9: 14 | C9: =IFERROR(_xlfn.RANK.EQ(B9,$B$8:$B$19,1),0) -> 6 | D9: 15.7 | E9: =IFERROR(_xlfn.RANK.EQ(D9,$D$8:$D$19,1),0) -> 6 | F9: 18.99 | G9: =IFERROR(_xlfn.RANK.EQ(F9,$F$8:$F$19,1),0) -> 4 | H9: 16.49 | I9: =IFERROR(_xlfn.RANK.EQ(H9,$H$8:$H$19,1),0) -> 1 | J9: 32.92 | K9: =IFERROR(_xlfn.RANK.EQ(J9,$J$8:$J$19,1),0) -> 3 | L9: 17.18 | M9: =IFERROR(_xlfn.RANK.EQ(L9,$L$8:$L$19,1),0) -> 1 | N9: 32.76 | O9: =IFERROR(_xlfn.RANK.EQ(N9,$N$8:$N$19,1),0) -> 5 | P9: =VLOOKUP(A9,Hoja1!$A$3:$B$19,2,0) -> https://www.davivienda.com/wps/portal/personas/nuevo/personas/tasasytarifas/!ut/p/z1/jZBNb4JAEIZ_DdedYReHtbdtg7akKsZY6F4MGIokLGsAy98vml6a1I1zm-R55uMFDRnoNv-uq3yobZs3U_-p6RAs3979iBIVCeKoXgPiUn74GCKkN0DIbbCOn_lqt5gLVCvcvaj5xt8sOehHfLxTCh_zHYB2j09B3xDXBy4AF-Ev4FgSg64Lw8ajYcgE0fUwpJBLCmh2zVi1hZAV6K78KruyY5duiv40DOf-yUMPx3FklbVVU7KjNR7-p5xsP0D2l4Sz2e8zrBOTyv4Hlats8Q!!/dz/d5/L2dBISEvZ0FBIS9nQSEh/
A10: Banco de Occidente | B10: 14.15 | C10: =IFERROR(_xlfn.RANK.EQ(B10,$B$8:$B$19,1),0) -> 7 | D10: 14.15 | E10: =IFERROR(_xlfn.RANK.EQ(D10,$D$8:$D$19,1),0) -> 4 | F10: 19.7 | G10: =IFERROR(_xlfn.RANK.EQ(F10,$F$8:$F$19,1),0) -> 7 | H10: 17.88 | I10: =IFERROR(_xlfn.RANK.EQ(H10,$H$8:$H$19,1),0) -> 3 | J10: 32.94 | K10: =IFERROR(_xlfn.RANK.EQ(J10,$J$8:$J$19,1),0) -> 5 | L10: 18.44 | M10: =IFERROR(_xlfn.RANK.EQ(L10,$L$8:$L$19,1),0) -> 3 | N10: 21.7 | O10: =IFERROR(_xlfn.RANK.EQ(N10,$N$8:$N$19,1),0) -> 1 | P10: =VLOOKUP(A10,Hoja1!$A$3:$B$19,2,0) -> https://www.bancodeoccidente.com.co/wps/wcm/connect/banco-de-occidente/c24390e8-b984-44de-b427-e59ff152a22c/tasas-personas-2022.pdf?MOD=AJPERES&CVID=o7LgirB
A11: Banco Caja Social S.A. | B11: 13 | C11: =IFERROR(_xlfn.RANK.EQ(B11,$B$8:$B$19,1),0) -> 3 | D11: 14.4 | E11: =IFERROR(_xlfn.RANK.EQ(D11,$D$8:$D$19,1),0) -> 5 | F11: 14.6 | G11: =IFERROR(_xlfn.RANK.EQ(F11,$F$8:$F$19,1),0) -> 1 | H11: 18.02 | I11: =IFERROR(_xlfn.RANK.EQ(H11,$H$8:$H$19,1),0) -> 4 | J11: 31.22 | K11: =IFERROR(_xlfn.RANK.EQ(J11,$J$8:$J$19,1),0) -> 1 | L11: N/A | M11: =IFERROR(_xlfn.RANK.EQ(L11,$L$8:$L$19,1),0) -> 0 | N11: 31.22 | O11: =IFERROR(_xlfn.RANK.EQ(N11,$N$8:$N$19,1),0) -> 3 | P11: =VLOOKUP(A11,Hoja1!$A$3:$B$19,2,0) -> https://www.bancocajasocial.com/portalserver/tasas-precios-y-comisiones
A12: Bancolombia | B12: 15.15 | C12: =IFERROR(_xlfn.RANK.EQ(B12,$B$8:$B$19,1),0) -> 8 | D12: 15.95 | E12: =IFERROR(_xlfn.RANK.EQ(D12,$D$8:$D$19,1),0) -> 8 | F12: 17.31 | G12: =IFERROR(_xlfn.RANK.EQ(F12,$F$8:$F$19,1),0) -> 2 | H12: 16.9 | I12: =IFERROR(_xlfn.RANK.EQ(H12,$H$8:$H$19,1),0) -> 2 | J12: 33.22 | K12: =IFERROR(_xlfn.RANK.EQ(J12,$J$8:$J$19,1),0) -> 11 | L12: 19.07 | M12: =IFERROR(_xlfn.RANK.EQ(L12,$L$8:$L$19,1),0) -> 4 | N12: 20.01 | O12: =IFERROR(_xlfn.RANK.EQ(N12,$N$8:$N$19,1),0) -> 0 | P12: =VLOOKUP(A12,Hoja1!$A$3:$B$19,2,0) -> https://www.bancolombia.com/personas/creditos/consumo/
A13: AV Villas | B13: 16.05 | C13: =IFERROR(_xlfn.RANK.EQ(B13,$B$8:$B$19,1),0) -> 9 | D13: 16.45 | E13: =IFERROR(_xlfn.RANK.EQ(D13,$D$8:$D$19,1),0) -> 9 | F13: 17.6 | G13: =IFERROR(_xlfn.RANK.EQ(F13,$F$8:$F$19,1),0) -> 3 | H13: N/A | I13: =IFERROR(_xlfn.RANK.EQ(H13,$H$8:$H$19,1),0) -> 0 | J13: 33 | K13: =IFERROR(_xlfn.RANK.EQ(J13,$J$8:$J$19,1),0) -> 6 | L13: 17.3 | M13: =IFERROR(_xlfn.RANK.EQ(L13,$L$8:$L$19,1),0) -> 2 | N13: N/A | O13: =IFERROR(_xlfn.RANK.EQ(N13,$N$8:$N$19,1),0) -> 0 | P13: =VLOOKUP(A13,Hoja1!$A$3:$B$19,2,0) -> https://www.avvillas.com.co/wps/portal/avvillas/banco/banca-personal/tasas-tarifas-personas/
A14: Scotiabank Colpatria S.A. | B14: 13.99 | C14: =IFERROR(_xlfn.RANK.EQ(B14,$B$8:$B$19,1),0) -> 5 | D14: 15.89 | E14: =IFERROR(_xlfn.RANK.EQ(D14,$D$8:$D$19,1),0) -> 7 | F14: N/A | G14: =IFERROR(_xlfn.RANK.EQ(F14,$F$8:$F$19,1),0) -> 0 | H14: 21.69 | I14: =IFERROR(_xlfn.RANK.EQ(H14,$H$8:$H$19,1),0) -> 8 | J14: 33.06 | K14: =IFERROR(_xlfn.RANK.EQ(J14,$J$8:$J$19,1),0) -> 8 | L14: N/A | M14: =IFERROR(_xlfn.RANK.EQ(L14,$L$8:$L$19,1),0) -> 0 | N14: 33.29 | O14: =IFERROR(_xlfn.RANK.EQ(N14,$N$8:$N$19,1),0) -> 8 | P14: =VLOOKUP(A14,Hoja1!$A$3:$B$19,2,0) -> https://www.scotiabankcolpatria.com/tasas-y-tarifas
A15: Itaú | B15: 13.64 | C15: =IFERROR(_xlfn.RANK.EQ(B15,$B$8:$B$19,1),0) -> 4 | D15: 13.64 | E15: =IFERROR(_xlfn.RANK.EQ(D15,$D$8:$D$19,1),0) -> 2 | F15: 19.279 | G15: =IFERROR(_xlfn.RANK.EQ(F15,$F$8:$F$19,1),0) -> 6 | H15: 21.699 | I15: =IFERROR(_xlfn.RANK.EQ(H15,$H$8:$H$19,1),0) -> 9 | J15: 33 | K15: =IFERROR(_xlfn.RANK.EQ(J15,$J$8:$J$19,1),0) -> 6 | L15: 24.311 | M15: =IFERROR(_xlfn.RANK.EQ(L15,$L$8:$L$19,1),0) -> 9 | N15: 31.528 | O15: =IFERROR(_xlfn.RANK.EQ(N15,$N$8:$N$19,1),0) -> 4 | P15: =VLOOKUP(A15,Hoja1!$A$3:$B$19,2,0) -> https://banco.itau.co/web/personas/informacion-de-interes/tasas-y-tarifas
A16: Banco de Bogotá | B16: 11.88 | C16: =IFERROR(_xlfn.RANK.EQ(B16,$B$8:$B$19,1),0) -> 1 | D16: 11.88 | E16: =IFERROR(_xlfn.RANK.EQ(D16,$D$8:$D$19,1),0) -> 1 | F16: 30.44 | G16: =IFERROR(_xlfn.RANK.EQ(F16,$F$8:$F$19,1),0) -> 11 | H16: 19.56 | I16: =IFERROR(_xlfn.RANK.EQ(H16,$H$8:$H$19,1),0) -> 6 | J16: 33.06 | K16: =IFERROR(_xlfn.RANK.EQ(J16,$J$8:$J$19,1),0) -> 8 | L16: 23.04 | M16: =IFERROR(_xlfn.RANK.EQ(L16,$L$8:$L$19,1),0) -> 6 | N16: 34.88 | O16: =IFERROR(_xlfn.RANK.EQ(N16,$N$8:$N$19,1),0) -> 9 | P16: =VLOOKUP(A16,Hoja1!$A$3:$B$19,2,0) -> https://www.bancodebogota.com/wps/portal/banco-de-bogota/bogota/productos/para-ti/tasas-y-tarifas/tasas-2023
A17: Banco Serfinanza S.A. | B17: N/A | C17: =IFERROR(_xlfn.RANK.EQ(B17,$B$8:$B$19,1),0) -> 0 | D17: N/A | E17: =IFERROR(_xlfn.RANK.EQ(D17,$D$8:$D$19,1),0) -> 0 | F17: 26.82 | G17: =IFERROR(_xlfn.RANK.EQ(F17,$F$8:$F$19,1),0) -> 9 | H17: 23.73 | I17: =IFERROR(_xlfn.RANK.EQ(H17,$H$8:$H$19,1),0) -> 10 | J17: N/A | K17: =IFERROR(_xlfn.RANK.EQ(J17,$J$8:$J$19,1),0) -> 0 | L17: 23.73 | M17: =IFERROR(_xlfn.RANK.EQ(L17,$L$8:$L$19,1),0) -> 8 | N17: 29.84 | O17: =IFERROR(_xlfn.RANK.EQ(N17,$N$8:$N$19,1),0) -> 2 | P17: https://bancoserfinanza.com/servicio-al-cliente/tasas/
A18: Banco Popular | B18: 17.55 | C18: =IFERROR(_xlfn.RANK.EQ(B18,$B$8:$B$19,1),0) -> 10 | D18: 17.55 | E18: =IFERROR(_xlfn.RANK.EQ(D18,$D$8:$D$19,1),0) -> 10 | F18: 27.57 | G18: =IFERROR(_xlfn.RANK.EQ(F18,$F$8:$F$19,1),0) -> 10 | H18: N/A | I18: =IFERROR(_xlfn.RANK.EQ(H18,$H$8:$H$19,1),0) -> 0 | J18: 33.07 | K18: =IFERROR(_xlfn.RANK.EQ(J18,$J$8:$J$19,1),0) -> 10 | L18: 23.43 | M18: =IFERROR(_xlfn.RANK.EQ(L18,$L$8:$L$19,1),0) -> 7 | N18: N/A | O18: =IFERROR(_xlfn.RANK.EQ(N18,$N$8:$N$19,1),0) -> 0 | P18: =VLOOKUP(A18,Hoja1!$A$3:$B$19,2,0) -> https://www.bancopopular.com.co/wps/portal/bancopopular/inicio/informacion-interes/tasas
A19: Pichincha | B19: N/A | C19: =IFERROR(_xlfn.RANK.EQ(B19,$B$8:$B$19,1),0) -> 0 | D19: N/A | E19: =IFERROR(_xlfn.RANK.EQ(D19,$D$8:$D$19,1),0) -> 0 | F19: 19 | G19: =IFERROR(_xlfn.RANK.EQ(F19,$F$8:$F$19,1),0) -> 5 | H19: 21.54 | I19: =IFERROR(_xlfn.RANK.EQ(H19,$H$8:$H$19,1),0) -> 7 | J19: 32.92 | K19: =IFERROR(_xlfn.RANK.EQ(J19,$J$8:$J$19,1),0) -> 3 | L19: 26.23 | M19: =IFERROR(_xlfn.RANK.EQ(L19,$L$8:$L$19,1),0) -> 10 | N19: 33.03 | O19: =IFERROR(_xlfn.RANK.EQ(N19,$N$8:$N$19,1),0) -> 7 | P19: =VLOOKUP(A19,Hoja1!$A$3:$B$19,2,0) -> https://www.bancopichincha.com.co/web/corporativo/tasas-y-tarifas
A20: Cooperativas Financieras | B20: Tasa | C20: Ranking | D20: Tasa | E20: Ranking | F20: Tasa | G20: Ranking | H20: Tasa | I20: Ranking | J20: Tasa | K20: Ranking | L20: Tasa | M20: Ranking | N20: Tasa | O20: Ranking
A21: PRESENTE | B21: =B8 -> 12.7 | C21: =IFERROR(_xlfn.RANK.EQ(B21,$B$21:$B$27,1),0) -> 1 | D21: =D8 -> 13.83 | E21: =IFERROR(_xlfn.RANK.EQ(D21,$D$21:$D$27,1),0) -> 1 | F21: =F8 -> 26.68 | G21: =IFERROR(_xlfn.RANK.EQ(F21,$F$21:$F$27,1),0) -> 4 | H21: =H8 -> 18.3 | I21: =IFERROR(_xlfn.RANK.EQ(H21,$H$21:$H$27,1),0) -> 1 | J21: =J8 -> 32.77 | K21: =IFERROR(_xlfn.RANK.EQ(J21,$J$21:$J$27,1),0) -> 2 | L21: =L8 -> 19.52 | M21: =IFERROR(_xlfn.RANK.EQ(L21,$L$21:$L$27,1),0) -> 1 | N21: =N8 -> 32.77 | O21: =IFERROR(_xlfn.RANK.EQ(N21,$N$21:$N$27,1),0) -> 3
A22: Cotrafa | B22: 16.77 | C22: =IFERROR(_xlfn.RANK.EQ(B22,$B$21:$B$27,1),0) -> 2 | D22: 19.56 | E22: =IFERROR(_xlfn.RANK.EQ(D22,$D$21:$D$27,1),0) -> 5 | F22: 18.86 | G22: =IFERROR(_xlfn.RANK.EQ(F22,$F$21:$F$27,1),0) -> 1 | H22: N/A | I22: =IFERROR(_xlfn.RANK.EQ(H22,$H$21:$H$27,1),0) -> 0 | J22: N/A | K22: =IFERROR(_xlfn.RANK.EQ(J22,$J$21:$J$27,1),0) -> 0 | L22: N/A | M22: =IFERROR(_xlfn.RANK.EQ(L22,$L$21:$L$27,1),0) -> 0 | N22: 32.92 | O22: =IFERROR(_xlfn.RANK.EQ(N22,$N$22:$N$27,1),0) -> 3 | P22: =VLOOKUP(A22,Hoja1!$A$3:$B$19,2,0) -> https://www.cotrafa.com.co/portafolio-de-credito
A23: Confiar | B23: 17 | C23: =IFERROR(_xlfn.RANK.EQ(B23,$B$21:$B$27,1),0) -> 3 | D23: 17 | E23: =IFERROR(_xlfn.RANK.EQ(D23,$D$21:$D$27,1),0) -> 2 | F23: 21.9 | G23: =IFERROR(_xlfn.RANK.EQ(F23,$F$21:$F$27,1),0) -> 2 | H23: N/A | I23: =IFERROR(_xlfn.RANK.EQ(H23,$H$21:$H$27,1),0) -> 0 | J23: 28 | K23: =IFERROR(_xlfn.RANK.EQ(J23,$J$21:$J$27,1),0) -> 1 | L23: 23.8 | M23: =IFERROR(_xlfn.RANK.EQ(L23,$L$21:$L$27,1),0) -> 2 | N23: N/A | O23: =IFERROR(_xlfn.RANK.EQ(N23,$N$22:$N$27,1),0) -> 0 | P23: =VLOOKUP(A23,Hoja1!$A$3:$B$19,2,0) -> https://www.confiar.coop/personas/productos/credito/credito-para-comprar-vivienda/
A24: Coopetraban | B24: 18.86 | C24: =IFERROR(_xlfn.RANK.EQ(B24,$B$21:$B$27,1),0) -> 5 | D24: 18.86 | E24: =IFERROR(_xlfn.RANK.EQ(D24,$D$21:$D$27,1),0) -> 4 | F24: 23.43 | G24: =IFERROR(_xlfn.RANK.EQ(F24,$F$21:$F$27,1),0) -> 3 | H24: 18.86 | I24: =IFERROR(_xlfn.RANK.EQ(H24,$H$21:$H$27,1),0) -> 2 | J24: N/A | K24: =IFERROR(_xlfn.RANK.EQ(J24,$J$21:$J$27,1),0) -> 0 | L24: N/A | M24: =IFERROR(_xlfn.RANK.EQ(L24,$L$21:$L$27,1),0) -> 0 | N24: 23.87 | O24: =IFERROR(_xlfn.RANK.EQ(N24,$N$22:$N$27,1),0) -> 1 | P24: =VLOOKUP(A24,Hoja1!$A$3:$B$19,2,0) -> https://www.coopetraban.com.co/tasas-de-interes-para-credito/
A25: Cooperativa Financiera de Antioquia | B25: 17.52 | C25: =IFERROR(_xlfn.RANK.EQ(B25,$B$21:$B$27,1),0) -> 4 | D25: 18.73 | E25: =IFERROR(_xlfn.RANK.EQ(D25,$D$21:$D$27,1),0) -> 3 | F25: 32.43 | G25: =IFERROR(_xlfn.RANK.EQ(F25,$F$21:$F$27,1),0) -> 5 | H25: 28.24 | I25: =IFERROR(_xlfn.RANK.EQ(H25,$H$21:$H$27,1),0) -> 3 | J25: N/A | K25: =IFERROR(_xlfn.RANK.EQ(J25,$J$21:$J$27,1),0) -> 0 | L25: N/A | M25: =IFERROR(_xlfn.RANK.EQ(L25,$L$21:$L$27,1),0) -> 0 | N25: 26.72 | O25: =IFERROR(_xlfn.RANK.EQ(N25,$N$22:$N$27,1),0) -> 2 | P25: =VLOOKUP(A25,Hoja1!$A$3:$B$19,2,0) -> https://www.cfa.com.co/tasas-de-colocacion/
A26: Financiera Juriscoop C.F. | C26: =IFERROR(_xlfn.RANK.EQ(B26,$B$21:$B$27,1),0) -> 0 | E26: =IFERROR(_xlfn.RANK.EQ(D26,$D$21:$D$27,1),0) -> 0 | G26: =IFERROR(_xlfn.RANK.EQ(F26,$F$21:$F$27,1),0) -> 0 | I26: =IFERROR(_xlfn.RANK.EQ(H26,$H$21:$H$27,1),0) -> 0 | K26: =IFERROR(_xlfn.RANK.EQ(J26,$J$21:$J$27,1),0) -> 0 | M26: =IFERROR(_xlfn.RANK.EQ(L26,$L$21:$L$27,1),0) -> 0 | O26: =IFERROR(_xlfn.RANK.EQ(N26,$N$22:$N$27,1),0) -> 0 | P26: =VLOOKUP(A26,Hoja1!$A$3:$B$19,2,0) -> https://financierajuriscoop.com.co/tasas-y-tarifas
A27: JFK Cooperativa Financiera | C27: =IFERROR(_xlfn.RANK.EQ(B27,$B$21:$B$27,1),0) -> 0 | E27: =IFERROR(_xlfn.RANK.EQ(D27,$D$21:$D$27,1),0) -> 0 | G27: =IFERROR(_xlfn.RANK.EQ(F27,$F$21:$F$27,1),0) -> 0 | I27: =IFERROR(_xlfn.RANK.EQ(H27,$H$21:$H$27,1),0) -> 0 | K27: =IFERROR(_xlfn.RANK.EQ(J27,$J$21:$J$27,1),0) -> 0 | M27: =IFERROR(_xlfn.RANK.EQ(L27,$L$21:$L$27,1),0) -> 0 | O27: =IFERROR(_xlfn.RANK.EQ(N27,$N$22:$N$27,1),0) -> 0 | P27: =VLOOKUP(A27,Hoja1!$A$3:$B$19,2,0) -> https://www.jfk.com.co/credito/tasas
Q28: 11.151274
A29: conversión Coopetraban | B29: =(1+1.038%)^(12/1)-1 -> 0.13192302 | P29: 0.116189 | Q29: =EFFECT(P29,12) -> 0.12258056
A30: NOMBRE ENTIDAD | F30: CONSUMO (T.E.A.) | Q30: 12.258056
F31: LIBRE INVERSION | H31: VEHICULO | J31: TARJETA | L31: COMPRA CARTERA | N31: CREDITOS ROTATIVOS
A32: Entidad Bancaria | F32: Tasa | G32: Ranking | H32: Tasa | I32: Ranking | J32: Tasa | K32: Ranking | L32: Tasa | M32: Ranking | N32: Tasa | O32: Ranking
A33: PRESENTE | F33: =VLOOKUP(A33,$A$5:$O$27,6,0)+F55 -> 29.18 | G33: =IFERROR(_xlfn.RANK.EQ(F33,$F$33:$F$44,1),0) -> 10 | H33: =VLOOKUP(A33,$A$5:$O$27,8,0)+H55 -> 20.8 | I33: =IFERROR(_xlfn.RANK.EQ(H33,$H$33:$H$44,1),0) -> 6 | J33: =VLOOKUP(A33,$A$5:$O$27,10,0)+J55 -> 35.27 | K33: =IFERROR(_xlfn.RANK.EQ(J33,$J$33:$J$44,1),0) -> 11 | L33: =VLOOKUP(A33,$A$5:$O$27,12,0)+L55 -> 22.02 | M33: =IFERROR(_xlfn.RANK.EQ(L33,$L$33:$L$44,1),0) -> 5 | N33: =VLOOKUP(A33,$A$5:$O$27,14,0)+N55 -> 32.77 | O33: =IFERROR(_xlfn.RANK.EQ(N33,$N$33:$N$52,1),0) -> 9
A34: Banco de Occidente | F34: =IFERROR(VLOOKUP(A34,$A$5:$O$27,6,0),0) -> 19.7 | G34: =IFERROR(_xlfn.RANK.EQ(F34,$F$33:$F$44,1),0) -> 7 | H34: =VLOOKUP(A34,$A$5:$O$27,8,0) -> 17.88 | I34: =IFERROR(_xlfn.RANK.EQ(H34,$H$33:$H$44,1),0) -> 3 | J34: =VLOOKUP(A34,$A$5:$O$27,10,0) -> 32.94 | K34: =IFERROR(_xlfn.RANK.EQ(J34,$J$33:$J$44,1),0) -> 4 | L34: =VLOOKUP(A34,$A$5:$O$27,12,0) -> 18.44 | M34: =IFERROR(_xlfn.RANK.EQ(L34,$L$33:$L$44,1),0) -> 3 | N34: =VLOOKUP(A34,$A$5:$O$27,14,0) -> 21.7 | O34: =IFERROR(_xlfn.RANK.EQ(N34,$N$33:$N$52,1),0) -> 3
A35: Banco Caja Social S.A. | F35: =IFERROR(VLOOKUP(A35,$A$5:$O$27,6,0),0) -> 14.6 | G35: =IFERROR(_xlfn.RANK.EQ(F35,$F$33:$F$44,1),0) -> 1 | H35: =VLOOKUP(A35,$A$5:$O$27,8,0) -> 18.02 | I35: =IFERROR(_xlfn.RANK.EQ(H35,$H$33:$H$44,1),0) -> 4 | J35: =VLOOKUP(A35,$A$5:$O$27,10,0) -> 31.22 | K35: =IFERROR(_xlfn.RANK.EQ(J35,$J$33:$J$44,1),0) -> 1 | L35: =VLOOKUP(A35,$A$5:$O$27,12,0) -> N/A | M35: =IFERROR(_xlfn.RANK.EQ(L35,$L$33:$L$44,1),0) -> 0 | N35: =VLOOKUP(A35,$A$5:$O$27,14,0) -> 31.22 | O35: =IFERROR(_xlfn.RANK.EQ(N35,$N$33:$N$52,1),0) -> 6
A36: Banco Davivienda | F36: =IFERROR(VLOOKUP(A36,$A$5:$O$27,6,0),0) -> 18.99 | G36: =IFERROR(_xlfn.RANK.EQ(F36,$F$33:$F$44,1),0) -> 4 | H36: =VLOOKUP(A36,$A$5:$O$27,8,0) -> 16.49 | I36: =IFERROR(_xlfn.RANK.EQ(H36,$H$33:$H$44,1),0) -> 1 | J36: =VLOOKUP(A36,$A$5:$O$27,10,0) -> 32.92 | K36: =IFERROR(_xlfn.RANK.EQ(J36,$J$33:$J$44,1),0) -> 2 | L36: =VLOOKUP(A36,$A$5:$O$27,12,0) -> 17.18 | M36: =IFERROR(_xlfn.RANK.EQ(L36,$L$33:$L$44,1),0) -> 1 | N36: =VLOOKUP(A36,$A$5:$O$27,14,0) -> 32.76 | O36: =IFERROR(_xlfn.RANK.EQ(N36,$N$33:$N$52,1),0) -> 8
A37: Bancolombia | F37: =IFERROR(VLOOKUP(A37,$A$5:$O$27,6,0),0) -> 17.31 | G37: =IFERROR(_xlfn.RANK.EQ(F37,$F$33:$F$44,1),0) -> 2 | H37: =VLOOKUP(A37,$A$5:$O$27,8,0) -> 16.9 | I37: =IFERROR(_xlfn.RANK.EQ(H37,$H$33:$H$44,1),0) -> 2 | J37: =VLOOKUP(A37,$A$5:$O$27,10,0) -> 33.22 | K37: =IFERROR(_xlfn.RANK.EQ(J37,$J$33:$J$44,1),0) -> 10 | L37: =VLOOKUP(A37,$A$5:$O$27,12,0) -> 19.07 | M37: =IFERROR(_xlfn.RANK.EQ(L37,$L$33:$L$44,1),0) -> 4 | N37: =VLOOKUP(A37,$A$5:$O$27,14,0) -> 20.01 | O37: =IFERROR(_xlfn.RANK.EQ(N37,$N$33:$N$52,1),0) -> 0
A38: AV Villas | F38: =IFERROR(VLOOKUP(A38,$A$5:$O$27,6,0),0) -> 17.6 | G38: =IFERROR(_xlfn.RANK.EQ(F38,$F$33:$F$44,1),0) -> 3 | H38: =VLOOKUP(A38,$A$5:$O$27,8,0) -> N/A | I38: =IFERROR(_xlfn.RANK.EQ(H38,$H$33:$H$44,1),0) -> 0 | J38: =VLOOKUP(A38,$A$5:$O$27,10,0) -> 33 | K38: =IFERROR(_xlfn.RANK.EQ(J38,$J$33:$J$44,1),0) -> 5 | L38: =VLOOKUP(A38,$A$5:$O$27,12,0) -> 17.3 | M38: =IFERROR(_xlfn.RANK.EQ(L38,$L$33:$L$44,1),0) -> 2 | N38: =VLOOKUP(A38,$A$5:$O$27,14,0) -> N/A | O38: =IFERROR(_xlfn.RANK.EQ(N38,$N$33:$N$52,1),0) -> 0
A39: Scotiabank Colpatria S.A. | F39: =IFERROR(VLOOKUP(A39,$A$5:$O$27,6,0),0) -> N/A | G39: =IFERROR(_xlfn.RANK.EQ(F39,$F$33:$F$44,1),0) -> 0 | H39: =VLOOKUP(A39,$A$5:$O$27,8,0) -> 21.69 | I39: =IFERROR(_xlfn.RANK.EQ(H39,$H$33:$H$44,1),0) -> 8 | J39: =VLOOKUP(A39,$A$5:$O$27,10,0) -> 33.06 | K39: =IFERROR(_xlfn.RANK.EQ(J39,$J$33:$J$44,1),0) -> 7 | L39: =VLOOKUP(A39,$A$5:$O$27,12,0) -> N/A | M39: =IFERROR(_xlfn.RANK.EQ(L39,$L$33:$L$44,1),0) -> 0 | N39: =VLOOKUP(A39,$A$5:$O$27,14,0) -> 33.29 | O39: =IFERROR(_xlfn.RANK.EQ(N39,$N$33:$N$52,1),0) -> 13
A40: Itaú | F40: =IFERROR(VLOOKUP(A40,$A$5:$O$27,6,0),0) -> 19.279 | G40: =IFERROR(_xlfn.RANK.EQ(F40,$F$33:$F$44,1),0) -> 6 | H40: =VLOOKUP(A40,$A$5:$O$27,8,0) -> 21.699 | I40: =IFERROR(_xlfn.RANK.EQ(H40,$H$33:$H$44,1),0) -> 9 | J40: =VLOOKUP(A40,$A$5:$O$27,10,0) -> 33 | K40: =IFERROR(_xlfn.RANK.EQ(J40,$J$33:$J$44,1),0) -> 5 | L40: =VLOOKUP(A40,$A$5:$O$27,12,0) -> 24.311 | M40: =IFERROR(_xlfn.RANK.EQ(L40,$L$33:$L$44,1),0) -> 9 | N40: =VLOOKUP(A40,$A$5:$O$27,14,0) -> 31.528 | O40: =IFERROR(_xlfn.RANK.EQ(N40,$N$33:$N$52,1),0) -> 7
A41: Banco de Bogotá | F41: =IFERROR(VLOOKUP(A41,$A$5:$O$27,6,0),0) -> 30.44 | G41: =IFERROR(_xlfn.RANK.EQ(F41,$F$33:$F$44,1),0) -> 11 | H41: =VLOOKUP(A41,$A$5:$O$27,8,0) -> 19.56 | I41: =IFERROR(_xlfn.RANK.EQ(H41,$H$33:$H$44,1),0) -> 5 | J41: =VLOOKUP(A41,$A$5:$O$27,10,0) -> 33.06 | K41: =IFERROR(_xlfn.RANK.EQ(J41,$J$33:$J$44,1),0) -> 7 | L41: =VLOOKUP(A41,$A$5:$O$27,12,0) -> 23.04 | M41: =IFERROR(_xlfn.RANK.EQ(L41,$L$33:$L$44,1),0) -> 6 | N41: =VLOOKUP(A41,$A$5:$O$27,14,0) -> 34.88 | O41: =IFERROR(_xlfn.RANK.EQ(N41,$N$33:$N$52,1),0) -> 14
...

Sheet Cartera Créditos - E
B1: INFORME DE TASAS DE CARTELERA POR MODALIDAD DE CRÉDITO
B2: Tasas efectivas anuales
D3: 45344
A5: NOMBRE ENTIDAD | B5: VIVIENDA en Pesos (T.E.A.) | F5: CONSUMO (T.E.A.)
B6: VIS | D6: NO VIS | F6: LIBRE INVERSION | H6: VEHICULO | J6: TARJETA | L6: COMPRA CARTERA | N6: CREDITOS ROTATIVOS
A7: Entidad Bancaria | B7: Tasa | C7: Ranking | D7: Tasa | E7: Ranking | F7: Tasa | G7: Ranking | H7: Tasa | I7: Ranking | J7: Tasa | K7: Ranking | L7: Tasa | M7: Ranking | N7: Tasa | O7: Ranking
A8: PRESENTE | B8: 13.19 | C8: =IFERROR(_xlfn.RANK.EQ(B8,$B$8:$B$19,1),0) -> 1 | D8: 15.25 | E8: =IFERROR(_xlfn.RANK.EQ(D8,$D$8:$D$19,1),0) -> 2 | F8: 26.68 | G8: =IFERROR(_xlfn.RANK.EQ(F8,$F$8:$F$19,1),0) -> 8 | H8: 18.3 | I8: =IFERROR(_xlfn.RANK.EQ(H8,$H$8:$H$19,1),0) -> 3 | J8: 36.87 | K8: =IFERROR(_xlfn.RANK.EQ(J8,$J$8:$J$19,1),0) -> 12 | L8: 19.52 | M8: =IFERROR(_xlfn.RANK.EQ(L8,$L$8:$L$19,1),0) -> 4 | N8: 34.65 | O8: =IFERROR(_xlfn.RANK.EQ(N8,$N$8:$N$19,1),0) -> 6 | P8: =VLOOKUP(A33,Hoja1!A2:B18,2,0) -> reglamento de crédito
A9: Banco Davivienda | B9: 14 | C9: =IFERROR(_xlfn.RANK.EQ(B9,$B$8:$B$19,1),0) -> 2 | D9: 17.6 | E9: =IFERROR(_xlfn.RANK.EQ(D9,$D$8:$D$19,1),0) -> 9 | F9: 21.98 | G9: =IFERROR(_xlfn.RANK.EQ(F9,$F$8:$F$19,1),0) -> 5 | H9: 17.74 | I9: =IFERROR(_xlfn.RANK.EQ(H9,$H$8:$H$19,1),0) -> 2 | J9: 34.8 | K9: =IFERROR(_xlfn.RANK.EQ(J9,$J$8:$J$19,1),0) -> 5 | L9: 18.85 | M9: =IFERROR(_xlfn.RANK.EQ(L9,$L$8:$L$19,1),0) -> 2 | N9: 33.54 | O9: =IFERROR(_xlfn.RANK.EQ(N9,$N$8:$N$19,1),0) -> 4 | P9: =VLOOKUP(A9,Hoja1!$A$3:$B$19,2,0) -> https://www.davivienda.com/wps/portal/personas/nuevo/personas/tasasytarifas/!ut/p/z1/jZBNb4JAEIZ_DdedYReHtbdtg7akKsZY6F4MGIokLGsAy98vml6a1I1zm-R55uMFDRnoNv-uq3yobZs3U_-p6RAs3979iBIVCeKoXgPiUn74GCKkN0DIbbCOn_lqt5gLVCvcvaj5xt8sOehHfLxTCh_zHYB2j09B3xDXBy4AF-Ev4FgSg64Lw8ajYcgE0fUwpJBLCmh2zVi1hZAV6K78KruyY5duiv40DOf-yUMPx3FklbVVU7KjNR7-p5xsP0D2l4Sz2e8zrBOTyv4Hlats8Q!!/dz/d5/L2dBISEvZ0FBIS9nQSEh/
A10: Banco de Occidente | B10: 14.9 | C10: =IFERROR(_xlfn.RANK.EQ(B10,$B$8:$B$19,1),0) -> 5 | D10: 14.9 | E10: =IFERROR(_xlfn.RANK.EQ(D10,$D$8:$D$19,1),0) -> 1 | F10: 21.7 | G10: =IFERROR(_xlfn.RANK.EQ(F10,$F$8:$F$19,1),0) -> 4 | H10: 18.86 | I10: =IFERROR(_xlfn.RANK.EQ(H10,$H$8:$H$19,1),0) -> 4 | J10: 34.83 | K10: =IFERROR(_xlfn.RANK.EQ(J10,$J$8:$J$19,1),0) -> 6 | L10: 19.84 | M10: =IFERROR(_xlfn.RANK.EQ(L10,$L$8:$L$19,1),0) -> 5 | N10: 21.7 | O10: =IFERROR(_xlfn.RANK.EQ(N10,$N$8:$N$19,1),0) -> 1 | P10: =VLOOKUP(A10,Hoja1!$A$3:$B$19,2,0) -> https://www.bancodeoccidente.com.co/wps/wcm/connect/banco-de-occidente/c24390e8-b984-44de-b427-e59ff152a22c/tasas-personas-2022.pdf?MOD=AJPERES&CVID=o7LgirB
A11: Banco Caja Social S.A. | B11: 14.5 | C11: =IFERROR(_xlfn.RANK.EQ(B11,$B$8:$B$19,1),0) -> 4 | D11: 15.6 | E11: =IFERROR(_xlfn.RANK.EQ(D11,$D$8:$D$19,1),0) -> 5 | F11: 18.8 | G11: =IFERROR(_xlfn.RANK.EQ(F11,$F$8:$F$19,1),0) -> 3 | H11: 19.84 | I11: =IFERROR(_xlfn.RANK.EQ(H11,$H$8:$H$19,1),0) -> 5 | J11: 33.7 | K11: =IFERROR(_xlfn.RANK.EQ(J11,$J$8:$J$19,1),0) -> 2 | L11: N/A | M11: =IFERROR(_xlfn.RANK.EQ(L11,$L$8:$L$19,1),0) -> 0 | N11: 33.7 | O11: =IFERROR(_xlfn.RANK.EQ(N11,$N$8:$N$19,1),0) -> 5 | P11: =VLOOKUP(A11,Hoja1!$A$3:$B$19,2,0) -> https://www.bancocajasocial.com/portalserver/tasas-precios-y-comisiones
A12: Bancolombia | B12: 15.15 | C12: =IFERROR(_xlfn.RANK.EQ(B12,$B$8:$B$19,1),0) -> 7 | D12: 15.95 | E12: =IFERROR(_xlfn.RANK.EQ(D12,$D$8:$D$19,1),0) -> 6 | F12: 17.31 | G12: =IFERROR(_xlfn.RANK.EQ(F12,$F$8:$F$19,1),0) -> 1 | H12: 16.9 | I12: =IFERROR(_xlfn.RANK.EQ(H12,$H$8:$H$19,1),0) -> 1 | J12: 27.03 | K12: =IFERROR(_xlfn.RANK.EQ(J12,$J$8:$J$19,1),0) -> 1 | L12: 19.07 | M12: =IFERROR(_xlfn.RANK.EQ(L12,$L$8:$L$19,1),0) -> 3 | N12: 20.01 | O12: =IFERROR(_xlfn.RANK.EQ(N12,$N$8:$N$19,1),0) -> 0 | P12: =VLOOKUP(A12,Hoja1!$A$3:$B$19,2,0) -> https://www.bancolombia.com/personas/creditos/consumo/
A13: AV Villas | B13: 17.8 | C13: =IFERROR(_xlfn.RANK.EQ(B13,$B$8:$B$19,1),0) -> 10 | D13: 17.85 | E13: =IFERROR(_xlfn.RANK.EQ(D13,$D$8:$D$19,1),0) -> 10 | F13: 17.6 | G13: =IFERROR(_xlfn.RANK.EQ(F13,$F$8:$F$19,1),0) -> 2 | H13: N/A | I13: =IFERROR(_xlfn.RANK.EQ(H13,$H$8:$H$19,1),0) -> 0 | J13: 34.68 | K13: =IFERROR(_xlfn.RANK.EQ(J13,$J$8:$J$19,1),0) -> 4 | L13: 17.3 | M13: =IFERROR(_xlfn.RANK.EQ(L13,$L$8:$L$19,1),0) -> 1 | N13: N/A | O13: =IFERROR(_xlfn.RANK.EQ(N13,$N$8:$N$19,1),0) -> 0 | P13: =VLOOKUP(A13,Hoja1!$A$3:$B$19,2,0) -> https://www.avvillas.com.co/wps/portal/avvillas/banco/banca-personal/tasas-tarifas-personas/
A14: Scotiabank Colpatria S.A. | B14: 14.3 | C14: =IFERROR(_xlfn.RANK.EQ(B14,$B$8:$B$19,1),0) -> 3 | D14: 17.31 | E14: =IFERROR(_xlfn.RANK.EQ(D14,$D$8:$D$19,1),0) -> 7 | F14: 25.66 | G14: =IFERROR(_xlfn.RANK.EQ(F14,$F$8:$F$19,1),0) -> 7 | H14: N/A | I14: =IFERROR(_xlfn.RANK.EQ(H14,$H$8:$H$19,1),0) -> 0 | J14: 34.94 | K14: =IFERROR(_xlfn.RANK.EQ(J14,$J$8:$J$19,1),0) -> 7 | L14: N/A | M14: =IFERROR(_xlfn.RANK.EQ(L14,$L$8:$L$19,1),0) -> 0 | N14: 34.97 | O14: =IFERROR(_xlfn.RANK.EQ(N14,$N$8:$N$19,1),0) -> 8 | P14: =VLOOKUP(A14,Hoja1!$A$3:$B$19,2,0) -> https://www.scotiabankcolpatria.com/tasas-y-tarifas
A15: Itaú | B15: 15.34 | C15: =IFERROR(_xlfn.RANK.EQ(B15,$B$8:$B$19,1),0) -> 8 | D15: 15.34 | E15: =IFERROR(_xlfn.RANK.EQ(D15,$D$8:$D$19,1),0) -> 3 | F15: 22.27 | G15: =IFERROR(_xlfn.RANK.EQ(F15,$F$8:$F$19,1),0) -> 6 | H15: 21.69 | I15: =IFERROR(_xlfn.RANK.EQ(H15,$H$8:$H$19,1),0) -> 8 | J15: 34.95 | K15: =IFERROR(_xlfn.RANK.EQ(J15,$J$8:$J$19,1),0) -> 9 | L15: 24.3 | M15: =IFERROR(_xlfn.RANK.EQ(L15,$L$8:$L$19,1),0) -> 9 | N15: 31.528 | O15: =IFERROR(_xlfn.RANK.EQ(N15,$N$8:$N$19,1),0) -> 3 | P15: =VLOOKUP(A15,Hoja1!$A$3:$B$19,2,0) -> https://banco.itau.co/web/personas/informacion-de-interes/tasas-y-tarifas
A16: Banco de Bogotá | B16: 15.12 | C16: =IFERROR(_xlfn.RANK.EQ(B16,$B$8:$B$19,1),0) -> 6 | D16: 15.39 | E16: =IFERROR(_xlfn.RANK.EQ(D16,$D$8:$D$19,1),0) -> 4 | F16: 31.34 | G16: =IFERROR(_xlfn.RANK.EQ(F16,$F$8:$F$19,1),0) -> 12 | H16: 21.13 | I16: =IFERROR(_xlfn.RANK.EQ(H16,$H$8:$H$19,1),0) -> 6 | J16: 34.98 | K16: =IFERROR(_xlfn.RANK.EQ(J16,$J$8:$J$19,1),0) -> 11 | L16: 23.44 | M16: =IFERROR(_xlfn.RANK.EQ(L16,$L$8:$L$19,1),0) -> 8 | N16: 34.88 | O16: =IFERROR(_xlfn.RANK.EQ(N16,$N$8:$N$19,1),0) -> 7 | P16: =VLOOKUP(A16,Hoja1!$A$3:$B$19,2,0) -> https://www.bancodebogota.com/wps/portal/banco-de-bogota/bogota/productos/para-ti/tasas-y-tarifas/tasas-2023
A17: Banco Serfinanza S.A. | B17: N/A | C17: =IFERROR(_xlfn.RANK.EQ(B17,$B$8:$B$19,1),0) -> 0 | D17: N/A | E17: =IFERROR(_xlfn.RANK.EQ(D17,$D$8:$D$19,1),0) -> 0 | F17: 29.84 | G17: =IFERROR(_xlfn.RANK.EQ(F17,$F$8:$F$19,1),0) -> 11 | H17: 23.73 | I17: =IFERROR(_xlfn.RANK.EQ(H17,$H$8:$H$19,1),0) -> 9 | J17: 34.65 | K17: =IFERROR(_xlfn.RANK.EQ(J17,$J$8:$J$19,1),0) -> 3 | L17: 22.28 | M17: =IFERROR(_xlfn.RANK.EQ(L17,$L$8:$L$19,1),0) -> 6 | N17: 26.82 | O17: =IFERROR(_xlfn.RANK.EQ(N17,$N$8:$N$19,1),0) -> 2 | P17: https://bancoserfinanza.com/servicio-al-cliente/tasas/
A18: Banco Popular | B18: 17.55 | C18: =IFERROR(_xlfn.RANK.EQ(B18,$B$8:$B$19,1),0) -> 9 | D18: 17.55 | E18: =IFERROR(_xlfn.RANK.EQ(D18,$D$8:$D$19,1),0) -> 8 | F18: 26.82 | G18: =IFERROR(_xlfn.RANK.EQ(F18,$F$8:$F$19,1),0) -> 9 | H18: N/A | I18: =IFERROR(_xlfn.RANK.EQ(H18,$H$8:$H$19,1),0) -> 0 | J18: 34.94 | K18: =IFERROR(_xlfn.RANK.EQ(J18,$J$8:$J$19,1),0) -> 7 | L18: 23.43 | M18: =IFERROR(_xlfn.RANK.EQ(L18,$L$8:$L$19,1),0) -> 7 | N18: N/A | O18: =IFERROR(_xlfn.RANK.EQ(N18,$N$8:$N$19,1),0) -> 0 | P18: =VLOOKUP(A18,Hoja1!$A$3:$B$19,2,0) -> https://www.bancopopular.com.co/wps/portal/bancopopular/inicio/informacion-interes/tasas
A19: Pichincha | B19: N/A | C19: =IFERROR(_xlfn.RANK.EQ(B19,$B$8:$B$19,1),0) -> 0 | D19: N/A | E19: =IFERROR(_xlfn.RANK.EQ(D19,$D$8:$D$19,1),0) -> 0 | F19: 26.97 | G19: =IFERROR(_xlfn.RANK.EQ(F19,$F$8:$F$19,1),0) -> 10 | H19: 21.54 | I19: =IFERROR(_xlfn.RANK.EQ(H19,$H$8:$H$19,1),0) -> 7 | J19: 34.96 | K19: =IFERROR(_xlfn.RANK.EQ(J19,$J$8:$J$19,1),0) -> 10 | L19: 25.93 | M19: =IFERROR(_xlfn.RANK.EQ(L19,$L$8:$L$19,1),0) -> 10 | N19: 34.98 | O19: =IFERROR(_xlfn.RANK.EQ(N19,$N$8:$N$19,1),0) -> 9 | P19: =VLOOKUP(A19,Hoja1!$A$3:$B$19,2,0) -> https://www.bancopichincha.com.co/web/corporativo/tasas-y-tarifas
A20: Cooperativas Financieras | B20: Tasa | C20: Ranking | D20: Tasa | E20: Ranking | F20: Tasa | G20: Ranking | H20: Tasa | I20: Ranking | J20: Tasa | K20: Ranking | L20: Tasa | M20: Ranking | N20: Tasa | O20: Ranking
A21: PRESENTE | B21: =B8 -> 13.19 | C21: =IFERROR(_xlfn.RANK.EQ(B21,$B$21:$B$27,1),0) -> 1 | D21: =D8 -> 15.25 | E21: =IFERROR(_xlfn.RANK.EQ(D21,$D$21:$D$27,1),0) -> 1 | F21: =F8 -> 26.68 | G21: =IFERROR(_xlfn.RANK.EQ(F21,$F$21:$F$27,1),0) -> 3 | H21: =H8 -> 18.3 | I21: =IFERROR(_xlfn.RANK.EQ(H21,$H$21:$H$27,1),0) -> 1 | J21: =J8 -> 36.87 | K21: =IFERROR(_xlfn.RANK.EQ(J21,$J$21:$J$27,1),0) -> 2 | L21: =L8 -> 19.52 | M21: =IFERROR(_xlfn.RANK.EQ(L21,$L$21:$L$27,1),0) -> 1 | N21: =N8 -> 34.65 | O21: =IFERROR(_xlfn.RANK.EQ(N21,$N$21:$N$27,1),0) -> 4
A22: Cotrafa | B22: 16.77 | C22: =IFERROR(_xlfn.RANK.EQ(B22,$B$21:$B$27,1),0) -> 2 | D22: 20.98 | E22: =IFERROR(_xlfn.RANK.EQ(D22,$D$21:$D$27,1),0) -> 3 | F22: 18.86 | G22: =IFERROR(_xlfn.RANK.EQ(F22,$F$21:$F$27,1),0) -> 1 | H22: N/A | I22: =IFERROR(_xlfn.RANK.EQ(H22,$H$21:$H$27,1),0) -> 0 | J22: N/A | K22: =IFERROR(_xlfn.RANK.EQ(J22,$J$21:$J$27,1),0) -> 0 | L22: N/A | M22: =IFERROR(_xlfn.RANK.EQ(L22,$L$21:$L$27,1),0) -> 0 | N22: 34.48 | O22: =IFERROR(_xlfn.RANK.EQ(N22,$N$22:$N$27,1),0) -> 3 | P22: =VLOOKUP(A22,Hoja1!$A$3:$B$19,2,0) -> https://www.cotrafa.com.co/portafolio-de-credito
A23: Confiar | B23: 17 | C23: =IFERROR(_xlfn.RANK.EQ(B23,$B$21:$B$27,1),0) -> 3 | D23: 17 | E23: =IFERROR(_xlfn.RANK.EQ(D23,$D$21:$D$27,1),0) -> 2 | F23: 21.9 | G23: =IFERROR(_xlfn.RANK.EQ(F23,$F$21:$F$27,1),0) -> 2 | H23: N/A | I23: =IFERROR(_xlfn.RANK.EQ(H23,$H$21:$H$27,1),0) -> 0 | J23: 28 | K23: =IFERROR(_xlfn.RANK.EQ(J23,$J$21:$J$27,1),0) -> 1 | L23: 23.8 | M23: =IFERROR(_xlfn.RANK.EQ(L23,$L$21:$L$27,1),0) -> 2 | N23: N/A | O23: =IFERROR(_xlfn.RANK.EQ(N23,$N$22:$N$27,1),0) -> 0 | P23: =VLOOKUP(A23,Hoja1!$A$3:$B$19,2,0) -> https://www.confiar.coop/personas/productos/credito/credito-para-comprar-vivienda/
A24: Coopetraban | B24: 22.42 | C24: =IFERROR(_xlfn.RANK.EQ(B24,$B$21:$B$27,1),0) -> 4 | D24: 22.42 | E24: =IFERROR(_xlfn.RANK.EQ(D24,$D$21:$D$27,1),0) -> 4 | F24: 28.32 | G24: =IFERROR(_xlfn.RANK.EQ(F24,$F$21:$F$27,1),0) -> 4 | H24: 22.42 | I24: =IFERROR(_xlfn.RANK.EQ(H24,$H$21:$H$27,1),0) -> 2 | J24: N/A | K24: =IFERROR(_xlfn.RANK.EQ(J24,$J$21:$J$27,1),0) -> 0 | L24: N/A | M24: =IFERROR(_xlfn.RANK.EQ(L24,$L$21:$L$27,1),0) -> 0 | N24: 27.57 | O24: =IFERROR(_xlfn.RANK.EQ(N24,$N$22:$N$27,1),0) -> 2 | P24: =VLOOKUP(A24,Hoja1!$A$3:$B$19,2,0) -> https://www.coopetraban.com.co/tasas-de-interes-para-credito/
A25: Cooperativa Financiera de Antioquia | B25: N/A | C25: =IFERROR(_xlfn.RANK.EQ(B25,$B$21:$B$27,1),0) -> 0 | D25: 22.71 | E25: =IFERROR(_xlfn.RANK.EQ(D25,$D$21:$D$27,1),0) -> 5 | F25: 36.81 | G25: =IFERROR(_xlfn.RANK.EQ(F25,$F$21:$F$27,1),0) -> 5 | H25: 28.24 | I25: =IFERROR(_xlfn.RANK.EQ(H25,$H$21:$H$27,1),0) -> 3 | J25: N/A | K25: =IFERROR(_xlfn.RANK.EQ(J25,$J$21:$J$27,1),0) -> 0 | L25: N/A | M25: =IFERROR(_xlfn.RANK.EQ(L25,$L$21:$L$27,1),0) -> 0 | N25: 26.72 | O25: =IFERROR(_xlfn.RANK.EQ(N25,$N$22:$N$27,1),0) -> 1 | P25: =VLOOKUP(A25,Hoja1!$A$3:$B$19,2,0) -> https://www.cfa.com.co/tasas-de-colocacion/
A26: Financiera Juriscoop C.F. | C26: =IFERROR(_xlfn.RANK.EQ(B26,$B$21:$B$27,1),0) -> 0 | E26: =IFERROR(_xlfn.RANK.EQ(D26,$D$21:$D$27,1),0) -> 0 | G26: =IFERROR(_xlfn.RANK.EQ(F26,$F$21:$F$27,1),0) -> 0 | I26: =IFERROR(_xlfn.RANK.EQ(H26,$H$21:$H$27,1),0) -> 0 | K26: =IFERROR(_xlfn.RANK.EQ(J26,$J$21:$J$27,1),0) -> 0 | M26: =IFERROR(_xlfn.RANK.EQ(L26,$L$21:$L$27,1),0) -> 0 | O26: =IFERROR(_xlfn.RANK.EQ(N26,$N$22:$N$27,1),0) -> 0 | P26: =VLOOKUP(A26,Hoja1!$A$3:$B$19,2,0) -> https://financierajuriscoop.com.co/tasas-y-tarifas
A27: JFK Cooperativa Financiera | C27: =IFERROR(_xlfn.RANK.EQ(B27,$B$21:$B$27,1),0) -> 0 | E27: =IFERROR(_xlfn.RANK.EQ(D27,$D$21:$D$27,1),0) -> 0 | G27: =IFERROR(_xlfn.RANK.EQ(F27,$F$21:$F$27,1),0) -> 0 | I27: =IFERROR(_xlfn.RANK.EQ(H27,$H$21:$H$27,1),0) -> 0 | K27: =IFERROR(_xlfn.RANK.EQ(J27,$J$21:$J$27,1),0) -> 0 | M27: =IFERROR(_xlfn.RANK.EQ(L27,$L$21:$L$27,1),0) -> 0 | O27: =IFERROR(_xlfn.RANK.EQ(N27,$N$22:$N$27,1),0) -> 0 | P27: =VLOOKUP(A27,Hoja1!$A$3:$B$19,2,0) -> https://www.jfk.com.co/credito/tasas
Q28: 11.151274
A29: conversión Coopetraban | B29: =(1+1.8%)^(12/1)-1 -> 0.23872053 | P29: 0.116189 | Q29: =EFFECT(P29,12) -> 0.12258056
A30: NOMBRE ENTIDAD | F30: CONSUMO (T.E.A.) | Q30: 12.258056
F31: LIBRE INVERSION | H31: VEHICULO | J31: TARJETA | L31: COMPRA CARTERA | N31: CREDITOS ROTATIVOS
A32: Entidad Bancaria | F32: Tasa | G32: Ranking | H32: Tasa | I32: Ranking | J32: Tasa | K32: Ranking | L32: Tasa | M32: Ranking | N32: Tasa | O32: Ranking
A33: PRESENTE | F33: =VLOOKUP(A33,$A$5:$O$27,6,0)+F55 -> 29.18 | G33: =IFERROR(_xlfn.RANK.EQ(F33,$F$33:$F$44,1),0) -> 10 | H33: =VLOOKUP(A33,$A$5:$O$27,8,0)+H55 -> 20.8 | I33: =IFERROR(_xlfn.RANK.EQ(H33,$H$33:$H$44,1),0) -> 5 | J33: =VLOOKUP(A33,$A$5:$O$27,10,0)+J55 -> 39.37 | K33: =IFERROR(_xlfn.RANK.EQ(J33,$J$33:$J$44,1),0) -> 12 | L33: =VLOOKUP(A33,$A$5:$O$27,12,0)+L55 -> 22.02 | M33: =IFERROR(_xlfn.RANK.EQ(L33,$L$33:$L$44,1),0) -> 5 | N33: =VLOOKUP(A33,$A$5:$O$27,14,0)+N55 -> 34.65 | O33: =IFERROR(_xlfn.RANK.EQ(N33,$N$33:$N$52,1),0) -> 10
A34: Banco de Occidente | F34: =IFERROR(VLOOKUP(A34,$A$5:$O$27,6,0),0) -> 21.7 | G34: =IFERROR(_xlfn.RANK.EQ(F34,$F$33:$F$44,1),0) -> 4 | H34: =VLOOKUP(A34,$A$5:$O$27,8,0) -> 18.86 | I34: =IFERROR(_xlfn.RANK.EQ(H34,$H$33:$H$44,1),0) -> 3 | J34: =VLOOKUP(A34,$A$5:$O$27,10,0) -> 34.83 | K34: =IFERROR(_xlfn.RANK.EQ(J34,$J$33:$J$44,1),0) -> 6 | L34: =VLOOKUP(A34,$A$5:$O$27,12,0) -> 19.84 | M34: =IFERROR(_xlfn.RANK.EQ(L34,$L$33:$L$44,1),0) -> 4 | N34: =VLOOKUP(A34,$A$5:$O$27,14,0) -> 21.7 | O34: =IFERROR(_xlfn.RANK.EQ(N34,$N$33:$N$52,1),0) -> 3
A35: Banco Caja Social S.A. | F35: =IFERROR(VLOOKUP(A35,$A$5:$O$27,6,0),0) -> 18.8 | G35: =IFERROR(_xlfn.RANK.EQ(F35,$F$33:$F$44,1),0) -> 3 | H35: =VLOOKUP(A35,$A$5:$O$27,8,0) -> 19.84 | I35: =IFERROR(_xlfn.RANK.EQ(H35,$H$33:$H$44,1),0) -> 4 | J35: =VLOOKUP(A35,$A$5:$O$27,10,0) -> 33.7 | K35: =IFERROR(_xlfn.RANK.EQ(J35,$J$33:$J$44,1),0) -> 2 | L35: =VLOOKUP(A35,$A$5:$O$27,12,0) -> N/A | M35: =IFERROR(_xlfn.RANK.EQ(L35,$L$33:$L$44,1),0) -> 0 | N35: =VLOOKUP(A35,$A$5:$O$27,14,0) -> 33.7 | O35: =IFERROR(_xlfn.RANK.EQ(N35,$N$33:$N$52,1),0) -> 8
A36: Banco Davivienda | F36: =IFERROR(VLOOKUP(A36,$A$5:$O$27,6,0),0) -> 21.98 | G36: =IFERROR(_xlfn.RANK.EQ(F36,$F$33:$F$44,1),0) -> 5 | H36: =VLOOKUP(A36,$A$5:$O$27,8,0) -> 17.74 | I36: =IFERROR(_xlfn.RANK.EQ(H36,$H$33:$H$44,1),0) -> 2 | J36: =VLOOKUP(A36,$A$5:$O$27,10,0) -> 34.8 | K36: =IFERROR(_xlfn.RANK.EQ(J36,$J$33:$J$44,1),0) -> 5 | L36: =VLOOKUP(A36,$A$5:$O$27,12,0) -> 18.85 | M36: =IFERROR(_xlfn.RANK.EQ(L36,$L$33:$L$44,1),0) -> 2 | N36: =VLOOKUP(A36,$A$5:$O$27,14,0) -> 33.54 | O36: =IFERROR(_xlfn.RANK.EQ(N36,$N$33:$N$52,1),0) -> 7
A37: Bancolombia | F37: =IFERROR(VLOOKUP(A37,$A$5:$O$27,6,0),0) -> 17.31 | G37: =IFERROR(_xlfn.RANK.EQ(F37,$F$33:$F$44,1),0) -> 1 | H37: =VLOOKUP(A37,$A$5:$O$27,8,0) -> 16.9 | I37: =IFERROR(_xlfn.RANK.EQ(H37,$H$33:$H$44,1),0) -> 1 | J37: =VLOOKUP(A37,$A$5:$O$27,10,0) -> 27.03 | K37: =IFERROR(_xlfn.RANK.EQ(J37,$J$33:$J$44,1),0) -> 1 | L37: =VLOOKUP(A37,$A$5:$O$27,12,0) -> 19.07 | M37: =IFERROR(_xlfn.RANK.EQ(L37,$L$33:$L$44,1),0) -> 3 | N37: =VLOOKUP(A37,$A$5:$O$27,14,0) -> 20.01 | O37: =IFERROR(_xlfn.RANK.EQ(N37,$N$33:$N$52,1),0) -> 0
A38: AV Villas | F38: =IFERROR(VLOOKUP(A38,$A$5:$O$27,6,0),0) -> 17.6 | G38: =IFERROR(_xlfn.RANK.EQ(F38,$F$33:$F$44,1),0) -> 2 | H38: =VLOOKUP(A38,$A$5:$O$27,8,0) -> N/A | I38: =IFERROR(_xlfn.RANK.EQ(H38,$H$33:$H$44,1),0) -> 0 | J38: =VLOOKUP(A38,$A$5:$O$27,10,0) -> 34.68 | K38: =IFERROR(_xlfn.RANK.EQ(J38,$J$33:$J$44,1),0) -> 4 | L38: =VLOOKUP(A38,$A$5:$O$27,12,0) -> 17.3 | M38: =IFERROR(_xlfn.RANK.EQ(L38,$L$33:$L$44,1),0) -> 1 | N38: =VLOOKUP(A38,$A$5:$O$27,14,0) -> N/A | O38: =IFERROR(_xlfn.RANK.EQ(N38,$N$33:$N$52,1),0) -> 0
A39: Scotiabank Colpatria S.A. | F39: =IFERROR(VLOOKUP(A39,$A$5:$O$27,6,0),0) -> 25.66 | G39: =IFERROR(_xlfn.RANK.EQ(F39,$F$33:$F$44,1),0) -> 7 | H39: =VLOOKUP(A39,$A$5:$O$27,8,0) -> N/A | I39: =IFERROR(_xlfn.RANK.EQ(H39,$H$33:$H$44,1),0) -> 0 | J39: =VLOOKUP(A39,$A$5:$O$27,10,0) -> 34.94 | K39: =IFERROR(_xlfn.RANK.EQ(J39,$J$33:$J$44,1),0) -> 7 | L39: =VLOOKUP(A39,$A$5:$O$27,12,0) -> N/A | M39: =IFERROR(_xlfn.RANK.EQ(L39,$L$33:$L$44,1),0) -> 0 | N39: =VLOOKUP(A39,$A$5:$O$27,14,0) -> 34.97 | O39: =IFERROR(_xlfn.RANK.EQ(N39,$N$33:$N$52,1),0) -> 13
A40: Itaú | F40: =IFERROR(VLOOKUP(A40,$A$5:$O$27,6,0),0) -> 22.27 | G40: =IFERROR(_xlfn.RANK.EQ(F40,$F$33:$F$44,1),0) -> 6 | H40: =VLOOKUP(A40,$A$5:$O$27,8,0) -> 21.69 | I40: =IFERROR(_xlfn.RANK.EQ(H40,$H$33:$H$44,1),0) -> 8 | J40: =VLOOKUP(A40,$A$5:$O$27,10,0) -> 34.95 | K40: =IFERROR(_xlfn.RANK.EQ(J40,$J$33:$J$44,1),0) -> 9 | L40: =VLOOKUP(A40,$A$5:$O$27,12,0) -> 24.3 | M40: =IFERROR(_xlfn.RANK.EQ(L40,$L$33:$L$44,1),0) -> 9 | N40: =VLOOKUP(A40,$A$5:$O$27,14,0) -> 31.528 | O40: =IFERROR(_xlfn.RANK.EQ(N40,$N$33:$N$52,1),0) -> 6
A41: Banco de Bogotá | F41: =IFERROR(VLOOKUP(A41,$A$5:$O$27,6,0),0) -> 31.34 | G41: =IFERROR(_xlfn.RANK.EQ(F41,$F$33:$F$44,1),0) -> 12 | H41: =VLOOKUP(A41,$A$5:$O$27,8,0) -> 21.13 | I41: =IFERROR(_xlfn.RANK.EQ(H41,$H$33:$H$44,1),0) -> 6 | J41: =VLOOKUP(A41,$A$5:$O$27,10,0) -> 34.98 | K41: =IFERROR(_xlfn.RANK.EQ(J41,$J$33:$J$44,1),0) -> 11 | L41: =VLOOKUP(A41,$A$5:$O$27,12,0) -> 23.44 | M41: =IFERROR(_xlfn.RANK.EQ(L41,$L$33:$L$44,1),0) -> 8 | N41: =VLOOKUP(A41,$A$5:$O$27,14,0) -> 34.88 | O41: =IFERROR(_xlfn.RANK.EQ(N41,$N$33:$N$52,1),0) -> 12
...

Sheet Historico
B3: Entidades | C3: VIS | D3: NO VIS | E3: LIBRE INVERSION | F3: VEHICULO | G3: TARJETA | H3: COMPRA CARTERA | I3: CREDITOS ROTATIVOS
B4: Bancos | C4: =AVERAGE('Cartera Créditos - E'!B9:B19) -> 15.406667 | D4: =AVERAGE('Cartera Créditos - E'!D9:D19) -> 16.387778 | E4: =AVERAGE('Cartera Créditos - E'!F9:F19) -> 23.662727 | F4: =AVERAGE('Cartera Créditos - E'!H9:H19) -> 20.17875 | G4: =AVERAGE('Cartera Créditos - E'!J9:J19) -> 34.041818 | H4: =AVERAGE('Cartera Créditos - E'!L9:L19) -> 21.604444 | I4: =AVERAGE('Cartera Créditos - E'!N9:N19) -> 31.51475
B5: Cooperativas Financieras | C5: =AVERAGE('Cartera Créditos - E'!B22:B27) -> 18.73 | D5: =AVERAGE('Cartera Créditos - E'!D22:D27) -> 20.7775 | E5: =AVERAGE('Cartera Créditos - E'!F22:F27) -> 26.4725 | F5: =AVERAGE('Cartera Créditos - E'!H22:H27) -> 25.33 | G5: =AVERAGE('Cartera Créditos - E'!J22:J27) -> 28 | H5: =AVERAGE('Cartera Créditos - E'!L22:L27) -> 23.8 | I5: =AVERAGE('Cartera Créditos - E'!N22:N27) -> 29.59
B6: PRESENTE | C6: 14.15 | D6: 16.96 | E6: 28.03 | F6: 18.27 | G6: 38.19 | H6: 19.52 | I6: 38.19

Sheet Cartera Créditos - E (2)
B1: INFORME DE TASAS DE CARTELERA POR MODALIDAD DE CRÉDITO
B2: Tasas efectivas anuales
D3: 44743
B4: vis | D4: no vis | E4: 7 | F4: 14 | H4: 17
A5: NOMBRE ENTIDAD | B5: VIVIENDA en Pesos (T.E.A.) | F5: CONSUMO
B6: VIS | D6: NO VIS | F6: LIBRE INVERSION | H6: TARJETA | J6: fuente | K6: fuente | L6: fuente
B7: Tasa | C7: Ranking | D7: Tasa | E7: Ranking | F7: Tasa | G7: Ranking | H7: Tasa | I7: Ranking
A8: PRESENTE | B8: =M31*100 -> 0 | C8: =IFERROR(_xlfn.RANK.EQ(B8,$B$8:$B$20,1),0) -> 1 | D8: 11.6 | E8: =IFERROR(_xlfn.RANK.EQ(D8,$D$8:$D$20,1),0) -> 2 | F8: =(19.64) -> 19.64 | G8: =IFERROR(_xlfn.RANK.EQ(F8,$F$8:$F$20,1),0) -> 7 | H8: =22.03 -> 22.03 | I8: =IFERROR(_xlfn.RANK.EQ(H8,$H$8:$H$20,1),0) -> 1 | J8: reglamento de crédito
A9: Banco de Occidente | B9: 11.85 | C9: =IFERROR(_xlfn.RANK.EQ(B9,$B$8:$B$20,1),0) -> 2 | D9: 11.85 | E9: =IFERROR(_xlfn.RANK.EQ(D9,$D$8:$D$20,1),0) -> 3 | F9: 17.04 | G9: =IFERROR(_xlfn.RANK.EQ(F9,$F$8:$F$20,1),0) -> 4 | H9: 31.77 | I9: =IFERROR(_xlfn.RANK.EQ(H9,$H$8:$H$20,1),0) -> 5 | J9: https://www.bancodeoccidente.com.co/wps/wcm/connect/banco-de-occidente/c24390e8-b984-44de-b427-e59ff152a22c/tasas-personas-2022.pdf?MOD=AJPERES&CVID=o7LgirB
A10: Banco Davivienda | B10: 12 | C10: =IFERROR(_xlfn.RANK.EQ(B10,$B$8:$B$20,1),0) -> 3 | D10: 12.8 | E10: =IFERROR(_xlfn.RANK.EQ(D10,$D$8:$D$20,1),0) -> 7 | F10: 29.53 | G10: =IFERROR(_xlfn.RANK.EQ(F10,$F$8:$F$20,1),0) -> 11 | H10: 31.68 | I10: =IFERROR(_xlfn.RANK.EQ(H10,$H$8:$H$20,1),0) -> 4 | J10: https://www.davivienda.com/wps/wcm/connect/personas/0e0c4565-6984-4ffe-b66e-7e5822271871/TASAS+TARIFAS+DAVIVIENDA+13+07+2022.pdf?MOD=AJPERES&CVID=o7U4EW7
A11: Cotrafa | B11: 12.01 | C11: =IFERROR(_xlfn.RANK.EQ(B11,$B$8:$B$20,1),0) -> 4 | D11: 12.55 | E11: =IFERROR(_xlfn.RANK.EQ(D11,$D$8:$D$20,1),0) -> 5 | F11: 19.56 | G11: =IFERROR(_xlfn.RANK.EQ(F11,$F$8:$F$20,1),0) -> 6 | H11: N/A | I11: =IFERROR(_xlfn.RANK.EQ(H11,$H$8:$H$20,1),0) -> 0 | J11: https://www.cotrafa.com.co/portafolio-de-credito
A12: Bancolombia | B12: 12.05 | C12: =IFERROR(_xlfn.RANK.EQ(B12,$B$8:$B$20,1),0) -> 5 | D12: 11.35 | E12: =IFERROR(_xlfn.RANK.EQ(D12,$D$8:$D$20,1),0) -> 1 | F12: 15.47 | G12: =IFERROR(_xlfn.RANK.EQ(F12,$F$8:$F$20,1),0) -> 2 | H12: 31.85 | I12: =IFERROR(_xlfn.RANK.EQ(H12,$H$8:$H$20,1),0) -> 6 | J12: https://www.bancodebogota.com/wps/themes/html/banco-de-bogota/pdf/productos-para-ti/tasas/2022/tasas-julio-2022.pdf
A13: Confiar | B13: 13.25 | C13: =IFERROR(_xlfn.RANK.EQ(B13,$B$8:$B$20,1),0) -> 6 | D13: N/A | E13: =IFERROR(_xlfn.RANK.EQ(D13,$D$8:$D$20,1),0) -> 0 | F13: 15.25 | G13: =IFERROR(_xlfn.RANK.EQ(F13,$F$8:$F$20,1),0) -> 1 | H13: 25.5 | I13: =IFERROR(_xlfn.RANK.EQ(H13,$H$8:$H$20,1),0) -> 2 | J13: https://www.bancopopular.com.co/wps/portal/bancopopular/inicio/informacion-interes/tasas | K13: https://www.bancolombia.com/personas/creditos/vivienda/credito-hipotecario-para-comprar-vivienda | L13: https://www.bancolombia.com/wcm/connect/5ffe2810-677d-43d2-96af-5a7235732704/07.Formato+consolidado+tasas+mensual+web+julio.pdf?MOD=AJPERES
