Workbook

Sheet Hoja1
A1: Mes | B1: Saldo total pasivos | C1: CDATs | D1: Ahorros Programados | E1: Ahorro Futuro | F1: Ahorros disponibles
A2: 44197 | B2: 115326.09 | C2: 73465.214 | D2: 10715.623 | F2: 31145.258
A3: 44228 | B3: 117671.71 | C3: 73772.071 | D3: 12802.952 | F3: 31096.686 | H3: Saldos Total Pasivos | L3: (se coloca en ppt)
A4: 44256 | B4: 123182.03 | C4: 74767.065 | D4: 14401.299 | F4: 34013.666
A5: 44287 | B5: 126697.75 | C5: 75881.323 | D5: 12282.455 | F5: 38533.969
A6: 44317 | B6: 130038.22 | C6: 76659.537 | D6: 14058.861 | F6: 39319.824
A7: 44348 | B7: 126681.17 | C7: 77468.472 | D7: 15849.704 | F7: 33362.993
A8: 44378 | B8: 126148.38 | C8: 77975.24 | D8: 17418.55 | F8: 30754.586
A9: 44409 | B9: 127282.91 | C9: 78706.551 | D9: 18977.502 | F9: 29598.855
A10: 44440 | B10: 129910.25 | C10: 80386.805 | D10: 20781.489 | F10: 28741.957
A11: 44470 | B11: 133036.42 | C11: 81623.998 | D11: 22134.823 | F11: 29277.598
A12: 44501 | B12: 147448.95 | C12: 82695.783 | D12: 7886.8415 | F12: 56866.324
A13: 44531 | B13: 125992.91 | C13: 79148.031 | D13: 9136.6101 | F13: 37708.27
A14: 44562 | B14: 125091.32 | C14: 81436.113 | D14: 10526.253 | F14: 33128.958
A15: 44593 | B15: 127021.53 | C15: 81607.054 | D15: 12582.863 | F15: 32831.615
... A25: 44896 | B25: 121164.38 | C25: 80687.644 | D25: 9058.6891 | F25: 31418.05
A26: 44927 | B26: 119283.92 | C26: 80695.194 | D26: 10538.672 | E26: 55034.263 | F26: 28050.051
A27: 44958 | B27: =+C27+D27+F27 -> 125011.66 | C27: 81073.982 | D27: 12827.258 | E27: 54434.305 | F27: 31110.419
A28: 44986 | B28: =+C28+D28+F28 -> 125378.33 | C28: 82634.711 | D28: 14388.775 | E28: 55172.233 | F28: 28354.839
A29: 45017 | B29: =+C29+D29+F29 -> 127634.47 | C29: 83229.723 | D29: 13038.809 | E29: 55929.897 | F29: 31365.942
A30: 45047 | B30: =+C30+D30+F30 -> 133896.26 | C30: 84032.611 | D30: 14494.992 | E30: 56059.554 | F30: 35368.658
A31: 45078 | B31: =+C31+D31+F31 -> 129692.17 | C31: 86121.546 | D31: 16689.804 | E31: 60222.902 | F31: 26880.822
A32: 45108 | B32: =+C32+D32+F32 -> 129758.17 | C32: 87260.803 | D32: 18288.248 | E32: 58665.088 | F32: 24209.12
A33: 45139 | B33: =+C33+D33+F33 -> 132228.45 | C33: 87102.781 | D33: 20014.3 | E33: 60783.081 | F33: 25111.372
A34: 45170 | B34: =+C34+D34+F34 -> 133134.96 | C34: 86266.348 | D34: 22131.72 | E34: 58702.29 | F34: 24736.893
A35: 45200 | B35: =+C35+D35+F35 -> 131587.51 | C35: 84746.958 | D35: 23592.291 | E35: 56535.423 | F35: 23248.264
A36: 45231 | B36: =+C36+D36+F36 -> 141522.24 | C36: 85474.425 | D36: 9947.7147 | E36: 58754.091 | F36: 46100.1
A37: 45261 | B37: =+C37+D37+E37+F37 -> 188005.8 | C37: 85038.37 | D37: 11207.772 | E37: 59203.979 | F37: 32555.675
A38: 45292 | B38: =+C38+D38+E38+F38 -> 187764.21 | C38: 86109.524 | D38: 12855.045 | E38: 59214.379 | F38: 29585.259
A39: 45323 | B39: =+C39+D39+E39+F39 -> 198973.4 | C39: 90581.596 | D39: 15200.213 | E39: 58754.18 | F39: 34437.408
A40: 45352 | B40: =+C40+D40+E40+F40 -> 198589.86 | C40: 89035.283 | D40: 16632.486 | E40: 58123.989 | F40: 34798.097
A41: 45383 | B41: =+C41+D41+E41+F41 -> 194584.7 | C41: 89901.62 | D41: 14920.796 | E41: 56911.791 | F41: 32850.496
A42: 45413 | B42: =+C42+D42+E42+F42 -> 191985.44 | C42: 90253.219 | D42: 15971.981 | E42: 56512.459 | F42: 29247.779
A43: 45444 | B43: =+C43+D43+E43+F43 -> 197118.25 | C43: 91133.023 | D43: 17668.677 | E43: 55984.563 | F43: 32331.988
A44: 45474 | B44: =+C44+D44+E44+F44 -> 195610.28 | C44: 90868.152 | D44: 18790.596 | E44: 55405.982 | F44: 30545.551
A45: 45505 | B45: =+C45+D45+E45+F45 -> 194749.66 | C45: 89989.976 | D45: 20195.294 | E45: 55250.081 | F45: 29314.306
A46: 45536 | B46: =+C46+D46+E46+F46 -> 193508.92 | C46: 90280.665 | D46: 22074.321 | E46: 54685.055 | F46: 26468.877
A47: 45566 | B47: =+C47+D47+E47+F47 -> 192628.95 | C47: 88235.778 | D47: 23069.178 | E47: 54017.928 | F47: 27306.063
A48: 45597 | B48: =+C48+D48+E48+F48 -> 207183.73 | C48: 87723.372 | D48: 9512.739 | E48: 53846.862 | F48: 56100.758
... A54: 45778 | B54: =+C54+D54+E54+F54 -> 198131.01 | C54: 93039.533 | D54: 16500.702 | E54: 52530.324 | F54: 36060.447
...

Sheet CDATS - TPP
A1: Mes | B1: Saldo CDATs | C1: Saldo Captación | D1: TPP CDAT | E1: TPP VISTA | F1: TPP contractual | G1: Total TPP captación | H1: Saldos cdats cancelados anticipadamente
A2: 44197 | B2: 73465.214 | C2: 115326.09 | D2: 6.56 | E2: 1.7 | F2: 3.38 | G2: 4.9520364 | H2: 30.582708 | I2: =H2/B2 -> 0.00041628829
A3: 44228 | B3: 73772.071 | C3: 117671.71 | D3: 6.5 | E3: 1.69 | F3: 3.35 | G3: 4.8861511 | H3: 573.47353 | I3: =H3/B3 -> 0.0077735858 | K3: TPP captación y Saldos | O3: (se coloca en ppt) | V3: TPP captación y Saldos | Z3: (se coloca en ppt)
A4: 44256 | B4: 74767.065 | C4: 123182.03 | D4: 6.4 | E4: 1.7096104 | F4: 3.328737 | G4: 4.7474236 | H4: 334.56443 | I4: =H4/B4 -> 0.0044747568
A5: 44287 | B5: 75881.323 | C5: 126697.75 | D5: 6.32 | E5: 1.74 | F5: 3.26 | G5: 4.6320305 | H5: 278.07418 | I5: =H5/B5 -> 0.0036645932
A6: 44317 | B6: 76659.537 | C6: 130038.22 | D6: 6.27 | E6: 1.6387898 | F6: 3.2539715 | G6: 4.543611 | H6: 625.48145 | I6: =H6/B6 -> 0.0081592125
A7: 44348 | B7: 77468.472 | C7: 126681.17 | D7: 6.23 | E7: 1.7066659 | F7: 3.2367188 | G7: 4.6575747 | H7: 304.873 | I7: =H7/B7 -> 0.0039354462
A8: 44378 | B8: 77975.24 | C8: 126148.38 | D8: 6.21 | E8: 1.7243771 | F8: 3.2245248 | G8: 4.7014058 | H8: 254.60268 | I8: =H8/B8 -> 0.0032651734
A9: 44409 | B9: 78706.551 | C9: 127282.91 | D9: 6.17 | E9: 1.7438466 | F9: 3.2264204 | G9: 4.7070513 | H9: 237.70465 | I9: =H9/B9 -> 0.0030201381
A10: 44440 | B10: 80386.805 | C10: 129910.25 | D10: 6.15 | E10: 1.7342278 | F10: 3.1340371 | G10: 4.6990321 | H10: 168.53287 | I10: =H10/B10 -> 0.002096524
A11: 44470 | B11: 81623.998 | C11: 133036.42 | D11: 6.14 | E11: 1.7700946 | F11: 3.1312065 | G11: 4.6825144 | H11: 210.48353 | I11: =H11/B11 -> 0.0025786966
A12: 44501 | B12: 82695.783 | C12: 147448.95 | D12: 6.12 | E12: 1.6594827 | F12: 3.279357 | G12: 4.2355509 | H12: 168.98781 | I12: =H12/B12 -> 0.0020434876
A13: 44531 | B13: 79148.031 | C13: 125992.91 | D13: 6.07 | E13: 1.74 | F13: 3.14 | G13: 4.561605 | H13: 209.752 | I13: =H13/B13 -> 0.0026501227
A14: 44562 | B14: 81436.113 | C14: 125091.32 | D14: 6.02 | E14: 1.7302522 | F14: 3.0868867 | G14: 4.6349706 | H14: 503.82923 | I14: =H14/B14 -> 0.0061868034
A15: 44593 | B15: 81607.054 | C15: 127021.53 | D15: 6.01 | E15: 1.7222671 | F15: 3.037097 | G15: 4.6088559 | H15: 140.48453 | I15: =H15/B15 -> 0.0017214753
... A25: 44896 | B25: 80687.644 | C25: 121164.38 | D25: 10.33 | E25: 1.6531287 | F25: 2.862783 | G25: 7.521802 | H25: 606.38477 | I25: =H25/B25 -> 0.0075152123
A26: 44927 | B26: 80695.194 | C26: 119283.92 | D26: 11.17 | E26: 1.6973565 | F26: 2.818665 | G26: 8.204637 | H26: 575.80769 | I26: =H26/B26 -> 0.0071355884 | K26: TPP captación y Saldos | O26: (se coloca en ppt)
A27: 44958 | B27: 81073.982 | C27: 125008.51 | D27: 11.713956 | E27: 1.63 | F27: 2.7950022 | G27: 8.2884696 | H27: 221.90776 | I27: =H27/B27 -> 0.002737102
A28: 44986 | B28: =+Hoja1!C28 -> 82634.711 | C28: =+Hoja1!B28 -> 125378.33 | D28: 12.26 | E28: 1.6806646 | F28: 2.7602118 | G28: 8.8974679 | H28: 172.72103 | I28: =H28/B28 -> 0.0020901753
A29: 45017 | B29: 83229.723 | C29: =+Hoja1!B29 -> 127634.47 | D29: 12.577691 | E29: 1.7171555 | F29: 2.8007797 | G29: 9.0655485 | H29: 474.14702 | I29: =H29/B29 -> 0.0056968473
A30: 45047 | B30: 84032.611 | C30: 133896.26 | D30: 12.835957 | E30: 1.5472735 | F30: 2.7845573 | G30: 8.7659361 | H30: 267.7862 | I30: =H30/B30 -> 0.0031866939
A31: 45078 | B31: =+Hoja1!C31 -> 86121.546 | C31: =+Hoja1!B31 -> 129692.17 | D31: 13.03 | E31: 1.63 | F31: 2.78 | G31: 9.3481135 | H31: 391.54471 | I31: =H31/B31 -> 0.0045464198
A32: 45108 | B32: =+Hoja1!C32 -> 87260.803 | C32: =+Hoja1!B32 -> 129758.17 | D32: 13.11 | E32: 1.64 | F32: 2.77 | G32: 9.5126998 | H32: 1092.0679 | I32: =H32/B32 -> 0.012514988
A33: 45139 | B33: =+Hoja1!C33 -> 87102.781 | C33: =+Hoja1!B33 -> 132228.45 | D33: 13.17 | E33: 1.67 | F33: 2.78 | G33: 9.4134004 | H33: 316.56074 | I33: =H33/B33 -> 0.0036343356
A34: 45170 | B34: =+Hoja1!C34 -> 86266.348 | C34: =+Hoja1!B34 -> 133134.96 | D34: 13.197407 | E34: 1.6857608 | F34: 2.7693172 | G34: 9.3249915 | H34: 450.91626 | I34: =H34/B34 -> 0.0052270239
A35: 45200 | B35: 84746.958 | C35: 131587.51 | D35: 13.203507 | E35: 1.6966877 | F35: 2.76396 | G35: 9.2988323 | H35: 196.35698 | I35: =H35/B35 -> 0.0023169797
A36: 45231 | B36: 85474.425 | C36: 141522.24 | D36: 13.170191 | E36: 1.5913699 | F36: 3.0183337 | G36: 8.3050135 | H36: 249.12222 | I36: =H36/B36 -> 0.002914582
A37: 45261 | B37: 85038.37 | C37: 188005.8 | D37: 13.037304 | E37: 1.6421746 | F37: 10.557359 | G37: 10.135301 | H37: 1103.5206 | I37: =H37/B37 -> 0.012976738
A38: 45292 | B38: 86109.524 | C38: 187764.21 | D38: 13.038457 | E38: 1.6574969 | F38: 10.377327 | G38: 10.223785 | H38: 499.27864 | I38: =H38/B38 -> 0.0057981814
A39: 45323 | B39: 90581.596 | C39: 198973.4 | D39: 12.860664 | E39: 1.6152096 | F39: 10.122738 | G39: 9.8967201 | H39: 360.73409 | I39: =H39/B39 -> 0.0039824214
A40: 45352 | B40: =+Hoja1!C40 -> 89035.283 | C40: =+Hoja1!B40 -> 198589.86 | D40: 12.684885 | E40: 1.7285759 | F40: 9.9614191 | G40: 9.7398434 | H40: =+'Cancelación Anticp'!C40 -> 4043.1305 | I40: =H40/B40 -> 0.045410429
A41: 45383 | B41: 89901.62 | C41: 194584.7 | D41: 12.410821 | E41: 1.687276 | F41: 10.10577 | G41: 9.7495042 | H41: 206.32628 | I41: =H41/B41 -> 0.002295023
A42: 45413 | B42: 90253.219 | C42: 191985.44 | D42: 12.12864 | E42: 1.6941053 | F42: 9.9850649 | G42: 9.7296935 | H42: 307.3901 | I42: =H42/B42 -> 0.003405863
A43: 45444 | B43: 91133.023 | C43: 197118.25 | D43: 11.805198 | E43: 1.6330804 | F43: 8.4174594 | G43: 8.8709049 | H43: 160.6297 | I43: =H43/B43 -> 0.001762585
A44: 45474 | B44: 90868.152 | C44: 195610.28 | D44: 11.552063 | E44: 1.6695347 | F44: 8.7731808 | G44: 8.958315 | H44: 678.3231 | I44: =H44/B44 -> 0.0074649158
A45: 45505 | B45: =+Hoja1!C45 -> 89989.976 | C45: =+Hoja1!B45 -> 194749.66 | D45: 11.286619 | E45: 1.6971854 | F45: 8.23076 | G45: 8.6593588 | H45: 272.73854 | I45: =H45/B45 -> 0.0030307657
A46: 45536 | B46: =+Hoja1!C46 -> 90280.665 | C46: =+Hoja1!B46 -> 193508.92 | D46: 11.104272 | E46: 1.7070888 | F46: 7.7389709 | G46: 8.4839739 | H46: 48.185889 | I46: =H46/B46 -> 0.00053373431
A47: 45566 | B47: =+Hoja1!C47 -> 88235.778 | C47: =+Hoja1!B47 -> 192628.95 | D47: 10.934382 | E47: 1.7085968 | F47: 7.6528741 | G47: 8.3133748 | H47: 1361.5286 | I47: =H47/B47 -> 0.015430572
A48: 45597 | B48: =+Hoja1!C48 -> 87723.372 | C48: =+Hoja1!B48 -> 207183.73 | D48: 10.826615 | E48: 1.6177715 | F48: 8.7308308 | G48: 7.692145 | H48: 792.85436 | I48: =H48/B48 -> 0.00903812
A49: 45627 | B49: =+Hoja1!C49 -> 89551.243 | C49: =+Hoja1!B49 -> 187707.4 | D49: 10.562352 | E49: 1.650074 | F49: 8.62944 | G49: 8.2902905 | H49: 207.90637 | I49: =H49/B49 -> 0.002321647
...

Sheet Cancelación Anticp
A1: Mes | B1: Saldos CDAT | C1: CDATs cancelados anticipadamente | D1: % CDATs cancelados sobre saldo total | F1: Mes | G1: Saldos Ahorros programdos | H1: Ahorro programados cancelados anticipadamente | I1: % Ahorros cancelados sobre saldo total | K1: Mes | L1: Saldos Ahorros programdos | M1: Ahorro FUTURO cancelados anticipadamente | N1: % Ahorros cancelados sobre saldo total
A2: 44197 | B2: 73465.214 | C2: 30.582708 | D2: =+C2/B2 -> 0.00041628829 | F2: 44197 | G2: 10715.623 | H2: 15.835613 | I2: =+H2/G2 -> 0.0014778061 | K2: 44197
A3: 44228 | B3: 73772.071 | C3: 573.47353 | D3: =+C3/B3 -> 0.0077735858 | F3: 44228 | G3: 12802.952 | H3: 12.637 | I3: =+H3/G3 -> 0.00098703803 | K3: 44228
A4: 44256 | B4: 74767.065 | C4: 334.56443 | D4: =+C4/B4 -> 0.0044747568 | F4: 44256 | G4: 14401.299 | H4: 12.563 | I4: =+H4/G4 -> 0.00087235183 | K4: 44256
A5: 44287 | B5: 75881.323 | C5: 278.07418 | D5: =+C5/B5 -> 0.0036645932 | F5: 44287 | G5: 12282.455 | H5: 15.426565 | I5: =+H5/G5 -> 0.0012559838 | K5: 44287
A6: 44317 | B6: 76659.537 | C6: 625.48145 | D6: =+C6/B6 -> 0.0081592125 | F6: 44317 | G6: 14058.861 | H6: 12.316 | I6: =+H6/G6 -> 0.00087603114 | K6: 44317
A7: 44348 | B7: 77468.472 | C7: 304.873 | D7: =+C7/B7 -> 0.0039354462 | F7: 44348 | G7: 15849.704 | H7: 22.291884 | I7: =+H7/G7 -> 0.0014064543 | K7: 44348
A8: 44378 | B8: 77975.24 | C8: 254.60268 | D8: =+C8/B8 -> 0.0032651734 | F8: 44378 | G8: 17418.55 | H8: 26.017389 | I8: =+H8/G8 -> 0.0014936599 | K8: 44378
A9: 44409 | B9: 78706.551 | C9: 237.70465 | D9: =+C9/B9 -> 0.0030201381 | F9: 44409 | G9: 18977.502 | H9: 66.852285 | I9: =+H9/G9 -> 0.0035227125 | K9: 44409
A10: 44440 | B10: 80386.805 | C10: 168.53287 | D10: =+C10/B10 -> 0.002096524 | F10: 44440 | G10: 20781.489 | H10: 42.4535 | I10: =+H10/G10 -> 0.0020428517 | K10: 44440
A11: 44470 | B11: 81623.998 | C11: 210.48353 | D11: =+C11/B11 -> 0.0025786966 | F11: 44470 | G11: 22134.823 | H11: 61.403238 | I11: =+H11/G11 -> 0.002774056 | K11: 44470
A12: 44501 | B12: 82695.783 | C12: 168.98781 | D12: =+C12/B12 -> 0.0020434876 | F12: 44501 | G12: 7886.8415 | H12: 25.894602 | I12: =+H12/G12 -> 0.0032832664 | K12: 44501
A13: 44531 | B13: 79148.031 | C13: 209.752 | D13: =+C13/B13 -> 0.0026501227 | F13: 44531 | G13: 9136.6101 | H13: 28.986039 | I13: =+H13/G13 -> 0.0031725157 | K13: 44531
... A27: 44958 | B27: 81073.982 | C27: 221.90776 | D27: =+C27/B27 -> 0.002737102 | F27: 44958 | G27: 12827.258 | H27: 24.332 | I27: =+H27/G27 -> 0.001896898 | K27: 44958
A28: 44986 | B28: =+Hoja1!C28 -> 82634.711 | C28: 172.72103 | D28: =+C28/B28 -> 0.0020901753 | F28: 44986 | G28: =+Hoja1!D28 -> 14388.775 | H28: 45.348536 | I28: =+H28/G28 -> 0.0031516606 | K28: 44986
A29: 45017 | B29: =+Hoja1!C29 -> 83229.723 | C29: 474.14702 | D29: =+C29/B29 -> 0.0056968473 | F29: 45017 | G29: =+Hoja1!D29 -> 13038.809 | H29: 33.841852 | I29: =+H29/G29 -> 0.0025954711 | K29: 45017
A30: 45047 | B30: =+Hoja1!C30 -> 84032.611 | C30: 267.7862 | D30: =+C30/B30 -> 0.0031866939 | F30: 45047 | G30: =+Hoja1!D30 -> 14494.992 | H30: 56.990132 | I30: =+H30/G30 -> 0.0039317117 | K30: 45047
A31: 45078 | B31: =+Hoja1!C31 -> 86121.546 | C31: 391.54471 | D31: =+C31/B31 -> 0.0045464198 | F31: 45078 | G31: =+Hoja1!D31 -> 16689.804 | H31: 37.654483 | I31: =+H31/G31 -> 0.0022561369 | K31: 45078
A32: 45108 | B32: =+Hoja1!C32 -> 87260.803 | C32: 1092.0679 | D32: =+C32/B32 -> 0.012514988 | F32: 45108 | G32: =+Hoja1!D32 -> 18288.248 | H32: 53.141945 | I32: =+H32/G32 -> 0.0029057974 | K32: 45108
A33: 45139 | B33: =+Hoja1!C33 -> 87102.781 | C33: 316.56074 | D33: =+C33/B33 -> 0.0036343356 | F33: 45139 | G33: =+Hoja1!D33 -> 20014.3 | H33: 81.828418 | I33: =+H33/G33 -> 0.0040884977 | K33: 45139
A34: 45170 | B34: =+Hoja1!C34 -> 86266.348 | C34: 450.91626 | D34: =+C34/B34 -> 0.0052270239 | F34: 45170 | G34: =+Hoja1!D34 -> 22131.72 | H34: 74.639 | I34: =+H34/G34 -> 0.0033724899 | K34: 45170
A35: 45200 | B35: =+Hoja1!C35 -> 84746.958 | C35: 196.35698 | D35: =+C35/B35 -> 0.0023169797 | F35: 45200 | G35: =+Hoja1!D35 -> 23592.291 | H35: 67.426043 | I35: =+H35/G35 -> 0.0028579692 | K35: 45200
A36: 45231 | B36: 85474.425 | C36: 249.12222 | D36: =+C36/B36 -> 0.002914582 | F36: 45231 | G36: 9947.7147 | H36: 54.79 | I36: =+H36/G36 -> 0.0055077977 | K36: 45231
A37: 45261 | B37: 85038.37 | C37: 1103.5206 | D37: =+C37/B37 -> 0.012976738 | F37: 45261 | G37: 11207.772 | H37: 26.414037 | I37: =+H37/G37 -> 0.0023567608 | K37: 45261 | L37: 59203.979 | M37: 27.880649 | N37: =+M37/L37 -> 0.00047092525
A38: 45292 | B38: 86109.524 | C38: 499.27864 | D38: =+C38/B38 -> 0.0057981814 | F38: 45292 | G38: 12855.045 | H38: 32.972152 | I38: =+H38/G38 -> 0.0025649193 | K38: 45292 | L38: 59214.379 | M38: 402.65973 | N38: =+M38/L38 -> 0.006800033
A39: 45323 | B39: 90581.596 | C39: 360.73409 | D39: =+C39/B39 -> 0.0039824214 | F39: 45323 | G39: 15200.213 | H39: 70.210525 | I39: =+H39/G39 -> 0.0046190488 | K39: 45323 | L39: 58754.18 | M39: 854.96556 | N39: =+M39/L39 -> 0.01455157
A40: 45352 | B40: =+Hoja1!C40 -> 89035.283 | C40: 4043.1305 | D40: =+C40/B40 -> 0.045410429 | F40: 45352 | G40: =+Hoja1!D40 -> 16632.486 | H40: 91.949514 | I40: =+H40/G40 -> 0.0055283084 | K40: 45352 | L40: =+Hoja1!E40 -> 58123.989 | M40: 1149.1599 | N40: =+M40/L40 -> 0.019770837
A41: 45383 | B41: =+Hoja1!C41 -> 89901.62 | C41: 206.32628 | D41: =+C41/B41 -> 0.002295023 | F41: 45383 | G41: =+Hoja1!D41 -> 14920.796 | H41: 76.426909 | I41: =+H41/G41 -> 0.0051221738 | K41: 45383 | L41: =+Hoja1!E41 -> 56911.791 | M41: 1309.8839 | N41: =+M41/L41 -> 0.023016037
A42: 45413 | B42: =+Hoja1!C42 -> 90253.219 | C42: 307.3901 | D42: =+C42/B42 -> 0.003405863 | F42: 45413 | G42: =+Hoja1!D42 -> 15971.981 | H42: 49.529561 | I42: =+H42/G42 -> 0.003101028 | K42: 45413 | L42: =+Hoja1!E42 -> 56512.459 | M42: 1084.73 | N42: =+M42/L42 -> 0.019194528
A43: 45444 | B43: 91133.023 | C43: 160.6297 | D43: =+C43/B43 -> 0.001762585 | F43: 45444 | G43: 17668.677 | H43: 103.76324 | I43: =+H43/G43 -> 0.0058727226 | K43: 45444 | L43: 55984.563 | M43: 1549.0429 | N43: =+M43/L43 -> 0.027669108
A44: 45474 | B44: 90868.152 | C44: 678.3231 | D44: =+C44/B44 -> 0.0074649158 | F44: 45474 | G44: 18790.596 | H44: 140.70531 | I44: =+H44/G44 -> 0.0074880704 | K44: 45474 | L44: 55405.982 | M44: 1294.4355 | N44: =+M44/L44 -> 0.023362739
A45: 45505 | B45: =+Hoja1!C45 -> 89989.976 | C45: 272.73854 | D45: =+C45/B45 -> 0.0030307657 | F45: 45505 | G45: =+Hoja1!D45 -> 20195.294 | H45: 99.214483 | I45: =+H45/G45 -> 0.0049127526 | K45: 45505 | L45: =+Hoja1!E45 -> 55250.081 | M45: 862.06801 | N45: =+M45/L45 -> 0.015603018
A46: 45536 | B46: =+Hoja1!C46 -> 90280.665 | C46: 48.185889 | D46: =+C46/B46 -> 0.00053373431 | F46: 45536 | G46: =+Hoja1!D46 -> 22074.321 | H46: 86.030428 | I46: =+H46/G46 -> 0.003897308 | K46: 45536 | L46: =+Hoja1!E46 -> 54685.055 | M46: 1172.6748 | N46: =+M46/L46 -> 0.021444155
A47: 45566 | B47: =+Hoja1!C47 -> 88235.778 | C47: 1361.5286 | D47: =+C47/B47 -> 0.015430572 | F47: 45566 | G47: =+Hoja1!D47 -> 23069.178 | H47: 123.91805 | I47: =+H47/G47 -> 0.0053715847 | K47: 45566 | L47: =+Hoja1!E47 -> 54017.928 | M47: 933.56015 | N47: =+M47/L47 -> 0.017282413
A48: 45597 | B48: =+Hoja1!C48 -> 87723.372 | C48: 792.85436 | D48: =+C48/B48 -> 0.00903812 | F48: 45597 | G48: =+Hoja1!D48 -> 9512.739 | H48: 123 | I48: =+H48/G48 -> 0.01293003 | K48: 45597 | L48: =+Hoja1!E48 -> 53846.862 | M48: 899.83804 | N48: =+M48/L48 -> 0.016711058
A49: 45627 | B49: =+Hoja1!C49 -> 89551.243 | C49: 207.90637 | D49: =+C49/B49 -> 0.002321647 | F49: 45627 | G49: =+Hoja1!D49 -> 10492.84 | H49: 55.641219 | I49: =+H49/G49 -> 0.0053027796 | K49: 45627 | L49: =+Hoja1!E49 -> 53741.097 | M49: 776.45374 | N49: =+M49/L49 -> 0.014448044
A50: 45658 | B50: =+Hoja1!C50 -> 91352.129 | C50: 286.40193 | D50: =+C50/B50 -> 0.0031351424 | F50: 45658 | G50: =+Hoja1!D50 -> 12226.253 | H50: 36.679225 | I50: =+H50/G50 -> 0.003000038 | K50: 45658 | L50: =+Hoja1!E50 -> 53567.861 | M50: 462.20749 | N50: =+M50/L50 -> 0.0086284478
A51: 45689 | B51: =+Hoja1!C51 -> 92480.89 | C51: 619.50146 | D51: =+C51/B51 -> 0.006698697 | F51: 45689 | G51: =+Hoja1!D51 -> 14315.478 | H51: 72.481138 | I51: =+H51/G51 -> 0.005063131 | K51: 45689 | L51: =+Hoja1!E51 -> 52938.946 | M51: 1363.2524 | N51: =+M51/L51 -> 0.025751409
A52: 45717 | B52: =+Hoja1!C52 -> 92822.723 | C52: 140.01309 | D52: =+C52/B52 -> 0.0015083925 | F52: 45717 | G52: =+Hoja1!D52 -> 16034.149 | H52: 55.188677 | I52: =+H52/G52 -> 0.0034419461 | K52: 45717 | L52: =+Hoja1!E52 -> 52629.357 | M52: 893.95885 | N52: =+M52/L52 -> 0.016985935
A53: 45748 | B53: =+Hoja1!C53 -> 92923.13 | C53: 362.73033 | D53: =+C53/B53 -> 0.0039035526 | F53: 45748 | G53: =+Hoja1!D53 -> 14963.165 | H53: 63.397567 | I53: =+H53/G53 -> 0.0042369088 | K53: 45748 | L53: =+Hoja1!E53 -> 52559.052 | M53: 804.33193 | N53: =+M53/L53 -> 0.015303395
...

Sheet Hoja2
A1: Mes | B1: CDATs cancelados anticipadamente | C1: % CDATs cancelados sobre saldo total | D1: Ahorro programados cancelados anticipadamente | E1: % Ahorros cancelados sobre saldo total
A2: 45627 | B2: 207.90637 | C2: 0.002321647 | D2: 55.641219 | E2: 0.0053027796
A3: 45658 | B3: 286.40193 | C3: 0.0031351424 | D3: 36.679225 | E3: 0.003000038
A4: 45689 | B4: 619.50146 | C4: 0.006698697 | D4: 72.481138 | E4: 0.005063131
A5: 45717 | B5: 140.01309 | C5: 0.0015083925 | D5: 55.188677 | E5: 0.0034419461
A6: 45748 | B6: 362.73033 | C6: 0.0039035526 | D6: 63.397567 | E6: 0.0042369088
A7: 45778 | B7: 861.01873 | C7: 0.0092543321 | D7: 44.036747 | E7: 0.0026687801
A8: 45809 | B8: 19.545981 | C8: 0.00020204719 | D8: 65.094533 | E8: 0.0035270127
A9: 45839 | B9: 214.56716 | C9: 0.002141115 | D9: 94.030845 | E9: 0.0046904186
A10: 45870 | B10: 267.68354 | C10: 0.0025980853 | D10: 84.104547 | E10: 0.0038325368
A11: 45901 | B11: 272.06646 | C11: 0.002542202 | D11: 14.449453 | E11: 0.00059704389
A12: 45931 | B12: 746.92166 | C12: 0.0069344429 | D12: 13.180055 | E12: 0.0005144275
A13: 45962 | B13: 631.88959 | C13: 0.0056993743 | D13: 16.587958 | E13: 0.0014970754
A14: 45992 | B14: 318.48111 | C14: 0.0027702358 | D14: 10.409182 | E14: 0.0008671594

Sheet Futuro
A1: Fecha | B1: VIVIENDA | C1: # ASOCIADOS | D1: EDUCACIÒN | E1: # ASOCIADOS | F1: EXCEPCIÓN - REG AHORROS | G1: # ASOCIADOS | H1: CANCELACIÒN VOLUNTARIA | I1: # ASOCIADOS | J1: RETIRO FONDO | K1: # ASOCIADOS | L1: Valor total | M1: # total asoc
A2: 45261 | B2: =(136107053.72/A15)/1000 -> 136.10705 | C2: 38 | D2: =(48823537.87/A15)/1000 -> 48.823538 | E2: 14 | F2: =(7277466.03/A15)/1000 -> 7.277466 | G2: 4 | H2: =(139709334.65/A15)/1000 -> 139.70933 | I2: =64+17 -> 81 | L2: =+(B2+D2+F2+H2) -> 331.91739 | M2: =+C2+E2+G2+I2 -> 137 | Q2: NUMERO DE ASOCIADOS
A3: 45292 | B3: =(484361705.727/A15)/1000 -> 484.36171 | C3: 138 | D3: =(103895026.872/A15)/1000 -> 103.89503 | E3: 59 | F3: =(77455798.96/A15)/1000 -> 77.455799 | G3: 19 | H3: =(402659729.61/A15)/1000 -> 402.65973 | I3: 165 | L3: =(+B3+D3+F3+H3) -> 1068.3723 | M3: =+C3+E3+G3+I3 -> 381 | Q3: VIVIENDA | R3: EDUCACIÓN | S3: REG AHORROS | T3: Valor total
A4: 45323 | B4: =(457715701.781/A15)/1000 -> 457.7157 | C4: 99 | D4: =(84458080.105/A15)/1000 -> 84.45808 | E4: 28 | F4: =(322918345.978/A15)/1000 -> 322.91835 | G4: 69 | H4: =(854965557.13/A15)/1000 -> 854.96556 | I4: 462 | J4: 0 | K4: 0 | L4: =(+B4+D4+F4+H4) -> 1720.0577 | M4: =+C4+E4+G4+I4 -> 658 | P4: 45261 | Q4: 38 | R4: 14 | S4: 4 | T4: 137
A5: 45352 | B5: =(325075195.74/A15)/1000 -> 325.0752 | C5: 71 | D5: =(24815932.99/A15)/1000 -> 24.815933 | E5: 11 | F5: =(273992603.07/A15)/1000 -> 273.9926 | G5: 98 | H5: =(1149159897.59/A15)/1000 -> 1149.1599 | I5: 440 | L5: =(+B5+D5+F5+H5) -> 1773.0436 | M5: =+C5+E5+G5+I5 -> 620 | P5: 45292 | Q5: 138 | R5: 59 | S5: 19 | T5: 381
A6: 45383 | B6: 207.25432 | C6: 69 | D6: 119.54909 | E6: 12 | F6: 201.36194 | G6: 81 | H6: 1309.8839 | I6: 413 | L6: =(+B6+D6+F6+H6) -> 1838.0493 | M6: =+C6+E6+G6+I6 -> 575 | P6: 45323 | Q6: 99 | R6: 28 | S6: 69 | T6: 658
A7: 45413 | B7: 234.74696 | C7: 68 | D7: 21.366571 | E7: 6 | F7: 173.91316 | G7: 70 | H7: 1084.73 | I7: 478 | L7: =+B7+D7+F7+H7 -> 1514.7567 | M7: =+C7+E7+G7+I7 -> 622 | P7: 45352 | Q7: 71 | R7: 11 | S7: 98 | T7: 620
A8: 45444 | B8: 371.76217 | C8: 63 | D8: 476.78005 | E8: 27 | F8: 98.423324 | G8: 52 | H8: 1549.0429 | I8: 464 | L8: =+B8+D8+F8+H8 -> 2496.0084 | M8: =+C8+E8+G8+I8 -> 606
A9: 45474 | B9: 172.18361 | C9: 55 | D9: 77.316094 | E9: 38 | F9: 114.69601 | G9: 33 | H9: 1294.4355 | I9: 310 | L9: =+B9+D9+F9+H9 -> 1658.6312 | M9: =+C9+E9+G9+I9 -> 436 | R9: NUMERO DE ASOCIADOS
A10: 45505 | B10: 244.48025 | C10: 59 | D10: 47.381307 | E10: 16 | F10: 67.646783 | G10: 42 | H10: 862.06801 | I10: 306 | L10: =+B10+D10+F10+H10 -> 1221.5764 | M10: =+C10+E10+G10+I10 -> 423 | R10: CANCELACIÓN ANT | S10: Valor total
A11: 45536 | B11: 344.43537 | C11: 78 | D11: 33.309769 | E11: 17 | F11: 57.964716 | G11: 28 | H11: 1172.6748 | I11: 417 | L11: =+B11+D11+F11+H11 -> 1608.3846 | Q11: 45261 | R11: =64+17 -> 81 | S11: 137
A12: 45596 | B12: 357.70556 | C12: 60 | D12: 11.275684 | E12: 13 | F12: 46.701909 | G12: 25 | H12: 933.56015 | I12: 389 | L12: 1349.2433 | M12: 487
A13: 45626 | Q13: 45292 | R13: 165 | S13: 381
Q14: 45323 | R14: 462 | S14: 658
A15: 1000 | Q15: 45352 | R15: 440 | S15: 620
A16: 1000000

Sheet Evolución Rking
A1: MES | B1: 90 días | C1: 180 días | D1: 1 año | E1: 2 años | F1: 3 años
A2: 44621 | B2: 5 | C2: 5 | D2: 5 | E2: 9
A3: 44652 | B3: 6 | C3: 7 | D3: 7 | E3: 7 | F3: 6
A4: 44682 | B4: 6 | C4: 7 | D4: 7 | E4: 7 | F4: 6
A5: 44713 | B5: 7 | C5: 8 | D5: 9 | E5: 9 | F5: 7
A6: 44743 | B6: 10 | C6: 11 | D6: 11 | E6: 11 | F6: 9
A7: 44774 | B7: 10 | C7: 10 | D7: 10 | E7: 9 | F7: 7
A8: 44805 | B8: 9 | C8: 10 | D8: 8 | E8: 8 | F8: 7
A9: 44835 | B9: 8 | C9: 10 | D9: 8 | E9: 9 | F9: 7
A10: 44866 | B10: 9 | C10: 10 | D10: 10 | E10: 9 | F10: 6
A11: 44896 | B11: 9 | C11: 10 | D11: 10 | E11: 9 | F11: 7
A12: 44927 | B12: 7 | C12: 10 | D12: 10 | E12: 9 | F12: 6
A13: 44958 | B13: 8 | C13: 9 | D13: 9 | E13: 8 | F13: 4
A14: 44986 | B14: 8 | C14: 7 | D14: 3 | E14: 3 | F14: 1
... A41: 45809 | B41: 1 | C41: 1 | D41: 1 | E41: 2 | F41: 3
