Workbook
Name BloombergHeader: '[1]Datos Bloomberg'!$2:$2
Name BloombergRef: '[1]Datos Bloomberg'!$A$2
Name BloombergTickers: '[1]Datos Bloomberg'!$A:$B
Name Bmg_ref: [2]Refinitiv_precios!#REF!
Name Bmg_ticker: [2]Refinitiv_precios!#REF!
Name Canasta: [1]Canasta!$B:$F
Name Dividendos: #REF!
Name PreciosObjetivo: '[1]Precio Objetivo'!$A:$N
Name Refinitiv: [2]Refinitiv_precios!#REF!
Name SAA: [1]SAA!$E:$G

Sheet Hoja1
A1: Año | C1: Fecha | D1: Inflación anual | E1: Tasa Repo | F1: Ciclos | H1: Ciclos | I1: Meses | J1: Inflación anual % | K1: Tasa Repo | L1: Diferencia | M1: Tasa IPC+200PB | N1: Tasa vivienda
A2: 2000 | B2: 6 | C2: 36678 | D2: 9.68 | E2: 12 | F2: Ciclo 1 | H2: Ciclo 1 | I2: =+COUNTIF(F:F,H2) -> 21 | J2: =+AVERAGEIF($F$1:$F$293,H2,$D$1:$D$293) -> 8.2652381 | K2: =+AVERAGEIF($F$1:$F$293,H2,$E$1:$E$293) -> 11 | L2: =+K2-J2 -> 2.7347619 | M2: =+J2+2 -> 10.265238
A3: 2000 | B3: 7 | C3: 36708 | D3: 9.29 | E3: 12 | F3: Ciclo 1 | H3: Ciclo 2 | I3: =+COUNTIF(F:F,H3) -> 14 | J3: =+AVERAGEIF($F$1:$F$293,H3,$D$1:$D$293) -> 6.5892857 | K3: =+AVERAGEIF($F$1:$F$293,H3,$E$1:$E$293) -> 5.9107143 | L3: =+K3-J3 -> -0.67857143 | M3: =+J3+2 -> 8.5892857
A4: 2000 | B4: 8 | C4: 36739 | D4: 9.1 | E4: 12 | F4: Ciclo 1 | H4: Ciclo 3 | I4: =+COUNTIF(F:F,H4) -> 39 | J4: =+AVERAGEIF($F$1:$F$293,H4,$D$1:$D$293) -> 5.5469231 | K4: =+AVERAGEIF($F$1:$F$293,H4,$E$1:$E$293) -> 6.6538462 | L4: =+K4-J4 -> 1.1069231 | M4: =+J4+2 -> 7.5469231
A5: 2000 | B5: 9 | C5: 36770 | D5: 9.2 | E5: 12 | F5: Ciclo 1 | H5: Ciclo 4 | I5: =+COUNTIF(F:F,H5) -> 29 | J5: =+AVERAGEIF($F$1:$F$293,H5,$D$1:$D$293) -> 5.9544828 | K5: =+AVERAGEIF($F$1:$F$293,H5,$E$1:$E$293) -> 8.8362069 | L5: =+K5-J5 -> 2.8817241 | M5: =+J5+2 -> 7.9544828
A6: 2000 | B6: 10 | C6: 36800 | D6: 8.99 | E6: 12 | F6: Ciclo 1 | H6: Ciclo 5 | I6: =+COUNTIF(F:F,H6) -> 16 | J6: =+AVERAGEIF($F$1:$F$293,H6,$D$1:$D$293) -> 3.67625 | K6: =+AVERAGEIF($F$1:$F$293,H6,$E$1:$E$293) -> 5.375 | L6: =+K6-J6 -> 1.69875 | M6: =+J6+2 -> 5.67625
A7: 2000 | B7: 11 | C7: 36831 | D7: 8.82 | E7: 12 | F7: Ciclo 1 | H7: Ciclo 6 | I7: =+COUNTIF(F:F,H7) -> 18 | J7: =+AVERAGEIF($F$1:$F$293,H7,$D$1:$D$293) -> 2.9183333 | K7: =+AVERAGEIF($F$1:$F$293,H7,$E$1:$E$293) -> 3.4722222 | L7: =+K7-J7 -> 0.55388889 | M7: =+J7+2 -> 4.9183333
A8: 2000 | B8: 12 | C8: 36861 | D8: 8.75 | E8: 12 | F8: Ciclo 1 | H8: Ciclo 7 | I8: =+COUNTIF(F:F,H8) -> 26 | J8: =+AVERAGEIF($F$1:$F$293,H8,$D$1:$D$293) -> 2.6907692 | K8: =+AVERAGEIF($F$1:$F$293,H8,$E$1:$E$293) -> 4.2403846 | L8: =+K8-J8 -> 1.5496154 | M8: =+J8+2 -> 4.6907692
A9: 2001 | B9: 1 | C9: 36892 | D9: 8.49 | E9: 12 | F9: Ciclo 1 | H9: Ciclo 8 | I9: =+COUNTIF(F:F,H9) -> 31 | J9: =+AVERAGEIF($F$1:$F$293,H9,$D$1:$D$293) -> 4.8806452 | K9: =+AVERAGEIF($F$1:$F$293,H9,$E$1:$E$293) -> 4.7580645 | L9: =+K9-J9 -> -0.12258065 | M9: =+J9+2 -> 6.8806452
A10: 2001 | B10: 2 | C10: 36923 | D10: 8.06 | E10: 12 | F10: Ciclo 1 | H10: Ciclo 9 | I10: =+COUNTIF(F:F,H10) -> 57 | J10: =+AVERAGEIF($F$1:$F$293,H10,$D$1:$D$293) -> 3.5717544 | K10: =+AVERAGEIF($F$1:$F$293,H10,$E$1:$E$293) -> 4.5394737 | L10: =+K10-J10 -> 0.9677193 | M10: =+J10+2 -> 5.5717544
A11: 2001 | B11: 3 | C11: 36951 | D11: 7.81 | E11: 12 | F11: Ciclo 1 | H11: Ciclo 10 | I11: =+COUNTIF(F:F,H11) -> 23 | J11: =+AVERAGEIF($F$1:$F$293,H11,$D$1:$D$293) -> 8.5647826 | K11: =+AVERAGEIF($F$1:$F$293,H11,$E$1:$E$293) -> 5.9673913 | L11: =+K11-J11 -> -2.5973913 | M11: =+J11+2 -> 10.564783
A12: 2001 | B12: 4 | C12: 36982 | D12: 7.98 | E12: 11.5 | F12: Ciclo 1 | H12: Ciclo 11 | I12: =+COUNTIF(F:F,H12) -> 29 | J12: =+AVERAGEIF($F$1:$F$303,H12,$D$1:$D$303) -> 7.7317857 | K12: =+AVERAGEIF($F$1:$F$294,H12,$E$1:$E$294) -> 12.394737 | L12: =+K12-J12 -> 4.6629511 | M12: =+J12+2 -> 9.7317857
A13: 2001 | B13: 5 | C13: 37012 | D13: 7.87 | E13: 11.5 | F13: Ciclo 1 | J13: =+AVERAGE(J2:J12)/100 -> 0.054900227 | M13: =+AVERAGE(M2:M12) -> 7.4900227
A14: 2001 | B14: 6 | C14: 37043 | D14: 7.93 | E14: 11.5 | F14: Ciclo 1
A15: 2001 | B15: 7 | C15: 37073 | D15: 8.09 | E15: 11.5 | F15: Ciclo 1 | J15: Metodología 1
A16: 2001 | B16: 8 | C16: 37104 | D16: 8.03 | E16: 11 | F16: Ciclo 1 | J16: Prom IPC ciclos | K16: Anillo de seguridad | L16: Prima de fondeo PRESENTE | M16: Spread comercial AC | N16: Total tasa minímia en vivienda
A17: 2001 | B17: 9 | C17: 37135 | D17: 7.97 | E17: 10 | F17: Ciclo 1 | J17: =+J13 -> 0.054900227 | K17: 0.02 | L17: =9.41%-9.18% -> 0.0023 | M17: 0.02 | N17: =+J17+K17+L17+M17 -> 0.097200227
A18: 2001 | B18: 10 | C18: 37165 | D18: 8.01 | E18: 9.5 | F18: Ciclo 1
A19: 2001 | B19: 11 | C19: 37196 | D19: 7.78 | E19: 9.25 | F19: Ciclo 1
A20: 2001 | B20: 12 | C20: 37226 | D20: 7.65 | E20: 8.75 | F20: Ciclo 1 | J20: Metodología 2
A21: 2002 | B21: 1 | C21: 37257 | D21: 7.37 | E21: 8.5 | F21: Ciclo 1 | J21: Prom IPC ultimo ciclo | K21: Prom diferencial historico | L21: Tasa minima de colocación
A22: 2002 | B22: 2 | C22: 37288 | D22: 6.7 | E22: 8 | F22: Ciclo 1 | J22: 9.1755556 | K22: =+AVERAGE(L2:L12) -> 1.1597991 | L22: =+J22+K22 -> 10.335355
A23: 2002 | B23: 3 | C23: 37316 | D23: 5.89 | E23: 8 | F23: Ciclo 2
A24: 2002 | B24: 4 | C24: 37347 | D24: 5.65 | E24: 7.25 | F24: Ciclo 2
A25: 2002 | B25: 5 | C25: 37377 | D25: 5.84 | E25: 6.25 | F25: Ciclo 2
A26: 2002 | B26: 6 | C26: 37408 | D26: 6.25 | E26: 5.75 | F26: Ciclo 2
A27: 2002 | B27: 7 | C27: 37438 | D27: 6.16 | E27: 5.25 | F27: Ciclo 2
A28: 2002 | B28: 8 | C28: 37469 | D28: 5.98 | E28: 5.25 | F28: Ciclo 2
A29: 2002 | B29: 9 | C29: 37500 | D29: 5.97 | E29: 5.25 | F29: Ciclo 2
A30: 2002 | B30: 10 | C30: 37530 | D30: 6.37 | E30: 5.25 | F30: Ciclo 2
A31: 2002 | B31: 11 | C31: 37561 | D31: 7.07 | E31: 5.25 | F31: Ciclo 2
A32: 2002 | B32: 12 | C32: 37591 | D32: 6.99 | E32: 5.25 | F32: Ciclo 2
A33: 2003 | B33: 1 | C33: 37622 | D33: 7.39 | E33: 5.25 | F33: Ciclo 2
A34: 2003 | B34: 2 | C34: 37653 | D34: 7.24 | E34: 6.25 | F34: Ciclo 2
... A284: 2023 | B284: 12 | C284: 45261 | D284: 9.28 | E284: 13.25 | F284: Ciclo 11
A285: 2024 | B285: 1 | C285: 45292 | D285: 8.35 | E285: 13 | F285: Ciclo 11 | G285: =+E284-E285 -> 0.25
A286: 2024 | B286: 2 | C286: 45323 | D286: 7.74 | E286: 12.75 | F286: Ciclo 11 | G286: =+E285-E286 -> 0.25
A287: 2024 | B287: 3 | C287: 45352 | D287: 7.36 | E287: 12.75 | F287: Ciclo 11 | G287: =+E286-E287 -> 0
A288: 2024 | B288: 4 | C288: 45383 | D288: 7.16 | E288: 12.25 | F288: Ciclo 11 | G288: =+E287-E288 -> 0.5
A289: 2024 | B289: 5 | C289: 45413 | D289: 7.16 | E289: 12.25 | F289: Ciclo 11 | G289: =+E288-E289 -> 0
...

Sheet Hoja2
A1: Fecha | B1: Inflación anual | C1: Tasa Repo
A2: 36678 | B2: 9.68 | C2: 12
A3: 36708 | B3: 9.29 | C3: 12
A4: 36739 | B4: 9.1 | C4: 12
A5: 36770 | B5: 9.2 | C5: 12
A6: 36800 | B6: 8.99 | C6: 12
A7: 36831 | B7: 8.82 | C7: 12
A8: 36861 | B8: 8.75 | C8: 12
A9: 36892 | B9: 8.49 | C9: 12
A10: 36923 | B10: 8.06 | C10: 12
A11: 36951 | B11: 7.81 | C11: 12
A12: 36982 | B12: 7.98 | C12: 11.5
A13: 37012 | B13: 7.87 | C13: 11.5
... A308: 45992 | B308: 5.1 | C308: 9.25

Sheet Metodología
A1: Fecha | B1: Prom IPC ciclos | C1: Anillo de seguridad | D1: Prima de fondeo PRESENTE | E1: Spread comercial AC | F1: Total tasa minímia en vivienda
A2: 45565 | B2: 0.0562 | C2: 0.02 | D2: =+'Datos recursos'!K2-'Promedio ciclos'!D12/100 -> 0.0023755811 | E2: 0.02 | F2: =+B2+C2+D2+E2 -> 0.098575581
A3: 45596 | B3: 0.056 | C3: 0.02 | D3: =+'Datos recursos'!K3-'Promedio ciclos'!D13/100 -> 0.0031947062 | E3: 0.02 | F3: =+B3+C3+D3+E3 -> 0.099194706
A4: =+A3+30 -> 45626 | B4: 0.055860877 | C4: 0.02 | D4: =+'Datos recursos'!K4-'Promedio ciclos'!D14/100 -> 0.0018435315 | E4: 0.02 | F4: =+B4+C4+D4+E4 -> 0.097704408
A5: =+A4+31 -> 45657 | B5: 0.05570553 | C5: 0.02 | D5: =+'Datos recursos'!K5-'Promedio ciclos'!D15/100 -> 0.0066450459 | E5: 0.02 | F5: =+B5+C5+D5+E5 -> 0.10235058
A6: 45688 | B6: 0.05570553 | C6: 0.02 | D6: =+'Datos recursos'!K6-'Promedio ciclos'!D16/100 -> 0.0082671844 | E6: 0.02 | F6: =+B6+C6+D6+E6 -> 0.10397271
A7: 45716 | B7: 0.055439315 | C7: 0.02 | D7: =+'Datos recursos'!K7-'Promedio ciclos'!D17/100 -> 0.0089528911 | E7: 0.02 | F7: =+B7+C7+D7+E7 -> 0.10439221
A8: 45747 | B8: 0.055316786 | C8: 0.02 | D8: =+'Datos recursos'!K8-'Promedio ciclos'!D18/100 -> 0.01152558 | E8: 0.02 | F8: =+B8+C8+D8+E8 -> 0.10684237
A9: 45777 | B9: 0.055206604 | C9: 0.02 | D9: =+'Datos recursos'!K9-'Promedio ciclos'!D19/100 -> 0.011990265 | E9: 0.02 | F9: =+B9+C9+D9+E9 -> 0.10719687
A10: 45808 | B10: 0.055101052 | C10: 0.02 | D10: =+'Datos recursos'!K10-'Promedio ciclos'!D20/100 -> 0.013013113 | E10: 0.02 | F10: =+B10+C10+D10+E10 -> 0.10811416
A11: 45838 | B11: 0.054995574 | C11: 0.02 | D11: =+'Datos recursos'!K11-'Promedio ciclos'!D21/100 -> 0.015772514 | E11: 0.02 | F11: =+B11+C11+D11+E11 -> 0.11076809
A12: 45869 | B12: 0.054900227 | C12: 0.02 | D12: =+'Datos recursos'!K12-'Promedio ciclos'!D22/100 -> 0.016082934 | E12: 0.02 | F12: =+B12+C12+D12+E12 -> 0.11098316

Sheet Promedio ciclos
A1: Fecha | B1: Ciclos | C1: Meses | D1: Inflación anual % | E1: Tasa Repo | F1: Diferencia | G1: Tasa IPC+200PB
B2: Ciclo 1 | C2: =+COUNTIF(Hoja1!F:F,B2) -> 21 | D2: =+AVERAGEIF(Hoja1!F:F,B2,Hoja1!D:D) -> 8.2652381 | E2: =+AVERAGEIF(Hoja1!F:F,B2,Hoja1!E:E) -> 11 | F2: =+E2-D2 -> 2.7347619 | G2: =+D2+2 -> 10.265238
B3: Ciclo 2 | C3: =+COUNTIF(Hoja1!F:F,B3) -> 14 | D3: =+AVERAGEIF(Hoja1!F:F,B3,Hoja1!D:D) -> 6.5892857 | E3: =+AVERAGEIF(Hoja1!F:F,B3,Hoja1!E:E) -> 5.9107143 | F3: =+E3-D3 -> -0.67857143 | G3: =+D3+2 -> 8.5892857
B4: Ciclo 3 | C4: =+COUNTIF(Hoja1!F:F,B4) -> 39 | D4: =+AVERAGEIF(Hoja1!F:F,B4,Hoja1!D:D) -> 5.5469231 | E4: =+AVERAGEIF(Hoja1!F:F,B4,Hoja1!E:E) -> 6.6538462 | F4: =+E4-D4 -> 1.1069231 | G4: =+D4+2 -> 7.5469231
B5: Ciclo 4 | C5: =+COUNTIF(Hoja1!F:F,B5) -> 29 | D5: =+AVERAGEIF(Hoja1!F:F,B5,Hoja1!D:D) -> 5.9544828 | E5: =+AVERAGEIF(Hoja1!F:F,B5,Hoja1!E:E) -> 8.8362069 | F5: =+E5-D5 -> 2.8817241 | G5: =+D5+2 -> 7.9544828
B6: Ciclo 5 | C6: =+COUNTIF(Hoja1!F:F,B6) -> 16 | D6: =+AVERAGEIF(Hoja1!F:F,B6,Hoja1!D:D) -> 3.67625 | E6: =+AVERAGEIF(Hoja1!F:F,B6,Hoja1!E:E) -> 5.375 | F6: =+E6-D6 -> 1.69875 | G6: =+D6+2 -> 5.67625
B7: Ciclo 6 | C7: =+COUNTIF(Hoja1!F:F,B7) -> 18 | D7: =+AVERAGEIF(Hoja1!F:F,B7,Hoja1!D:D) -> 2.9183333 | E7: =+AVERAGEIF(Hoja1!F:F,B7,Hoja1!E:E) -> 3.4722222 | F7: =+E7-D7 -> 0.55388889 | G7: =+D7+2 -> 4.9183333
B8: Ciclo 7 | C8: =+COUNTIF(Hoja1!F:F,B8) -> 26 | D8: =+AVERAGEIF(Hoja1!F:F,B8,Hoja1!D:D) -> 2.6907692 | E8: =+AVERAGEIF(Hoja1!F:F,B8,Hoja1!E:E) -> 4.2403846 | F8: =+E8-D8 -> 1.5496154 | G8: =+D8+2 -> 4.6907692
B9: Ciclo 8 | C9: =+COUNTIF(Hoja1!F:F,B9) -> 31 | D9: =+AVERAGEIF(Hoja1!F:F,B9,Hoja1!D:D) -> 4.8806452 | E9: =+AVERAGEIF(Hoja1!F:F,B9,Hoja1!E:E) -> 4.7580645 | F9: =+E9-D9 -> -0.12258065 | G9: =+D9+2 -> 6.8806452
B10: Ciclo 9 | C10: =+COUNTIF(Hoja1!F:F,B10) -> 57 | D10: =+AVERAGEIF(Hoja1!F:F,B10,Hoja1!D:D) -> 3.5717544 | E10: =+AVERAGEIF(Hoja1!F:F,B10,Hoja1!E:E) -> 4.5394737 | F10: =+E10-D10 -> 0.9677193 | G10: =+D10+2 -> 5.5717544
B11: Ciclo 10 | C11: =+COUNTIF(Hoja1!F:F,B11) -> 23 | D11: =+AVERAGEIF(Hoja1!F:F,B11,Hoja1!D:D) -> 8.5647826 | E11: =+AVERAGEIF(Hoja1!F:F,B11,Hoja1!E:E) -> 5.9673913 | F11: =+E11-D11 -> -2.5973913 | G11: =+D11+2 -> 10.564783
A12: 45565 | B12: Ciclo 11 | C12: =+COUNTIF(Hoja1!$F$2:F293,B12) -> 18 | D12: =+AVERAGEIF(Hoja1!$F$2:F293,B12,Hoja1!D2:D293) -> 9.1755556 | E12: =+AVERAGEIF(Hoja1!$F$2:F293,B12,Hoja1!$E$2:E293) -> 12.541667 | F12: =+E12-D12 -> 3.3661111 | G12: =+D12+2 -> 11.175556
A13: 45596 | B13: Ciclo 11 | C13: =+COUNTIF(Hoja1!$F$2:F294,B13) -> 19 | D13: =+AVERAGEIF(Hoja1!$F$2:F294,B13,Hoja1!$D$2:D294) -> 8.9773684 | E13: =+AVERAGEIF(Hoja1!$F$2:F294,B13,Hoja1!$E$2:E294) -> 12.394737 | F13: =+E13-D13 -> 3.4173684 | G13: =+D13+2 -> 10.977368
A14: =+A13+30 -> 45626 | B14: Ciclo 11 | C14: =+COUNTIF(Hoja1!$F$2:F295,B14) -> 20 | D14: =+AVERAGEIF(Hoja1!$F$2:F295,B14,Hoja1!$D$2:D295) -> 8.7885 | E14: =+AVERAGEIF(Hoja1!$F$2:F295,B14,Hoja1!$E$2:E295) -> 12.2625 | F14: =+E14-D14 -> 3.474 | G14: =+D14+2 -> 10.7885
A15: =+A14+31 -> 45657 | B15: Ciclo 11 | C15: =+COUNTIF(Hoja1!$F$2:F296,B15) -> 21 | D15: =+AVERAGEIF(Hoja1!$F$2:F296,B15,Hoja1!$D$2:D296) -> 8.617619 | E15: =+AVERAGEIF(Hoja1!$F$2:F296,B15,Hoja1!$E$2:E296) -> 12.130952 | F15: =+E15-D15 -> 3.5133333 | G15: =+D15+2 -> 10.617619
A16: 45688 | B16: Ciclo 11 | C16: =+COUNTIF(Hoja1!$F$2:F297,B16) -> 22 | D16: =+AVERAGEIF(Hoja1!$F$2:F297,B16,Hoja1!$D$2:D297) -> 8.4631818 | E16: =+AVERAGEIF(Hoja1!$F$2:F297,B16,Hoja1!$E$2:E297) -> 12.011364 | F16: =+E16-D16 -> 3.5481818 | G16: =+D16+2 -> 10.463182
A17: 45716 | B17: Ciclo 11 | C17: =+COUNTIF(Hoja1!$F$2:F298,B17) -> 23 | D17: =+AVERAGEIF(Hoja1!$F$2:F298,B17,Hoja1!$D$2:D298) -> 8.3247826 | E17: =+AVERAGEIF(Hoja1!$F$2:F298,B17,Hoja1!$E$2:E298) -> 11.902174 | F17: =+E17-D17 -> 3.5773913 | G17: =+D17+2 -> 10.324783
A18: 45747 | B18: Ciclo 11 | C18: =+COUNTIF(Hoja1!$F$2:F299,B18) -> 24 | D18: =+AVERAGEIF(Hoja1!$F$2:F299,B18,Hoja1!$D$2:D299) -> 8.19 | E18: =+AVERAGEIF(Hoja1!$F$2:F299,B18,Hoja1!$E$2:E299) -> 11.802083 | F18: =+E18-D18 -> 3.6120833 | G18: =+D18+2 -> 10.19
A19: 45777 | B19: Ciclo 11 | C19: =+COUNTIF(Hoja1!$F$2:F300,B19) -> 25 | D19: =+AVERAGEIF(Hoja1!$F$2:F300,B19,Hoja1!$D$2:D300) -> 8.0688 | E19: =+AVERAGEIF(Hoja1!$F$2:F300,B19,Hoja1!$E$2:E300) -> 11.71 | F19: =+E19-D19 -> 3.6412 | G19: =+D19+2 -> 10.0688
A20: 45808 | B20: Ciclo 11 | C20: =+COUNTIF(Hoja1!$F$2:F301,B20) -> 26 | D20: =+AVERAGEIF(Hoja1!$F$2:F301,B20,Hoja1!$D$2:D301) -> 7.9526923 | E20: =+AVERAGEIF(Hoja1!$F$2:F301,B20,Hoja1!$E$2:E301) -> 11.615385 | F20: =+E20-D20 -> 3.6626923 | G20: =+D20+2 -> 9.9526923
A21: 45838 | B21: Ciclo 11 | C21: =+COUNTIF(Hoja1!$F$2:F302,B21) -> 27 | D21: =+AVERAGEIF(Hoja1!$F$2:F302,B21,Hoja1!$D$2:D302) -> 7.8366667 | E21: =+AVERAGEIF(Hoja1!$F$2:F302,B21,Hoja1!$E$2:E302) -> 11.527778 | F21: =+E21-D21 -> 3.6911111 | G21: =+D21+2 -> 9.8366667
A22: 45869 | B22: Ciclo 11 | C22: =+COUNTIF(Hoja1!$F$2:F303,B22) -> 28 | D22: =+AVERAGEIF(Hoja1!$F$2:F303,B22,Hoja1!$D$2:D303) -> 7.7317857 | E22: =+AVERAGEIF(Hoja1!$F$2:F303,B22,Hoja1!$E$2:E303) -> 11.446429 | F22: =+E22-D22 -> 3.7146429 | G22: =+D22+2 -> 9.7317857

Sheet Datos recursos
A1: fecha | B1: deuda externos cta 23* | C1: Captación cta 21* | D1: Recursos propios (Todo el patrimonio) cta 3* | E1: Costo deuda | F1: Costo captación | G1: WACC | H1: % deuda externa | I1: % captación | J1: % patrimonio | K1: TPP Recurso
A2: 45565 | B2: 41007.031 | C2: =+SUM(tpp!B2:E2) -> 207999.59 | D2: 162140.31 | E2: 0.1188 | F2: =+tpp!N2 -> 0.079625877 | G2: 0.1065 | H2: =+B2/SUM(B2:D2) -> 0.099738142 | I2: =+C2/SUM(B2:D2) -> 0.50590088 | J2: =+D2/SUM(B2:D2) -> 0.39436098 | K2: =+E2*H2+F2*I2+G2*J2 -> 0.094131137
A3: 45596 | B3: 41184.668 | C3: =+SUM(tpp!B3:E3) -> 207069.41 | D3: 162095.39 | E3: 0.1148 | F3: =+tpp!N3 -> 0.078033596 | G3: 0.1065 | H3: =+B3/SUM(B3:D3) -> 0.10036486 | I3: =+C3/SUM(B3:D3) -> 0.50461723 | J3: =+D3/SUM(B3:D3) -> 0.39501791 | K3: =+E3*H3+F3*I3+G3*J3 -> 0.09296839
A4: =+A3+30 -> 45626 | B4: 46220.716 | C4: =+SUM(tpp!B4:E4) -> 221678.99 | D4: 162708.38 | E4: 0.1131 | F4: =+tpp!N4 -> 0.072545557 | G4: 0.1065 | H4: =+B4/SUM(B4:D4) -> 0.10733824 | I4: =+C4/SUM(B4:D4) -> 0.51480452 | J4: =+D4/SUM(B4:D4) -> 0.37785723 | K4: =+E4*H4+F4*I4+G4*J4 -> 0.089728531
A5: =+A4+31 -> 45657 | B5: 48219.545 | C5: =+SUM(tpp!B5:E5) -> 202407.99 | D5: 163497.78 | E5: 0.1103 | F5: =+tpp!N5 -> 0.077608075 | G5: 0.1065 | H5: =+B5/SUM(B5:D5) -> 0.11643709 | I5: =+C5/SUM(B5:D5) -> 0.48876025 | J5: =+D5/SUM(B5:D5) -> 0.39480267 | K5: =+E5*H5+F5*I5+G5*J5 -> 0.092821236
A6: 45688 | B6: 43777.213 | C6: =+SUM(tpp!B6:E6) -> 203963.41 | D6: 180071.23 | E6: 0.1108 | F6: =+tpp!N6 -> 0.077049081 | G6: 0.1065 | H6: =+B6/SUM(B6:D6) -> 0.10232819 | I6: =+C6/SUM(B6:D6) -> 0.4767596 | J6: =+D6/SUM(B6:D6) -> 0.42091221 | K6: =+E6*H6+F6*I6+G6*J6 -> 0.092899003
A7: 45716 | B7: 44935.876 | C7: =+SUM(tpp!B7:E7) -> 207119.64 | D7: 181148.16 | E7: 0.1111 | F7: =+tpp!N7 -> 0.075594158 | G7: 0.1065 | H7: =+B7/SUM(B7:D7) -> 0.10372921 | I7: =+C7/SUM(B7:D7) -> 0.47811145 | J7: =+D7/SUM(B7:D7) -> 0.41815933 | K7: =+E7*H7+F7*I7+G7*J7 -> 0.092200717
A8: 45747 | B8: 56376.399 | C8: =+SUM(tpp!B8:E8) -> 206183.44 | D8: 169653.91 | E8: 0.1111 | F8: =+tpp!N8 -> 0.077834869 | G8: 0.1065 | H8: =+B8/SUM(B8:D8) -> 0.13043639 | I8: =+C8/SUM(B8:D8) -> 0.47704045 | J8: =+D8/SUM(B8:D8) -> 0.39252316 | K8: =+E8*H8+F8*I8+G8*J8 -> 0.09342558
A9: 45777 | B9: 69442.915 | C9: 216865.87 | D9: 170223.68 | E9: 0.1124 | F9: =+tpp!N9 -> 0.075514102 | G9: 0.1065 | H9: =+B9/SUM(B9:D9) -> 0.15210948 | I9: =+C9/SUM(B9:D9) -> 0.47502837 | J9: =+D9/SUM(B9:D9) -> 0.37286215 | K9: =+E9*H9+F9*I9+G9*J9 -> 0.092678265
A10: 45808 | B10: 82246.158 | C10: 223423.48 | D10: 171405.02 | E10: 0.1149 | F10: =+tpp!N10 -> 0.073599194 | G10: 0.1065 | H10: =+B10/SUM(B10:D10) -> 0.17239683 | I10: =+C10/SUM(B10:D10) -> 0.46831974 | J10: =+D10/SUM(B10:D10) -> 0.35928343 | K10: =+E10*H10+F10*I10+G10*J10 -> 0.092540036
A11: 45838 | B11: 82375.761 | C11: 220833.93 | D11: 172118.38 | E11: 0.115 | F11: =+tpp!N11 -> 0.076723605 | G11: 0.1065 | H11: =+B11/SUM(B11:D11) -> 0.17330296 | I11: =+C11/SUM(B11:D11) -> 0.46459266 | J11: =+D11/SUM(B11:D11) -> 0.36210438 | K11: =+E11*H11+F11*I11+G11*J11 -> 0.09413918
A12: 45869 | B12: 82362.199 | C12: 226191.2 | D12: 172922.44 | E12: 0.115 | F12: =+tpp!N12 -> 0.075521644 | G12: 0.1065 | H12: =+B12/SUM(B12:D12) -> 0.17106196 | I12: =+C12/SUM(B12:D12) -> 0.46978723 | J12: =+D12/SUM(B12:D12) -> 0.35915082 | K12: =+E12*H12+F12*I12+G12*J12 -> 0.093400791
A13: 45900 | E13: 0.1148
A14: 45930 | E14: 0.1157

Sheet tpp
A1: fecha | B1: CDAT | C1: Programados | D1: disponibles | E1: Permanente | F1: Tasa CDAT | G1: Tasa Programados | H1: Tasa disponibles | I1: TasaPermanente | J1: % CDAT | K1: % Programados | L1: % disponibles | M1: % Permanente | N1: TPP
A2: 45565 | B2: 90280.665 | C2: 76759.377 | D2: 26468.877 | E2: 14490.675 | F2: 0.11104272 | G2: 0.077389709 | H2: 0.017070888 | I2: 0.01 | J2: =+B2/SUM($B$2:$E$2) -> 0.43404251 | K2: =+C2/SUM($B$2:$E$2) -> 0.36903619 | L2: =+D2/SUM($B$2:$E$2) -> 0.12725446 | M2: =+E2/SUM($B$2:$E$2) -> 0.069666843 | N2: =+J2*F2+K2*G2+L2*H2+M2*I2 -> 0.079625877
A3: 45596 | B3: 88235.778 | C3: 77087.106 | D3: 27306.063 | E3: 14440.466 | F3: 0.10934381 | G3: 0.076528741 | H3: 0.017085968 | I3: 0.01 | J3: =+B3/SUM(B3:E3) -> 0.42611691 | K3: =+C3/SUM(B3:E3) -> 0.37227664 | L3: =+D3/SUM(B3:E3) -> 0.13186913 | M3: =+E3/SUM(B3:E3) -> 0.069737321 | N3: =+J3*F3+K3*G3+L3*H3+M3*I3 -> 0.078033596
A4: =+A3+30 -> 45626 | B4: 87723.372 | C4: 63359.601 | D4: 56100.758 | E4: 14495.257 | F4: 0.10826615 | G4: 0.087308308 | H4: 0.016177715 | I4: 0.01 | J4: =+B4/SUM(B4:E4) -> 0.39572254 | K4: =+C4/SUM(B4:E4) -> 0.2858169 | L4: =+D4/SUM(B4:E4) -> 0.25307206 | M4: =+E4/SUM(B4:E4) -> 0.065388504 | N4: =+J4*F4+K4*G4+L4*H4+M4*I4 -> 0.072545557
A5: =+A4+31 -> 45657 | B5: 89551.243 | C5: 64233.937 | D5: 33922.218 | E5: 14700.594 | F5: 0.10562352 | G5: 0.0862944 | H5: 0.01650074 | I5: 0.01 | J5: =+B5/SUM(B5:E5) -> 0.44242938 | K5: =+C5/SUM(B5:E5) -> 0.31734882 | L5: =+D5/SUM(B5:E5) -> 0.16759327 | M5: =+E5/SUM(B5:E5) -> 0.072628523 | N5: =+J5*F5+K5*G5+L5*H5+M5*I5 -> 0.077608075
A6: 45688 | B6: 91352.129 | C6: 65794.114 | D6: 32135.468 | E6: 14681.702 | F6: 0.1036 | G6: 0.0847 | H6: 0.016540428 | I6: 0.01 | J6: =+B6/SUM(B6:E6) -> 0.44788488 | K6: =+C6/SUM(B6:E6) -> 0.32257802 | L6: =+D6/SUM(B6:E6) -> 0.15755506 | M6: =+E6/SUM(B6:E6) -> 0.071982036 | N6: =+J6*F6+K6*G6+L6*H6+M6*I6 -> 0.077049081
A7: 45716 | B7: 92480.89 | C7: 67254.423 | D7: 32684.064 | E7: 14700.258 | F7: 0.10175989 | G7: 0.082857949 | H7: 0.01611252 | I7: 0.01 | J7: =+B7/SUM(B7:E7) -> 0.44650953 | K7: =+C7/SUM(B7:E7) -> 0.32471293 | L7: =+D7/SUM(B7:E7) -> 0.15780283 | M7: =+E7/SUM(B7:E7) -> 0.07097472 | N7: =+J7*F7+K7*G7+L7*H7+M7*I7 -> 0.075594158
A8: 45747 | B8: 92822.723 | C8: 68663.506 | D8: 29937.309 | E8: 14759.906 | F8: 0.1012 | G8: 0.087527504 | H8: 0.016603275 | I8: 0.01 | J8: =+B8/SUM(B8:E8) -> 0.45019484 | K8: =+C8/SUM(B8:E8) -> 0.33302143 | L8: =+D8/SUM(B8:E8) -> 0.14519744 | M8: =+E8/SUM(B8:E8) -> 0.071586281 | N8: =+J8*F8+K8*G8+L8*H8+M8*I8 -> 0.077834869
A9: 45777 | B9: 92923.13 | C9: 67522.217 | D9: 31537.726 | E9: 14843.073 | F9: 0.100995 | G9: 0.082253658 | H9: 0.016841388 | I9: 0.01 | J9: =+B9/SUM(B9:E9) -> 0.44928135 | K9: =+C9/SUM(B9:E9) -> 0.32646848 | L9: =+D9/SUM(B9:E9) -> 0.15248423 | M9: =+E9/SUM(B9:E9) -> 0.071765942 | N9: =+J9*F9+K9*G9+L9*H9+M9*I9 -> 0.075514102
A10: 45808 | B10: 93039.533 | C10: 69031.027 | D10: 36060.447 | E10: 14908.372 | F10: 0.10081436 | G10: 0.081051039 | H10: 0.015409827 | I10: 0.01 | J10: =+B10/SUM(B10:E10) -> 0.43672458 | K10: =+C10/SUM(B10:E10) -> 0.32402942 | L10: =+D10/SUM(B10:E10) -> 0.16926658 | M10: =+E10/SUM(B10:E10) -> 0.069979419 | N10: =+J10*F10+K10*G10+L10*H10+M10*I10 -> 0.073599194
A11: 45838 | B11: 96739.681 | C11: 70984.581 | D11: 27513.705 | E11: 14966.827 | F11: 0.10211808 | G11: 0.079514239 | H11: 0.016531599 | I11: 0.01 | J11: =+B11/SUM(B11:E11) -> 0.46021634 | K11: =+C11/SUM(B11:E11) -> 0.33769249 | L11: =+D11/SUM(B11:E11) -> 0.13089 | M11: =+E11/SUM(B11:E11) -> 0.071201169 | N11: =+J11*F11+K11*G11+L11*H11+M11*I11 -> 0.076723605
A12: 45869 | B12: 100212.82 | C12: 72544.614 | D12: 27485.329 | E12: 15025.205 | F12: 0.1030143 | G12: 0.073483204 | H12: 0.016480598 | I12: 0.01 | J12: =+B12/SUM(B12:E12) -> 0.46552592 | K12: =+C12/SUM(B12:E12) -> 0.33699679 | L12: =+D12/SUM(B12:E12) -> 0.12767961 | M12: =+E12/SUM(B12:E12) -> 0.069797681 | N12: =+J12*F12+K12*G12+L12*H12+M12*I12 -> 0.075521644
A15: 1000000
