Workbook

Sheet 1. Balance General
A1: ISAGEN S.A. E.S.P.
A2: ESTADO DE SITUACIÓN FINANCIERA
A3: Valores en millones de pesos colombianos (COP)
A5: CONCEPTO | B5: 2020 | C5: 2021 | D5: 2022 | E5: 2023 | F5: 2024 | G5: 2025 (Sep)
A6: ACTIVOS NO CORRIENTES
A7: Propiedades, planta y equipo, neto | B7: 15179609 | C7: 17230679 | D7: 17365315 | E7: 17742271 | F7: 17522981 | G7: 17319341
A8: Activos intangibles, neto | B8: 2774772 | C8: 2783815 | D8: 2755491 | E8: 2760600 | F8: 2769524 | G8: 2783735
A9: Cuentas por cobrar, neto | B9: 26655 | C9: 24142 | D9: 2024312 | E9: 1910168 | F9: 32960 | G9: 60923
A10: Instrumentos financieros | B10: 84 | C10: 84 | D10: 84 | E10: 84 | F10: 2493808 | G10: 544561
A11: Operaciones con derivados | B11: - | C11: 85660 | D11: 228189 | E11: 31816 | F11: 90034 | G11: 1202870
A12: Efectivo restringido | B12: 2127 | C12: 2185 | D12: 2159 | E12: 2541 | F12: 2928 | G12: 27114
A13: Otros activos | B13: 950 | C13: 950 | D13: 950 | G13: 3230
A14: Total Activos No Corrientes | B14: 17984197 | C14: 20127515 | D14: 22376500 | E14: 22447480 | F14: 22912235 | G14: 21941774
A16: ACTIVOS CORRIENTES
A17: Inventarios | B17: 34138 | C17: 35705 | D17: 27889 | E17: 29526 | F17: 33172 | G17: 41304
A18: Cuentas por cobrar, neto | B18: 514164 | C18: 663842 | D18: 883971 | E18: 934414 | F18: 815437 | G18: 735617
A19: Instrumentos financieros | B19: 84 | C19: 84 | D19: 84 | E19: 84 | F19: 2493808 | G19: 2716711
A20: Activos por impuestos | B20: 434 | C20: 52077 | D20: 1919 | E20: 7372 | F20: 21940 | G20: 70638
A21: Otros activos | B21: 11708 | C21: 28345 | D21: 57682 | E21: 26385 | F21: 38012 | G21: 143617
A22: Operaciones con derivados | B22: - | C22: 24079 | D22: 150851 | E22: 61809 | F22: 25205 | G22: 48341
A23: Efectivo restringido | B23: 261 | C23: 16901 | D23: 50 | E23: 50 | F23: 50 | G23: 8297
A24: Efectivo y equivalentes de efectivo | B24: 83749 | C24: 172827 | D24: 309200 | E24: 220352 | F24: 447198 | G24: 229542
A25: Total Activos Corrientes | B25: 644454 | C25: 993776 | D25: 1431562 | E25: 1279908 | F25: 1381014 | G25: 3923479
A26: nan
A27: TOTAL ACTIVOS | B27: 18628651 | C27: 21121291 | D27: 23808062 | E27: 23727388 | F27: 24293249 | G27: 25865253
A28: nan
A29: PATRIMONIO
A30: Capital | B30: 141552 | C30: 141552 | D30: 141552 | E30: 141552 | F30: 141552 | G30: 141552
A31: Reservas | B31: 2006640 | C31: 1580616 | D31: 660660 | E31: 863781 | F31: 1140297 | G31: 1550093
A32: Superávit de capital | B32: 2074259 | C32: 2074259 | D32: 2074259 | E32: 2074259 | F32: 2074259 | G32: 2074259
A33: Ganancias retenidas | B33: 1268261 | C33: 1268261 | D33: 1268261 | E33: 1268261 | F33: 1268350 | G33: 1268350
A34: Otro resultado integral | B34: -28353 | C34: 91255 | D34: 185776 | E34: 46069 | F34: 32508 | G34: 47436
A35: Resultado integral total periodo (Utilidad Neta) | B35: 496129 | C35: 523127 | D35: 1233838 | E35: 1035242 | F35: 904616 | G35: 606104
A36: Total Patrimonio de los Accionistas | B36: 5958488 | C36: 5679070 | D36: 5564346 | E36: 5429164 | F36: 5561582 | G36: 5687794
A37: nan
A38: PASIVOS NO CORRIENTES
A39: Operaciones de financiamiento | B39: 5834931 | C39: 7132894 | D39: 9781531 | E39: 9814359 | F39: 10148678 | G39: 10985428
A40: Obligaciones con vinculados | B40: 2767416 | C40: 3434629 | D40: 2540445 | E40: 2541954 | F40: 2542108 | G40: 2538988
A41: Operaciones con derivados | B41: 13150 | C41: - | D41: 18602 | E41: 3781 | F41: 11065 | G41: -
A42: Impuestos, contribuciones y tasas | B42: 3458998 | C42: 4208665 | D42: 4423094 | E42: 4506519 | F42: 4654129 | G42: 4753643
...

Sheet 2. Estado de Resultados
A1: ISAGEN S.A. E.S.P.
A2: ESTADO DE RESULTADOS INTEGRAL
A3: Valores en millones de pesos colombianos (COP)
A5: CONCEPTO | B5: 2020 | C5: 2021 | D5: 2022 | E5: 2023 | F5: 2024 | G5: 2025 (9m)
A6: Ingresos de contratos con clientes | B6: 3211250 | C6: 3481508 | D6: 4816990 | E6: 5523362 | F6: 6095701 | G6: 3847514
A7: Costo de ventas | B7: -1531443 | C7: -1345155 | D7: -1601980 | E7: -2427742 | F7: -3156150 | G7: -1505886
A8: Utilidad Bruta | B8: =SUM(B6:B7) | C8: =SUM(C6:C7) | D8: =SUM(D6:D7) | E8: =SUM(E6:E7) | F8: =SUM(F6:F7) | G8: =SUM(G6:G7)
A9: Otros ingresos | B9: 36002 | C9: 5951 | D9: 5082 | E9: 9704 | F9: 37485 | G9: 6665
A10: Gastos de administración | B10: -132538 | C10: -124062 | D10: -155931 | E10: -161731 | F10: -184607 | G10: -130464
A11: Otros gastos | B11: -13003 | C11: -8191 | D11: -94550 | E11: -37608 | F11: -53946 | G11: -38386
A12: Ingresos financieros | B12: 22992 | C12: 8278 | D12: 198968 | E12: 414971 | F12: 416117 | G12: 226003
A13: Gastos financieros | B13: -821768 | C13: -731988 | D13: -1317580 | E13: -1821155 | F13: -1870991 | G13: -1360062
A14: Diferencia en cambio, neta | B14: -34923 | C14: 7 | D14: -27239 | E14: 61822 | F14: -19632 | G14: -250894
A15: Utilidad Antes de Impuestos | B15: 736569 | C15: 1286348 | D15: 1823760 | E15: 1561623 | F15: 1263977 | G15: 794490
A16: EBIT | B16: =B15-B13-B12 | C16: =C15-C13-C12 | D16: =D15-D13-D12 | E16: =E15-E13-E12 | F16: =F15-F13-F12 | G16: =G15-G13-G12
A17: Depreciación | B17: 229772 | C17: 233257 | D17: 259748 | E17: 279121 | F17: 304317 | G17: 235541
A18: Amortización | B18: 1864 | C18: 3444 | D18: 2712 | E18: 2728 | F18: 5711 | G18: 3472
A19: EBITDA | B19: =B16+B17+B18 | C19: =C16+C17+C18 | D19: =D16+D17+D18 | E19: =E16+E17+E18 | F19: =F16+F17+F18 | G19: =G16+G17+G18
A20: Impuesto de renta - Corriente | B20: -165680 | C20: -70862 | D20: -467248 | E20: -326019 | F20: -234854 | G20: -91087
A21: Impuesto de renta - Diferido | B21: -74760 | C21: -692359 | D21: -167874 | E21: -151518 | F21: -154288 | G21: -92160
A22: Utilidad Neta del Periodo | B22: 496129 | C22: 523127 | D22: 1233838 | E22: 1035242 | F22: 904616 | G22: 606104
A25: OTRO RESULTADO INTEGRAL (ORI)
A26: Ganancias actuariales (Beneficios definidos) | B26: 1015 | C26: 10906 | D26: 17374 | E26: -27643 | F26: 10416
A27: Coberturas flujo de efectivo | B27: -29050 | C27: 108702 | D27: 73128 | E27: -112064 | F27: -23977
A28: Total Otro Resultado Integral, neto | B28: -28035 | C28: 119608 | D28: 94521 | E28: -139707 | F28: -13561 | G28: 14928
A29: RESULTADO INTEGRAL TOTAL | B29: 468094 | C29: 642735 | D29: 1328359 | E29: 895535 | F29: 891055 | G29: 621032
A30: nan
A31: Utilidad básica y diluida por acción ($) | B31: 405 | C31: 427 | D31: 1008 | E31: 846 | F31: 739 | G31: 495

Sheet 3. Análisis Vertical BSC
A1: ISAGEN S.A. E.S.P.
A2: ANÁLISIS VERTICAL - BALANCE GENERAL
A3: Composición porcentual respecto al Total de Activos (%)
A5: CONCEPTO | B5: 2020 | C5: 2021 | D5: 2022 | E5: 2023 | F5: 2024 | G5: 2025 (Sep)
A6: ACTIVOS NO CORRIENTES | B6: =('1. Balance General'!B6/'1. Balance General'!B27)*100 | C6: =('1. Balance General'!C6/'1. Balance General'!C27)*100 | D6: =('1. Balance General'!D6/'1. Balance General'!D27)*100 | E6: =('1. Balance General'!E6/'1. Balance General'!E27)*100 | F6: =('1. Balance General'!F6/'1. Balance General'!F27)*100 | G6: =('1. Balance General'!G6/'1. Balance General'!G27)*100
A7: Propiedades, planta y equipo, neto | B7: =('1. Balance General'!B7/'1. Balance General'!B27)*100 | C7: =('1. Balance General'!C7/'1. Balance General'!C27)*100 | D7: =('1. Balance General'!D7/'1. Balance General'!D27)*100 | E7: =('1. Balance General'!E7/'1. Balance General'!E27)*100 | F7: =('1. Balance General'!F7/'1. Balance General'!F27)*100 | G7: =('1. Balance General'!G7/'1. Balance General'!G27)*100
A8: Activos intangibles, neto | B8: =('1. Balance General'!B8/'1. Balance General'!B27)*100 | C8: =('1. Balance General'!C8/'1. Balance General'!C27)*100 | D8: =('1. Balance General'!D8/'1. Balance General'!D27)*100 | E8: =('1. Balance General'!E8/'1. Balance General'!E27)*100 | F8: =('1. Balance General'!F8/'1. Balance General'!F27)*100 | G8: =('1. Balance General'!G8/'1. Balance General'!G27)*100
A9: Cuentas por cobrar, neto | B9: =('1. Balance General'!B9/'1. Balance General'!B27)*100 | C9: =('1. Balance General'!C9/'1. Balance General'!C27)*100 | D9: =('1. Balance General'!D9/'1. Balance General'!D27)*100 | E9: =('1. Balance General'!E9/'1. Balance General'!E27)*100 | F9: =('1. Balance General'!F9/'1. Balance General'!F27)*100 | G9: =('1. Balance General'!G9/'1. Balance General'!G27)*100
A10: Instrumentos financieros | B10: =('1. Balance General'!B10/'1. Balance General'!B27)*100 | C10: =('1. Balance General'!C10/'1. Balance General'!C27)*100 | D10: =('1. Balance General'!D10/'1. Balance General'!D27)*100 | E10: =('1. Balance General'!E10/'1. Balance General'!E27)*100 | F10: =('1. Balance General'!F10/'1. Balance General'!F27)*100 | G10: =('1. Balance General'!G10/'1. Balance General'!G27)*100
A11: Operaciones con derivados | B11: =('1. Balance General'!B11/'1. Balance General'!B27)*100 | C11: =('1. Balance General'!C11/'1. Balance General'!C27)*100 | D11: =('1. Balance General'!D11/'1. Balance General'!D27)*100 | E11: =('1. Balance General'!E11/'1. Balance General'!E27)*100 | F11: =('1. Balance General'!F11/'1. Balance General'!F27)*100 | G11: =('1. Balance General'!G11/'1. Balance General'!G27)*100
A12: Efectivo restringido | B12: =('1. Balance General'!B12/'1. Balance General'!B27)*100 | C12: =('1. Balance General'!C12/'1. Balance General'!C27)*100 | D12: =('1. Balance General'!D12/'1. Balance General'!D27)*100 | E12: =('1. Balance General'!E12/'1. Balance General'!E27)*100 | F12: =('1. Balance General'!F12/'1. Balance General'!F27)*100 | G12: =('1. Balance General'!G12/'1. Balance General'!G27)*100
A13: Otros activos | B13: =('1. Balance General'!B13/'1. Balance General'!B27)*100 | C13: =('1. Balance General'!C13/'1. Balance General'!C27)*100 | D13: =('1. Balance General'!D13/'1. Balance General'!D27)*100 | E13: =('1. Balance General'!E13/'1. Balance General'!E27)*100 | F13: =('1. Balance General'!F13/'1. Balance General'!F27)*100 | G13: =('1. Balance General'!G13/'1. Balance General'!G27)*100
A14: Total Activos No Corrientes | B14: =('1. Balance General'!B14/'1. Balance General'!B27)*100 | C14: =('1. Balance General'!C14/'1. Balance General'!C27)*100 | D14: =('1. Balance General'!D14/'1. Balance General'!D27)*100 | E14: =('1. Balance General'!E14/'1. Balance General'!E27)*100 | F14: =('1. Balance General'!F14/'1. Balance General'!F27)*100 | G14: =('1. Balance General'!G14/'1. Balance General'!G27)*100
A16: ACTIVOS CORRIENTES | B16: =('1. Balance General'!B16/'1. Balance General'!B27)*100 | C16: =('1. Balance General'!C16/'1. Balance General'!C27)*100 | D16: =('1. Balance General'!D16/'1. Balance General'!D27)*100 | E16: =('1. Balance General'!E16/'1. Balance General'!E27)*100 | F16: =('1. Balance General'!F16/'1. Balance General'!F27)*100 | G16: =('1. Balance General'!G16/'1. Balance General'!G27)*100
A17: Inventarios | B17: =('1. Balance General'!B17/'1. Balance General'!B27)*100 | C17: =('1. Balance General'!C17/'1. Balance General'!C27)*100 | D17: =('1. Balance General'!D17/'1. Balance General'!D27)*100 | E17: =('1. Balance General'!E17/'1. Balance General'!E27)*100 | F17: =('1. Balance General'!F17/'1. Balance General'!F27)*100 | G17: =('1. Balance General'!G17/'1. Balance General'!G27)*100
A18: Cuentas por cobrar, neto | B18: =('1. Balance General'!B18/'1. Balance General'!B27)*100 | C18: =('1. Balance General'!C18/'1. Balance General'!C27)*100 | D18: =('1. Balance General'!D18/'1. Balance General'!D27)*100 | E18: =('1. Balance General'!E18/'1. Balance General'!E27)*100 | F18: =('1. Balance General'!F18/'1. Balance General'!F27)*100 | G18: =('1. Balance General'!G18/'1. Balance General'!G27)*100
A19: Instrumentos financieros | B19: =('1. Balance General'!B19/'1. Balance General'!B27)*100 | C19: =('1. Balance General'!C19/'1. Balance General'!C27)*100 | D19: =('1. Balance General'!D19/'1. Balance General'!D27)*100 | E19: =('1. Balance General'!E19/'1. Balance General'!E27)*100 | F19: =('1. Balance General'!F19/'1. Balance General'!F27)*100 | G19: =('1. Balance General'!G19/'1. Balance General'!G27)*100
A20: Activos por impuestos | B20: =('1. Balance General'!B20/'1. Balance General'!B27)*100 | C20: =('1. Balance General'!C20/'1. Balance General'!C27)*100 | D20: =('1. Balance General'!D20/'1. Balance General'!D27)*100 | E20: =('1. Balance General'!E20/'1. Balance General'!E27)*100 | F20: =('1. Balance General'!F20/'1. Balance General'!F27)*100 | G20: =('1. Balance General'!G20/'1. Balance General'!G27)*100
A21: Otros activos | B21: =('1. Balance General'!B21/'1. Balance General'!B27)*100 | C21: =('1. Balance General'!C21/'1. Balance General'!C27)*100 | D21: =('1. Balance General'!D21/'1. Balance General'!D27)*100 | E21: =('1. Balance General'!E21/'1. Balance General'!E27)*100 | F21: =('1. Balance General'!F21/'1. Balance General'!F27)*100 | G21: =('1. Balance General'!G21/'1. Balance General'!G27)*100
A22: Operaciones con derivados | B22: =('1. Balance General'!B22/'1. Balance General'!B27)*100 | C22: =('1. Balance General'!C22/'1. Balance General'!C27)*100 | D22: =('1. Balance General'!D22/'1. Balance General'!D27)*100 | E22: =('1. Balance General'!E22/'1. Balance General'!E27)*100 | F22: =('1. Balance General'!F22/'1. Balance General'!F27)*100 | G22: =('1. Balance General'!G22/'1. Balance General'!G27)*100
A23: Efectivo restringido | B23: =('1. Balance General'!B23/'1. Balance General'!B27)*100 | C23: =('1. Balance General'!C23/'1. Balance General'!C27)*100 | D23: =('1. Balance General'!D23/'1. Balance General'!D27)*100 | E23: =('1. Balance General'!E23/'1. Balance General'!E27)*100 | F23: =('1. Balance General'!F23/'1. Balance General'!F27)*100 | G23: =('1. Balance General'!G23/'1. Balance General'!G27)*100
A24: Efectivo y equivalentes de efectivo | B24: =('1. Balance General'!B24/'1. Balance General'!B27)*100 | C24: =('1. Balance General'!C24/'1. Balance General'!C27)*100 | D24: =('1. Balance General'!D24/'1. Balance General'!D27)*100 | E24: =('1. Balance General'!E24/'1. Balance General'!E27)*100 | F24: =('1. Balance General'!F24/'1. Balance General'!F27)*100 | G24: =('1. Balance General'!G24/'1. Balance General'!G27)*100
A25: Total Activos Corrientes | B25: =('1. Balance General'!B25/'1. Balance General'!B27)*100 | C25: =('1. Balance General'!C25/'1. Balance General'!C27)*100 | D25: =('1. Balance General'!D25/'1. Balance General'!D27)*100 | E25: =('1. Balance General'!E25/'1. Balance General'!E27)*100 | F25: =('1. Balance General'!F25/'1. Balance General'!F27)*100 | G25: =('1. Balance General'!G25/'1. Balance General'!G27)*100
A27: TOTAL ACTIVOS | B27: =('1. Balance General'!B27/'1. Balance General'!B27)*100 | C27: =('1. Balance General'!C27/'1. Balance General'!C27)*100 | D27: =('1. Balance General'!D27/'1. Balance General'!D27)*100 | E27: =('1. Balance General'!E27/'1. Balance General'!E27)*100 | F27: =('1. Balance General'!F27/'1. Balance General'!F27)*100 | G27: =('1. Balance General'!G27/'1. Balance General'!G27)*100
A29: PATRIMONIO | B29: =('1. Balance General'!B29/'1. Balance General'!B27)*100 | C29: =('1. Balance General'!C29/'1. Balance General'!C27)*100 | D29: =('1. Balance General'!D29/'1. Balance General'!D27)*100 | E29: =('1. Balance General'!E29/'1. Balance General'!E27)*100 | F29: =('1. Balance General'!F29/'1. Balance General'!F27)*100 | G29: =('1. Balance General'!G29/'1. Balance General'!G27)*100
A30: Capital | B30: =('1. Balance General'!B30/'1. Balance General'!B27)*100 | C30: =('1. Balance General'!C30/'1. Balance General'!C27)*100 | D30: =('1. Balance General'!D30/'1. Balance General'!D27)*100 | E30: =('1. Balance General'!E30/'1. Balance General'!E27)*100 | F30: =('1. Balance General'!F30/'1. Balance General'!F27)*100 | G30: =('1. Balance General'!G30/'1. Balance General'!G27)*100
A31: Reservas | B31: =('1. Balance General'!B31/'1. Balance General'!B27)*100 | C31: =('1. Balance General'!C31/'1. Balance General'!C27)*100 | D31: =('1. Balance General'!D31/'1. Balance General'!D27)*100 | E31: =('1. Balance General'!E31/'1. Balance General'!E27)*100 | F31: =('1. Balance General'!F31/'1. Balance General'!F27)*100 | G31: =('1. Balance General'!G31/'1. Balance General'!G27)*100
A32: Superávit de capital | B32: =('1. Balance General'!B32/'1. Balance General'!B27)*100 | C32: =('1. Balance General'!C32/'1. Balance General'!C27)*100 | D32: =('1. Balance General'!D32/'1. Balance General'!D27)*100 | E32: =('1. Balance General'!E32/'1. Balance General'!E27)*100 | F32: =('1. Balance General'!F32/'1. Balance General'!F27)*100 | G32: =('1. Balance General'!G32/'1. Balance General'!G27)*100
A33: Ganancias retenidas | B33: =('1. Balance General'!B33/'1. Balance General'!B27)*100 | C33: =('1. Balance General'!C33/'1. Balance General'!C27)*100 | D33: =('1. Balance General'!D33/'1. Balance General'!D27)*100 | E33: =('1. Balance General'!E33/'1. Balance General'!E27)*100 | F33: =('1. Balance General'!F33/'1. Balance General'!F27)*100 | G33: =('1. Balance General'!G33/'1. Balance General'!G27)*100
A34: Otro resultado integral | B34: =('1. Balance General'!B34/'1. Balance General'!B27)*100 | C34: =('1. Balance General'!C34/'1. Balance General'!C27)*100 | D34: =('1. Balance General'!D34/'1. Balance General'!D27)*100 | E34: =('1. Balance General'!E34/'1. Balance General'!E27)*100 | F34: =('1. Balance General'!F34/'1. Balance General'!F27)*100 | G34: =('1. Balance General'!G34/'1. Balance General'!G27)*100
A35: Resultado integral total periodo (Utilidad Neta) | B35: =('1. Balance General'!B35/'1. Balance General'!B27)*100 | C35: =('1. Balance General'!C35/'1. Balance General'!C27)*100 | D35: =('1. Balance General'!D35/'1. Balance General'!D27)*100 | E35: =('1. Balance General'!E35/'1. Balance General'!E27)*100 | F35: =('1. Balance General'!F35/'1. Balance General'!F27)*100 | G35: =('1. Balance General'!G35/'1. Balance General'!G27)*100
A36: Total Patrimonio de los Accionistas | B36: =('1. Balance General'!B36/'1. Balance General'!B27)*100 | C36: =('1. Balance General'!C36/'1. Balance General'!C27)*100 | D36: =('1. Balance General'!D36/'1. Balance General'!D27)*100 | E36: =('1. Balance General'!E36/'1. Balance General'!E27)*100 | F36: =('1. Balance General'!F36/'1. Balance General'!F27)*100 | G36: =('1. Balance General'!G36/'1. Balance General'!G27)*100
A38: PASIVOS NO CORRIENTES | B38: =('1. Balance General'!B38/'1. Balance General'!B27)*100 | C38: =('1. Balance General'!C38/'1. Balance General'!C27)*100 | D38: =('1. Balance General'!D38/'1. Balance General'!D27)*100 | E38: =('1. Balance General'!E38/'1. Balance General'!E27)*100 | F38: =('1. Balance General'!F38/'1. Balance General'!F27)*100 | G38: =('1. Balance General'!G38/'1. Balance General'!G27)*100
A39: Operaciones de financiamiento | B39: =('1. Balance General'!B39/'1. Balance General'!B27)*100 | C39: =('1. Balance General'!C39/'1. Balance General'!C27)*100 | D39: =('1. Balance General'!D39/'1. Balance General'!D27)*100 | E39: =('1. Balance General'!E39/'1. Balance General'!E27)*100 | F39: =('1. Balance General'!F39/'1. Balance General'!F27)*100 | G39: =('1. Balance General'!G39/'1. Balance General'!G27)*100
A40: Obligaciones con vinculados | B40: =('1. Balance General'!B40/'1. Balance General'!B27)*100 | C40: =('1. Balance General'!C40/'1. Balance General'!C27)*100 | D40: =('1. Balance General'!D40/'1. Balance General'!D27)*100 | E40: =('1. Balance General'!E40/'1. Balance General'!E27)*100 | F40: =('1. Balance General'!F40/'1. Balance General'!F27)*100 | G40: =('1. Balance General'!G40/'1. Balance General'!G27)*100
A41: Operaciones con derivados | B41: =('1. Balance General'!B41/'1. Balance General'!B27)*100 | C41: =('1. Balance General'!C41/'1. Balance General'!C27)*100 | D41: =('1. Balance General'!D41/'1. Balance General'!D27)*100 | E41: =('1. Balance General'!E41/'1. Balance General'!E27)*100 | F41: =('1. Balance General'!F41/'1. Balance General'!F27)*100 | G41: =('1. Balance General'!G41/'1. Balance General'!G27)*100
A42: Impuestos, contribuciones y tasas | B42: =('1. Balance General'!B42/'1. Balance General'!B27)*100 | C42: =('1. Balance General'!C42/'1. Balance General'!C27)*100 | D42: =('1. Balance General'!D42/'1. Balance General'!D27)*100 | E42: =('1. Balance General'!E42/'1. Balance General'!E27)*100 | F42: =('1. Balance General'!F42/'1. Balance General'!F27)*100 | G42: =('1. Balance General'!G42/'1. Balance General'!G27)*100
A43: Beneficios a empleados | B43: =('1. Balance General'!B43/'1. Balance General'!B27)*100 | C43: =('1. Balance General'!C43/'1. Balance General'!C27)*100 | D43: =('1. Balance General'!D43/'1. Balance General'!D27)*100 | E43: =('1. Balance General'!E43/'1. Balance General'!E27)*100 | F43: =('1. Balance General'!F43/'1. Balance General'!F27)*100 | G43: =('1. Balance General'!G43/'1. Balance General'!G27)*100
A44: Provisiones | B44: =('1. Balance General'!B44/'1. Balance General'!B27)*100 | C44: =('1. Balance General'!C44/'1. Balance General'!C27)*100 | D44: =('1. Balance General'!D44/'1. Balance General'!D27)*100 | E44: =('1. Balance General'!E44/'1. Balance General'!E27)*100 | F44: =('1. Balance General'!F44/'1. Balance General'!F27)*100 | G44: =('1. Balance General'!G44/'1. Balance General'!G27)*100
A45: Cuentas por pagar | B45: =('1. Balance General'!B45/'1. Balance General'!B27)*100 | C45: =('1. Balance General'!C45/'1. Balance General'!C27)*100 | D45: =('1. Balance General'!D45/'1. Balance General'!D27)*100 | E45: =('1. Balance General'!E45/'1. Balance General'!E27)*100 | F45: =('1. Balance General'!F45/'1. Balance General'!F27)*100 | G45: =('1. Balance General'!G45/'1. Balance General'!G27)*100
...

Sheet 4. Análisis Horizontal BSC
A1: ISAGEN S.A. E.S.P.
A2: ANÁLISIS HORIZONTAL - BALANCE GENERAL
A3: Variación porcentual interanual (%)
A5: CONCEPTO | B5: 2020-2021 | C5: 2021-2022 | D5: 2022-2023 | E5: 2023-2024 | F5: 2024-2025
A6: ACTIVOS NO CORRIENTES
A7: Propiedades, planta y equipo, neto | B7: =(('1. Balance General'!C7-'1. Balance General'!B7)/'1. Balance General'!B7)*100 | C7: =(('1. Balance General'!D7-'1. Balance General'!C7)/'1. Balance General'!C7)*100 | D7: =(('1. Balance General'!E7-'1. Balance General'!D7)/'1. Balance General'!D7)*100 | E7: =(('1. Balance General'!F7-'1. Balance General'!E7)/'1. Balance General'!E7)*100 | F7: =(('1. Balance General'!G7-'1. Balance General'!F7)/'1. Balance General'!F7)*100
A8: Activos intangibles, neto | B8: =(('1. Balance General'!C8-'1. Balance General'!B8)/'1. Balance General'!B8)*100 | C8: =(('1. Balance General'!D8-'1. Balance General'!C8)/'1. Balance General'!C8)*100 | D8: =(('1. Balance General'!E8-'1. Balance General'!D8)/'1. Balance General'!D8)*100 | E8: =(('1. Balance General'!F8-'1. Balance General'!E8)/'1. Balance General'!E8)*100 | F8: =(('1. Balance General'!G8-'1. Balance General'!F8)/'1. Balance General'!F8)*100
A9: Cuentas por cobrar, neto | B9: =(('1. Balance General'!C9-'1. Balance General'!B9)/'1. Balance General'!B9)*100 | C9: =(('1. Balance General'!D9-'1. Balance General'!C9)/'1. Balance General'!C9)*100 | D9: =(('1. Balance General'!E9-'1. Balance General'!D9)/'1. Balance General'!D9)*100 | E9: =(('1. Balance General'!F9-'1. Balance General'!E9)/'1. Balance General'!E9)*100 | F9: =(('1. Balance General'!G9-'1. Balance General'!F9)/'1. Balance General'!F9)*100
A10: Instrumentos financieros | B10: =(('1. Balance General'!C10-'1. Balance General'!B10)/'1. Balance General'!B10)*100 | C10: =(('1. Balance General'!D10-'1. Balance General'!C10)/'1. Balance General'!C10)*100 | D10: =(('1. Balance General'!E10-'1. Balance General'!D10)/'1. Balance General'!D10)*100 | E10: =(('1. Balance General'!F10-'1. Balance General'!E10)/'1. Balance General'!E10)*100 | F10: =(('1. Balance General'!G10-'1. Balance General'!F10)/'1. Balance General'!F10)*100
A11: Operaciones con derivados | B11: =(('1. Balance General'!C11-'1. Balance General'!B11)/'1. Balance General'!B11)*100 | C11: =(('1. Balance General'!D11-'1. Balance General'!C11)/'1. Balance General'!C11)*100 | D11: =(('1. Balance General'!E11-'1. Balance General'!D11)/'1. Balance General'!D11)*100 | E11: =(('1. Balance General'!F11-'1. Balance General'!E11)/'1. Balance General'!E11)*100 | F11: =(('1. Balance General'!G11-'1. Balance General'!F11)/'1. Balance General'!F11)*100
A12: Efectivo restringido | B12: =(('1. Balance General'!C12-'1. Balance General'!B12)/'1. Balance General'!B12)*100 | C12: =(('1. Balance General'!D12-'1. Balance General'!C12)/'1. Balance General'!C12)*100 | D12: =(('1. Balance General'!E12-'1. Balance General'!D12)/'1. Balance General'!D12)*100 | E12: =(('1. Balance General'!F12-'1. Balance General'!E12)/'1. Balance General'!E12)*100 | F12: =(('1. Balance General'!G12-'1. Balance General'!F12)/'1. Balance General'!F12)*100
A13: Otros activos | B13: =(('1. Balance General'!C13-'1. Balance General'!B13)/'1. Balance General'!B13)*100 | C13: =(('1. Balance General'!D13-'1. Balance General'!C13)/'1. Balance General'!C13)*100 | D13: =(('1. Balance General'!E13-'1. Balance General'!D13)/'1. Balance General'!D13)*100 | E13: =(('1. Balance General'!F13-'1. Balance General'!E13)/'1. Balance General'!E13)*100 | F13: =(('1. Balance General'!G13-'1. Balance General'!F13)/'1. Balance General'!F13)*100
A14: Total Activos No Corrientes | B14: =(('1. Balance General'!C14-'1. Balance General'!B14)/'1. Balance General'!B14)*100 | C14: =(('1. Balance General'!D14-'1. Balance General'!C14)/'1. Balance General'!C14)*100 | D14: =(('1. Balance General'!E14-'1. Balance General'!D14)/'1. Balance General'!D14)*100 | E14: =(('1. Balance General'!F14-'1. Balance General'!E14)/'1. Balance General'!E14)*100 | F14: =(('1. Balance General'!G14-'1. Balance General'!F14)/'1. Balance General'!F14)*100
A16: ACTIVOS CORRIENTES
A17: Inventarios | B17: =(('1. Balance General'!C17-'1. Balance General'!B17)/'1. Balance General'!B17)*100 | C17: =(('1. Balance General'!D17-'1. Balance General'!C17)/'1. Balance General'!C17)*100 | D17: =(('1. Balance General'!E17-'1. Balance General'!D17)/'1. Balance General'!D17)*100 | E17: =(('1. Balance General'!F17-'1. Balance General'!E17)/'1. Balance General'!E17)*100 | F17: =(('1. Balance General'!G17-'1. Balance General'!F17)/'1. Balance General'!F17)*100
A18: Cuentas por cobrar, neto | B18: =(('1. Balance General'!C18-'1. Balance General'!B18)/'1. Balance General'!B18)*100 | C18: =(('1. Balance General'!D18-'1. Balance General'!C18)/'1. Balance General'!C18)*100 | D18: =(('1. Balance General'!E18-'1. Balance General'!D18)/'1. Balance General'!D18)*100 | E18: =(('1. Balance General'!F18-'1. Balance General'!E18)/'1. Balance General'!E18)*100 | F18: =(('1. Balance General'!G18-'1. Balance General'!F18)/'1. Balance General'!F18)*100
A19: Instrumentos financieros | B19: =(('1. Balance General'!C19-'1. Balance General'!B19)/'1. Balance General'!B19)*100 | C19: =(('1. Balance General'!D19-'1. Balance General'!C19)/'1. Balance General'!C19)*100 | D19: =(('1. Balance General'!E19-'1. Balance General'!D19)/'1. Balance General'!D19)*100 | E19: =(('1. Balance General'!F19-'1. Balance General'!E19)/'1. Balance General'!E19)*100 | F19: =(('1. Balance General'!G19-'1. Balance General'!F19)/'1. Balance General'!F19)*100
A20: Activos por impuestos | B20: =(('1. Balance General'!C20-'1. Balance General'!B20)/'1. Balance General'!B20)*100 | C20: =(('1. Balance General'!D20-'1. Balance General'!C20)/'1. Balance General'!C20)*100 | D20: =(('1. Balance General'!E20-'1. Balance General'!D20)/'1. Balance General'!D20)*100 | E20: =(('1. Balance General'!F20-'1. Balance General'!E20)/'1. Balance General'!E20)*100 | F20: =(('1. Balance General'!G20-'1. Balance General'!F20)/'1. Balance General'!F20)*100
A21: Otros activos | B21: =(('1. Balance General'!C21-'1. Balance General'!B21)/'1. Balance General'!B21)*100 | C21: =(('1. Balance General'!D21-'1. Balance General'!C21)/'1. Balance General'!C21)*100 | D21: =(('1. Balance General'!E21-'1. Balance General'!D21)/'1. Balance General'!D21)*100 | E21: =(('1. Balance General'!F21-'1. Balance General'!E21)/'1. Balance General'!E21)*100 | F21: =(('1. Balance General'!G21-'1. Balance General'!F21)/'1. Balance General'!F21)*100
A22: Operaciones con derivados | B22: =(('1. Balance General'!C22-'1. Balance General'!B22)/'1. Balance General'!B22)*100 | C22: =(('1. Balance General'!D22-'1. Balance General'!C22)/'1. Balance General'!C22)*100 | D22: =(('1. Balance General'!E22-'1. Balance General'!D22)/'1. Balance General'!D22)*100 | E22: =(('1. Balance General'!F22-'1. Balance General'!E22)/'1. Balance General'!E22)*100 | F22: =(('1. Balance General'!G22-'1. Balance General'!F22)/'1. Balance General'!F22)*100
A23: Efectivo restringido | B23: =(('1. Balance General'!C23-'1. Balance General'!B23)/'1. Balance General'!B23)*100 | C23: =(('1. Balance General'!D23-'1. Balance General'!C23)/'1. Balance General'!C23)*100 | D23: =(('1. Balance General'!E23-'1. Balance General'!D23)/'1. Balance General'!D23)*100 | E23: =(('1. Balance General'!F23-'1. Balance General'!E23)/'1. Balance General'!E23)*100 | F23: =(('1. Balance General'!G23-'1. Balance General'!F23)/'1. Balance General'!F23)*100
A24: Efectivo y equivalentes de efectivo | B24: =(('1. Balance General'!C24-'1. Balance General'!B24)/'1. Balance General'!B24)*100 | C24: =(('1. Balance General'!D24-'1. Balance General'!C24)/'1. Balance General'!C24)*100 | D24: =(('1. Balance General'!E24-'1. Balance General'!D24)/'1. Balance General'!D24)*100 | E24: =(('1. Balance General'!F24-'1. Balance General'!E24)/'1. Balance General'!E24)*100 | F24: =(('1. Balance General'!G24-'1. Balance General'!F24)/'1. Balance General'!F24)*100
A25: Total Activos Corrientes | B25: =(('1. Balance General'!C25-'1. Balance General'!B25)/'1. Balance General'!B25)*100 | C25: =(('1. Balance General'!D25-'1. Balance General'!C25)/'1. Balance General'!C25)*100 | D25: =(('1. Balance General'!E25-'1. Balance General'!D25)/'1. Balance General'!D25)*100 | E25: =(('1. Balance General'!F25-'1. Balance General'!E25)/'1. Balance General'!E25)*100 | F25: =(('1. Balance General'!G25-'1. Balance General'!F25)/'1. Balance General'!F25)*100
A27: TOTAL ACTIVOS | B27: =(('1. Balance General'!C27-'1. Balance General'!B27)/'1. Balance General'!B27)*100 | C27: =(('1. Balance General'!D27-'1. Balance General'!C27)/'1. Balance General'!C27)*100 | D27: =(('1. Balance General'!E27-'1. Balance General'!D27)/'1. Balance General'!D27)*100 | E27: =(('1. Balance General'!F27-'1. Balance General'!E27)/'1. Balance General'!E27)*100 | F27: =(('1. Balance General'!G27-'1. Balance General'!F27)/'1. Balance General'!F27)*100
A29: PATRIMONIO
A30: Capital | B30: =(('1. Balance General'!C30-'1. Balance General'!B30)/'1. Balance General'!B30)*100 | C30: =(('1. Balance General'!D30-'1. Balance General'!C30)/'1. Balance General'!C30)*100 | D30: =(('1. Balance General'!E30-'1. Balance General'!D30)/'1. Balance General'!D30)*100 | E30: =(('1. Balance General'!F30-'1. Balance General'!E30)/'1. Balance General'!E30)*100 | F30: =(('1. Balance General'!G30-'1. Balance General'!F30)/'1. Balance General'!F30)*100
A31: Reservas | B31: =(('1. Balance General'!C31-'1. Balance General'!B31)/'1. Balance General'!B31)*100 | C31: =(('1. Balance General'!D31-'1. Balance General'!C31)/'1. Balance General'!C31)*100 | D31: =(('1. Balance General'!E31-'1. Balance General'!D31)/'1. Balance General'!D31)*100 | E31: =(('1. Balance General'!F31-'1. Balance General'!E31)/'1. Balance General'!E31)*100 | F31: =(('1. Balance General'!G31-'1. Balance General'!F31)/'1. Balance General'!F31)*100
A32: Superávit de capital | B32: =(('1. Balance General'!C32-'1. Balance General'!B32)/'1. Balance General'!B32)*100 | C32: =(('1. Balance General'!D32-'1. Balance General'!C32)/'1. Balance General'!C32)*100 | D32: =(('1. Balance General'!E32-'1. Balance General'!D32)/'1. Balance General'!D32)*100 | E32: =(('1. Balance General'!F32-'1. Balance General'!E32)/'1. Balance General'!E32)*100 | F32: =(('1. Balance General'!G32-'1. Balance General'!F32)/'1. Balance General'!F32)*100
A33: Ganancias retenidas | B33: =(('1. Balance General'!C33-'1. Balance General'!B33)/'1. Balance General'!B33)*100 | C33: =(('1. Balance General'!D33-'1. Balance General'!C33)/'1. Balance General'!C33)*100 | D33: =(('1. Balance General'!E33-'1. Balance General'!D33)/'1. Balance General'!D33)*100 | E33: =(('1. Balance General'!F33-'1. Balance General'!E33)/'1. Balance General'!E33)*100 | F33: =(('1. Balance General'!G33-'1. Balance General'!F33)/'1. Balance General'!F33)*100
A34: Otro resultado integral | B34: =(('1. Balance General'!C34-'1. Balance General'!B34)/'1. Balance General'!B34)*100 | C34: =(('1. Balance General'!D34-'1. Balance General'!C34)/'1. Balance General'!C34)*100 | D34: =(('1. Balance General'!E34-'1. Balance General'!D34)/'1. Balance General'!D34)*100 | E34: =(('1. Balance General'!F34-'1. Balance General'!E34)/'1. Balance General'!E34)*100 | F34: =(('1. Balance General'!G34-'1. Balance General'!F34)/'1. Balance General'!F34)*100
A35: Resultado integral total periodo (Utilidad Neta) | B35: =(('1. Balance General'!C35-'1. Balance General'!B35)/'1. Balance General'!B35)*100 | C35: =(('1. Balance General'!D35-'1. Balance General'!C35)/'1. Balance General'!C35)*100 | D35: =(('1. Balance General'!E35-'1. Balance General'!D35)/'1. Balance General'!D35)*100 | E35: =(('1. Balance General'!F35-'1. Balance General'!E35)/'1. Balance General'!E35)*100 | F35: =(('1. Balance General'!G35-'1. Balance General'!F35)/'1. Balance General'!F35)*100
A36: Total Patrimonio de los Accionistas | B36: =(('1. Balance General'!C36-'1. Balance General'!B36)/'1. Balance General'!B36)*100 | C36: =(('1. Balance General'!D36-'1. Balance General'!C36)/'1. Balance General'!C36)*100 | D36: =(('1. Balance General'!E36-'1. Balance General'!D36)/'1. Balance General'!D36)*100 | E36: =(('1. Balance General'!F36-'1. Balance General'!E36)/'1. Balance General'!E36)*100 | F36: =(('1. Balance General'!G36-'1. Balance General'!F36)/'1. Balance General'!F36)*100
A38: PASIVOS NO CORRIENTES
A39: Operaciones de financiamiento | B39: =(('1. Balance General'!C39-'1. Balance General'!B39)/'1. Balance General'!B39)*100 | C39: =(('1. Balance General'!D39-'1. Balance General'!C39)/'1. Balance General'!C39)*100 | D39: =(('1. Balance General'!E39-'1. Balance General'!D39)/'1. Balance General'!D39)*100 | E39: =(('1. Balance General'!F39-'1. Balance General'!E39)/'1. Balance General'!E39)*100 | F39: =(('1. Balance General'!G39-'1. Balance General'!F39)/'1. Balance General'!F39)*100
A40: Obligaciones con vinculados | B40: =(('1. Balance General'!C40-'1. Balance General'!B40)/'1. Balance General'!B40)*100 | C40: =(('1. Balance General'!D40-'1. Balance General'!C40)/'1. Balance General'!C40)*100 | D40: =(('1. Balance General'!E40-'1. Balance General'!D40)/'1. Balance General'!D40)*100 | E40: =(('1. Balance General'!F40-'1. Balance General'!E40)/'1. Balance General'!E40)*100 | F40: =(('1. Balance General'!G40-'1. Balance General'!F40)/'1. Balance General'!F40)*100
A41: Operaciones con derivados | B41: =(('1. Balance General'!C41-'1. Balance General'!B41)/'1. Balance General'!B41)*100 | C41: =(('1. Balance General'!D41-'1. Balance General'!C41)/'1. Balance General'!C41)*100 | D41: =(('1. Balance General'!E41-'1. Balance General'!D41)/'1. Balance General'!D41)*100 | E41: =(('1. Balance General'!F41-'1. Balance General'!E41)/'1. Balance General'!E41)*100 | F41: =(('1. Balance General'!G41-'1. Balance General'!F41)/'1. Balance General'!F41)*100
A42: Impuestos, contribuciones y tasas | B42: =(('1. Balance General'!C42-'1. Balance General'!B42)/'1. Balance General'!B42)*100 | C42: =(('1. Balance General'!D42-'1. Balance General'!C42)/'1. Balance General'!C42)*100 | D42: =(('1. Balance General'!E42-'1. Balance General'!D42)/'1. Balance General'!D42)*100 | E42: =(('1. Balance General'!F42-'1. Balance General'!E42)/'1. Balance General'!E42)*100 | F42: =(('1. Balance General'!G42-'1. Balance General'!F42)/'1. Balance General'!F42)*100
A43: Beneficios a empleados | B43: =(('1. Balance General'!C43-'1. Balance General'!B43)/'1. Balance General'!B43)*100 | C43: =(('1. Balance General'!D43-'1. Balance General'!C43)/'1. Balance General'!C43)*100 | D43: =(('1. Balance General'!E43-'1. Balance General'!D43)/'1. Balance General'!D43)*100 | E43: =(('1. Balance General'!F43-'1. Balance General'!E43)/'1. Balance General'!E43)*100 | F43: =(('1. Balance General'!G43-'1. Balance General'!F43)/'1. Balance General'!F43)*100
A44: Provisiones | B44: =(('1. Balance General'!C44-'1. Balance General'!B44)/'1. Balance General'!B44)*100 | C44: =(('1. Balance General'!D44-'1. Balance General'!C44)/'1. Balance General'!C44)*100 | D44: =(('1. Balance General'!E44-'1. Balance General'!D44)/'1. Balance General'!D44)*100 | E44: =(('1. Balance General'!F44-'1. Balance General'!E44)/'1. Balance General'!E44)*100 | F44: =(('1. Balance General'!G44-'1. Balance General'!F44)/'1. Balance General'!F44)*100
A45: Cuentas por pagar | B45: =(('1. Balance General'!C45-'1. Balance General'!B45)/'1. Balance General'!B45)*100 | C45: =(('1. Balance General'!D45-'1. Balance General'!C45)/'1. Balance General'!C45)*100 | D45: =(('1. Balance General'!E45-'1. Balance General'!D45)/'1. Balance General'!D45)*100 | E45: =(('1. Balance General'!F45-'1. Balance General'!E45)/'1. Balance General'!E45)*100 | F45: =(('1. Balance General'!G45-'1. Balance General'!F45)/'1. Balance General'!F45)*100
...

Sheet 5. Análisis Vertical ER
A1: ISAGEN S.A. E.S.P.
A2: ANÁLISIS VERTICAL - ESTADO DE RESULTADOS
A3: Composición porcentual respecto a Ingresos (%)
A5: CONCEPTO | B5: 2020 | C5: 2021 | D5: 2022 | E5: 2023 | F5: 2024 | G5: 2025 (9m)
A6: Ingresos de contratos con clientes | B6: =('2. Estado de Resultados'!B6/'2. Estado de Resultados'!B6)*100 | C6: =('2. Estado de Resultados'!C6/'2. Estado de Resultados'!C6)*100 | D6: =('2. Estado de Resultados'!D6/'2. Estado de Resultados'!D6)*100 | E6: =('2. Estado de Resultados'!E6/'2. Estado de Resultados'!E6)*100 | F6: =('2. Estado de Resultados'!F6/'2. Estado de Resultados'!F6)*100 | G6: =('2. Estado de Resultados'!G6/'2. Estado de Resultados'!G6)*100
A7: Costo de ventas | B7: =('2. Estado de Resultados'!B7/'2. Estado de Resultados'!B6)*100 | C7: =('2. Estado de Resultados'!C7/'2. Estado de Resultados'!C6)*100 | D7: =('2. Estado de Resultados'!D7/'2. Estado de Resultados'!D6)*100 | E7: =('2. Estado de Resultados'!E7/'2. Estado de Resultados'!E6)*100 | F7: =('2. Estado de Resultados'!F7/'2. Estado de Resultados'!F6)*100 | G7: =('2. Estado de Resultados'!G7/'2. Estado de Resultados'!G6)*100
A8: Utilidad Bruta | B8: =('2. Estado de Resultados'!B8/'2. Estado de Resultados'!B6)*100 | C8: =('2. Estado de Resultados'!C8/'2. Estado de Resultados'!C6)*100 | D8: =('2. Estado de Resultados'!D8/'2. Estado de Resultados'!D6)*100 | E8: =('2. Estado de Resultados'!E8/'2. Estado de Resultados'!E6)*100 | F8: =('2. Estado de Resultados'!F8/'2. Estado de Resultados'!F6)*100 | G8: =('2. Estado de Resultados'!G8/'2. Estado de Resultados'!G6)*100
A9: Otros ingresos | B9: =('2. Estado de Resultados'!B9/'2. Estado de Resultados'!B6)*100 | C9: =('2. Estado de Resultados'!C9/'2. Estado de Resultados'!C6)*100 | D9: =('2. Estado de Resultados'!D9/'2. Estado de Resultados'!D6)*100 | E9: =('2. Estado de Resultados'!E9/'2. Estado de Resultados'!E6)*100 | F9: =('2. Estado de Resultados'!F9/'2. Estado de Resultados'!F6)*100 | G9: =('2. Estado de Resultados'!G9/'2. Estado de Resultados'!G6)*100
A10: Gastos de administración | B10: =('2. Estado de Resultados'!B10/'2. Estado de Resultados'!B6)*100 | C10: =('2. Estado de Resultados'!C10/'2. Estado de Resultados'!C6)*100 | D10: =('2. Estado de Resultados'!D10/'2. Estado de Resultados'!D6)*100 | E10: =('2. Estado de Resultados'!E10/'2. Estado de Resultados'!E6)*100 | F10: =('2. Estado de Resultados'!F10/'2. Estado de Resultados'!F6)*100 | G10: =('2. Estado de Resultados'!G10/'2. Estado de Resultados'!G6)*100
A11: Otros gastos | B11: =('2. Estado de Resultados'!B11/'2. Estado de Resultados'!B6)*100 | C11: =('2. Estado de Resultados'!C11/'2. Estado de Resultados'!C6)*100 | D11: =('2. Estado de Resultados'!D11/'2. Estado de Resultados'!D6)*100 | E11: =('2. Estado de Resultados'!E11/'2. Estado de Resultados'!E6)*100 | F11: =('2. Estado de Resultados'!F11/'2. Estado de Resultados'!F6)*100 | G11: =('2. Estado de Resultados'!G11/'2. Estado de Resultados'!G6)*100
A12: Ingresos financieros | B12: =('2. Estado de Resultados'!B12/'2. Estado de Resultados'!B6)*100 | C12: =('2. Estado de Resultados'!C12/'2. Estado de Resultados'!C6)*100 | D12: =('2. Estado de Resultados'!D12/'2. Estado de Resultados'!D6)*100 | E12: =('2. Estado de Resultados'!E12/'2. Estado de Resultados'!E6)*100 | F12: =('2. Estado de Resultados'!F12/'2. Estado de Resultados'!F6)*100 | G12: =('2. Estado de Resultados'!G12/'2. Estado de Resultados'!G6)*100
A13: Gastos financieros | B13: =('2. Estado de Resultados'!B13/'2. Estado de Resultados'!B6)*100 | C13: =('2. Estado de Resultados'!C13/'2. Estado de Resultados'!C6)*100 | D13: =('2. Estado de Resultados'!D13/'2. Estado de Resultados'!D6)*100 | E13: =('2. Estado de Resultados'!E13/'2. Estado de Resultados'!E6)*100 | F13: =('2. Estado de Resultados'!F13/'2. Estado de Resultados'!F6)*100 | G13: =('2. Estado de Resultados'!G13/'2. Estado de Resultados'!G6)*100
A14: Diferencia en cambio, neta | B14: =('2. Estado de Resultados'!B14/'2. Estado de Resultados'!B6)*100 | C14: =('2. Estado de Resultados'!C14/'2. Estado de Resultados'!C6)*100 | D14: =('2. Estado de Resultados'!D14/'2. Estado de Resultados'!D6)*100 | E14: =('2. Estado de Resultados'!E14/'2. Estado de Resultados'!E6)*100 | F14: =('2. Estado de Resultados'!F14/'2. Estado de Resultados'!F6)*100 | G14: =('2. Estado de Resultados'!G14/'2. Estado de Resultados'!G6)*100
A15: Utilidad Antes de Impuestos | B15: =('2. Estado de Resultados'!B15/'2. Estado de Resultados'!B6)*100 | C15: =('2. Estado de Resultados'!C15/'2. Estado de Resultados'!C6)*100 | D15: =('2. Estado de Resultados'!D15/'2. Estado de Resultados'!D6)*100 | E15: =('2. Estado de Resultados'!E15/'2. Estado de Resultados'!E6)*100 | F15: =('2. Estado de Resultados'!F15/'2. Estado de Resultados'!F6)*100 | G15: =('2. Estado de Resultados'!G15/'2. Estado de Resultados'!G6)*100
A16: EBIT | B16: =('2. Estado de Resultados'!B16/'2. Estado de Resultados'!B6)*100 | C16: =('2. Estado de Resultados'!C16/'2. Estado de Resultados'!C6)*100 | D16: =('2. Estado de Resultados'!D16/'2. Estado de Resultados'!D6)*100 | E16: =('2. Estado de Resultados'!E16/'2. Estado de Resultados'!E6)*100 | F16: =('2. Estado de Resultados'!F16/'2. Estado de Resultados'!F6)*100 | G16: =('2. Estado de Resultados'!G16/'2. Estado de Resultados'!G6)*100
A17: Depreciación | B17: =('2. Estado de Resultados'!B17/'2. Estado de Resultados'!B6)*100 | C17: =('2. Estado de Resultados'!C17/'2. Estado de Resultados'!C6)*100 | D17: =('2. Estado de Resultados'!D17/'2. Estado de Resultados'!D6)*100 | E17: =('2. Estado de Resultados'!E17/'2. Estado de Resultados'!E6)*100 | F17: =('2. Estado de Resultados'!F17/'2. Estado de Resultados'!F6)*100 | G17: =('2. Estado de Resultados'!G17/'2. Estado de Resultados'!G6)*100
A18: Amortización | B18: =('2. Estado de Resultados'!B18/'2. Estado de Resultados'!B6)*100 | C18: =('2. Estado de Resultados'!C18/'2. Estado de Resultados'!C6)*100 | D18: =('2. Estado de Resultados'!D18/'2. Estado de Resultados'!D6)*100 | E18: =('2. Estado de Resultados'!E18/'2. Estado de Resultados'!E6)*100 | F18: =('2. Estado de Resultados'!F18/'2. Estado de Resultados'!F6)*100 | G18: =('2. Estado de Resultados'!G18/'2. Estado de Resultados'!G6)*100
A19: EBITDA | B19: =('2. Estado de Resultados'!B19/'2. Estado de Resultados'!B6)*100 | C19: =('2. Estado de Resultados'!C19/'2. Estado de Resultados'!C6)*100 | D19: =('2. Estado de Resultados'!D19/'2. Estado de Resultados'!D6)*100 | E19: =('2. Estado de Resultados'!E19/'2. Estado de Resultados'!E6)*100 | F19: =('2. Estado de Resultados'!F19/'2. Estado de Resultados'!F6)*100 | G19: =('2. Estado de Resultados'!G19/'2. Estado de Resultados'!G6)*100
A20: Impuesto de renta - Corriente | B20: =('2. Estado de Resultados'!B20/'2. Estado de Resultados'!B6)*100 | C20: =('2. Estado de Resultados'!C20/'2. Estado de Resultados'!C6)*100 | D20: =('2. Estado de Resultados'!D20/'2. Estado de Resultados'!D6)*100 | E20: =('2. Estado de Resultados'!E20/'2. Estado de Resultados'!E6)*100 | F20: =('2. Estado de Resultados'!F20/'2. Estado de Resultados'!F6)*100 | G20: =('2. Estado de Resultados'!G20/'2. Estado de Resultados'!G6)*100
A21: Impuesto de renta - Diferido | B21: =('2. Estado de Resultados'!B21/'2. Estado de Resultados'!B6)*100 | C21: =('2. Estado de Resultados'!C21/'2. Estado de Resultados'!C6)*100 | D21: =('2. Estado de Resultados'!D21/'2. Estado de Resultados'!D6)*100 | E21: =('2. Estado de Resultados'!E21/'2. Estado de Resultados'!E6)*100 | F21: =('2. Estado de Resultados'!F21/'2. Estado de Resultados'!F6)*100 | G21: =('2. Estado de Resultados'!G21/'2. Estado de Resultados'!G6)*100
A22: Utilidad Neta del Periodo | B22: =('2. Estado de Resultados'!B22/'2. Estado de Resultados'!B6)*100 | C22: =('2. Estado de Resultados'!C22/'2. Estado de Resultados'!C6)*100 | D22: =('2. Estado de Resultados'!D22/'2. Estado de Resultados'!D6)*100 | E22: =('2. Estado de Resultados'!E22/'2. Estado de Resultados'!E6)*100 | F22: =('2. Estado de Resultados'!F22/'2. Estado de Resultados'!F6)*100 | G22: =('2. Estado de Resultados'!G22/'2. Estado de Resultados'!G6)*100
A25: OTRO RESULTADO INTEGRAL (ORI)
A26: Ganancias actuariales (Beneficios definidos) | B26: =('2. Estado de Resultados'!B26/'2. Estado de Resultados'!B6)*100 | C26: =('2. Estado de Resultados'!C26/'2. Estado de Resultados'!C6)*100 | D26: =('2. Estado de Resultados'!D26/'2. Estado de Resultados'!D6)*100 | E26: =('2. Estado de Resultados'!E26/'2. Estado de Resultados'!E6)*100 | F26: =('2. Estado de Resultados'!F26/'2. Estado de Resultados'!F6)*100 | G26: =('2. Estado de Resultados'!G26/'2. Estado de Resultados'!G6)*100
A27: Coberturas flujo de efectivo | B27: =('2. Estado de Resultados'!B27/'2. Estado de Resultados'!B6)*100 | C27: =('2. Estado de Resultados'!C27/'2. Estado de Resultados'!C6)*100 | D27: =('2. Estado de Resultados'!D27/'2. Estado de Resultados'!D6)*100 | E27: =('2. Estado de Resultados'!E27/'2. Estado de Resultados'!E6)*100 | F27: =('2. Estado de Resultados'!F27/'2. Estado de Resultados'!F6)*100 | G27: =('2. Estado de Resultados'!G27/'2. Estado de Resultados'!G6)*100
A28: Total Otro Resultado Integral, neto | B28: =('2. Estado de Resultados'!B28/'2. Estado de Resultados'!B6)*100 | C28: =('2. Estado de Resultados'!C28/'2. Estado de Resultados'!C6)*100 | D28: =('2. Estado de Resultados'!D28/'2. Estado de Resultados'!D6)*100 | E28: =('2. Estado de Resultados'!E28/'2. Estado de Resultados'!E6)*100 | F28: =('2. Estado de Resultados'!F28/'2. Estado de Resultados'!F6)*100 | G28: =('2. Estado de Resultados'!G28/'2. Estado de Resultados'!G6)*100
A29: RESULTADO INTEGRAL TOTAL | B29: =('2. Estado de Resultados'!B29/'2. Estado de Resultados'!B6)*100 | C29: =('2. Estado de Resultados'!C29/'2. Estado de Resultados'!C6)*100 | D29: =('2. Estado de Resultados'!D29/'2. Estado de Resultados'!D6)*100 | E29: =('2. Estado de Resultados'!E29/'2. Estado de Resultados'!E6)*100 | F29: =('2. Estado de Resultados'!F29/'2. Estado de Resultados'!F6)*100 | G29: =('2. Estado de Resultados'!G29/'2. Estado de Resultados'!G6)*100
A31: Utilidad básica y diluida por acción ($) | B31: =('2. Estado de Resultados'!B31/'2. Estado de Resultados'!B6)*100 | C31: =('2. Estado de Resultados'!C31/'2. Estado de Resultados'!C6)*100 | D31: =('2. Estado de Resultados'!D31/'2. Estado de Resultados'!D6)*100 | E31: =('2. Estado de Resultados'!E31/'2. Estado de Resultados'!E6)*100 | F31: =('2. Estado de Resultados'!F31/'2. Estado de Resultados'!F6)*100 | G31: =('2. Estado de Resultados'!G31/'2. Estado de Resultados'!G6)*100

Sheet 6. Análisis Horizontal ER
A1: ISAGEN S.A. E.S.P.
A2: ANÁLISIS HORIZONTAL - ESTADO DE RESULTADOS
A3: Variación porcentual interanual (%)
A5: CONCEPTO | B5: 2020-2021 | C5: 2021-2022 | D5: 2022-2023 | E5: 2023-2024 | F5: 2024-2025
A6: Ingresos de contratos con clientes | B6: =(('2. Estado de Resultados'!C6-'2. Estado de Resultados'!B6)/'2. Estado de Resultados'!B6)*100 | C6: =(('2. Estado de Resultados'!D6-'2. Estado de Resultados'!C6)/'2. Estado de Resultados'!C6)*100 | D6: =(('2. Estado de Resultados'!E6-'2. Estado de Resultados'!D6)/'2. Estado de Resultados'!D6)*100 | E6: =(('2. Estado de Resultados'!F6-'2. Estado de Resultados'!E6)/'2. Estado de Resultados'!E6)*100 | F6: =(('2. Estado de Resultados'!G6-'2. Estado de Resultados'!F6)/'2. Estado de Resultados'!F6)*100
A7: Costo de ventas | B7: =(('2. Estado de Resultados'!C7-'2. Estado de Resultados'!B7)/'2. Estado de Resultados'!B7)*100 | C7: =(('2. Estado de Resultados'!D7-'2. Estado de Resultados'!C7)/'2. Estado de Resultados'!C7)*100 | D7: =(('2. Estado de Resultados'!E7-'2. Estado de Resultados'!D7)/'2. Estado de Resultados'!D7)*100 | E7: =(('2. Estado de Resultados'!F7-'2. Estado de Resultados'!E7)/'2. Estado de Resultados'!E7)*100 | F7: =(('2. Estado de Resultados'!G7-'2. Estado de Resultados'!F7)/'2. Estado de Resultados'!F7)*100
A8: Utilidad Bruta | B8: =(('2. Estado de Resultados'!C8-'2. Estado de Resultados'!B8)/'2. Estado de Resultados'!B8)*100 | C8: =(('2. Estado de Resultados'!D8-'2. Estado de Resultados'!C8)/'2. Estado de Resultados'!C8)*100 | D8: =(('2. Estado de Resultados'!E8-'2. Estado de Resultados'!D8)/'2. Estado de Resultados'!D8)*100 | E8: =(('2. Estado de Resultados'!F8-'2. Estado de Resultados'!E8)/'2. Estado de Resultados'!E8)*100 | F8: =(('2. Estado de Resultados'!G8-'2. Estado de Resultados'!F8)/'2. Estado de Resultados'!F8)*100
A9: Otros ingresos | B9: =(('2. Estado de Resultados'!C9-'2. Estado de Resultados'!B9)/'2. Estado de Resultados'!B9)*100 | C9: =(('2. Estado de Resultados'!D9-'2. Estado de Resultados'!C9)/'2. Estado de Resultados'!C9)*100 | D9: =(('2. Estado de Resultados'!E9-'2. Estado de Resultados'!D9)/'2. Estado de Resultados'!D9)*100 | E9: =(('2. Estado de Resultados'!F9-'2. Estado de Resultados'!E9)/'2. Estado de Resultados'!E9)*100 | F9: =(('2. Estado de Resultados'!G9-'2. Estado de Resultados'!F9)/'2. Estado de Resultados'!F9)*100
A10: Gastos de administración | B10: =(('2. Estado de Resultados'!C10-'2. Estado de Resultados'!B10)/'2. Estado de Resultados'!B10)*100 | C10: =(('2. Estado de Resultados'!D10-'2. Estado de Resultados'!C10)/'2. Estado de Resultados'!C10)*100 | D10: =(('2. Estado de Resultados'!E10-'2. Estado de Resultados'!D10)/'2. Estado de Resultados'!D10)*100 | E10: =(('2. Estado de Resultados'!F10-'2. Estado de Resultados'!E10)/'2. Estado de Resultados'!E10)*100 | F10: =(('2. Estado de Resultados'!G10-'2. Estado de Resultados'!F10)/'2. Estado de Resultados'!F10)*100
A11: Otros gastos | B11: =(('2. Estado de Resultados'!C11-'2. Estado de Resultados'!B11)/'2. Estado de Resultados'!B11)*100 | C11: =(('2. Estado de Resultados'!D11-'2. Estado de Resultados'!C11)/'2. Estado de Resultados'!C11)*100 | D11: =(('2. Estado de Resultados'!E11-'2. Estado de Resultados'!D11)/'2. Estado de Resultados'!D11)*100 | E11: =(('2. Estado de Resultados'!F11-'2. Estado de Resultados'!E11)/'2. Estado de Resultados'!E11)*100 | F11: =(('2. Estado de Resultados'!G11-'2. Estado de Resultados'!F11)/'2. Estado de Resultados'!F11)*100
A12: Ingresos financieros | B12: =(('2. Estado de Resultados'!C12-'2. Estado de Resultados'!B12)/'2. Estado de Resultados'!B12)*100 | C12: =(('2. Estado de Resultados'!D12-'2. Estado de Resultados'!C12)/'2. Estado de Resultados'!C12)*100 | D12: =(('2. Estado de Resultados'!E12-'2. Estado de Resultados'!D12)/'2. Estado de Resultados'!D12)*100 | E12: =(('2. Estado de Resultados'!F12-'2. Estado de Resultados'!E12)/'2. Estado de Resultados'!E12)*100 | F12: =(('2. Estado de Resultados'!G12-'2. Estado de Resultados'!F12)/'2. Estado de Resultados'!F12)*100
A13: Gastos financieros | B13: =(('2. Estado de Resultados'!C13-'2. Estado de Resultados'!B13)/'2. Estado de Resultados'!B13)*100 | C13: =(('2. Estado de Resultados'!D13-'2. Estado de Resultados'!C13)/'2. Estado de Resultados'!C13)*100 | D13: =(('2. Estado de Resultados'!E13-'2. Estado de Resultados'!D13)/'2. Estado de Resultados'!D13)*100 | E13: =(('2. Estado de Resultados'!F13-'2. Estado de Resultados'!E13)/'2. Estado de Resultados'!E13)*100 | F13: =(('2. Estado de Resultados'!G13-'2. Estado de Resultados'!F13)/'2. Estado de Resultados'!F13)*100
A14: Diferencia en cambio, neta | B14: =(('2. Estado de Resultados'!C14-'2. Estado de Resultados'!B14)/'2. Estado de Resultados'!B14)*100 | C14: =(('2. Estado de Resultados'!D14-'2. Estado de Resultados'!C14)/'2. Estado de Resultados'!C14)*100 | D14: =(('2. Estado de Resultados'!E14-'2. Estado de Resultados'!D14)/'2. Estado de Resultados'!D14)*100 | E14: =(('2. Estado de Resultados'!F14-'2. Estado de Resultados'!E14)/'2. Estado de Resultados'!E14)*100 | F14: =(('2. Estado de Resultados'!G14-'2. Estado de Resultados'!F14)/'2. Estado de Resultados'!F14)*100
A15: Utilidad Antes de Impuestos | B15: =(('2. Estado de Resultados'!C15-'2. Estado de Resultados'!B15)/'2. Estado de Resultados'!B15)*100 | C15: =(('2. Estado de Resultados'!D15-'2. Estado de Resultados'!C15)/'2. Estado de Resultados'!C15)*100 | D15: =(('2. Estado de Resultados'!E15-'2. Estado de Resultados'!D15)/'2. Estado de Resultados'!D15)*100 | E15: =(('2. Estado de Resultados'!F15-'2. Estado de Resultados'!E15)/'2. Estado de Resultados'!E15)*100 | F15: =(('2. Estado de Resultados'!G15-'2. Estado de Resultados'!F15)/'2. Estado de Resultados'!F15)*100
A16: EBIT | B16: =(('2. Estado de Resultados'!C16-'2. Estado de Resultados'!B16)/'2. Estado de Resultados'!B16)*100 | C16: =(('2. Estado de Resultados'!D16-'2. Estado de Resultados'!C16)/'2. Estado de Resultados'!C16)*100 | D16: =(('2. Estado de Resultados'!E16-'2. Estado de Resultados'!D16)/'2. Estado de Resultados'!D16)*100 | E16: =(('2. Estado de Resultados'!F16-'2. Estado de Resultados'!E16)/'2. Estado de Resultados'!E16)*100 | F16: =(('2. Estado de Resultados'!G16-'2. Estado de Resultados'!F16)/'2. Estado de Resultados'!F16)*100
A17: Depreciación | B17: =(('2. Estado de Resultados'!C17-'2. Estado de Resultados'!B17)/'2. Estado de Resultados'!B17)*100 | C17: =(('2. Estado de Resultados'!D17-'2. Estado de Resultados'!C17)/'2. Estado de Resultados'!C17)*100 | D17: =(('2. Estado de Resultados'!E17-'2. Estado de Resultados'!D17)/'2. Estado de Resultados'!D17)*100 | E17: =(('2. Estado de Resultados'!F17-'2. Estado de Resultados'!E17)/'2. Estado de Resultados'!E17)*100 | F17: =(('2. Estado de Resultados'!G17-'2. Estado de Resultados'!F17)/'2. Estado de Resultados'!F17)*100
... A22: Utilidad Neta del Periodo | B22: =(('2. Estado de Resultados'!C22-'2. Estado de Resultados'!B22)/'2. Estado de Resultados'!B22)*100 | C22: =(('2. Estado de Resultados'!D22-'2. Estado de Resultados'!C22)/'2. Estado de Resultados'!C22)*100 | D22: =(('2. Estado de Resultados'!E22-'2. Estado de Resultados'!D22)/'2. Estado de Resultados'!D22)*100 | E22: =(('2. Estado de Resultados'!F22-'2. Estado de Resultados'!E22)/'2. Estado de Resultados'!E22)*100 | F22: =(('2. Estado de Resultados'!G22-'2. Estado de Resultados'!F22)/'2. Estado de Resultados'!F22)*100
A25: OTRO RESULTADO INTEGRAL (ORI)
A26: Ganancias actuariales (Beneficios definidos) | B26: =(('2. Estado de Resultados'!C26-'2. Estado de Resultados'!B26)/'2. Estado de Resultados'!B26)*100 | C26: =(('2. Estado de Resultados'!D26-'2. Estado de Resultados'!C26)/'2. Estado de Resultados'!C26)*100 | D26: =(('2. Estado de Resultados'!E26-'2. Estado de Resultados'!D26)/'2. Estado de Resultados'!D26)*100 | E26: =(('2. Estado de Resultados'!F26-'2. Estado de Resultados'!E26)/'2. Estado de Resultados'!E26)*100 | F26: =(('2. Estado de Resultados'!G26-'2. Estado de Resultados'!F26)/'2. Estado de Resultados'!F26)*100
A27: Coberturas flujo de efectivo | B27: =(('2. Estado de Resultados'!C27-'2. Estado de Resultados'!B27)/'2. Estado de Resultados'!B27)*100 | C27: =(('2. Estado de Resultados'!D27-'2. Estado de Resultados'!C27)/'2. Estado de Resultados'!C27)*100 | D27: =(('2. Estado de Resultados'!E27-'2. Estado de Resultados'!D27)/'2. Estado de Resultados'!D27)*100 | E27: =(('2. Estado de Resultados'!F27-'2. Estado de Resultados'!E27)/'2. Estado de Resultados'!E27)*100 | F27: =(('2. Estado de Resultados'!G27-'2. Estado de Resultados'!F27)/'2. Estado de Resultados'!F27)*100
A28: Total Otro Resultado Integral, neto | B28: =(('2. Estado de Resultados'!C28-'2. Estado de Resultados'!B28)/'2. Estado de Resultados'!B28)*100 | C28: =(('2. Estado de Resultados'!D28-'2. Estado de Resultados'!C28)/'2. Estado de Resultados'!C28)*100 | D28: =(('2. Estado de Resultados'!E28-'2. Estado de Resultados'!D28)/'2. Estado de Resultados'!D28)*100 | E28: =(('2. Estado de Resultados'!F28-'2. Estado de Resultados'!E28)/'2. Estado de Resultados'!E28)*100 | F28: =(('2. Estado de Resultados'!G28-'2. Estado de Resultados'!F28)/'2. Estado de Resultados'!F28)*100
A29: RESULTADO INTEGRAL TOTAL | B29: =(('2. Estado de Resultados'!C29-'2. Estado de Resultados'!B29)/'2. Estado de Resultados'!B29)*100 | C29: =(('2. Estado de Resultados'!D29-'2. Estado de Resultados'!C29)/'2. Estado de Resultados'!C29)*100 | D29: =(('2. Estado de Resultados'!E29-'2. Estado de Resultados'!D29)/'2. Estado de Resultados'!D29)*100 | E29: =(('2. Estado de Resultados'!F29-'2. Estado de Resultados'!E29)/'2. Estado de Resultados'!E29)*100 | F29: =(('2. Estado de Resultados'!G29-'2. Estado de Resultados'!F29)/'2. Estado de Resultados'!F29)*100
A31: Utilidad básica y diluida por acción ($) | B31: =(('2. Estado de Resultados'!C31-'2. Estado de Resultados'!B31)/'2. Estado de Resultados'!B31)*100 | C31: =(('2. Estado de Resultados'!D31-'2. Estado de Resultados'!C31)/'2. Estado de Resultados'!C31)*100 | D31: =(('2. Estado de Resultados'!E31-'2. Estado de Resultados'!D31)/'2. Estado de Resultados'!D31)*100 | E31: =(('2. Estado de Resultados'!F31-'2. Estado de Resultados'!E31)/'2. Estado de Resultados'!E31)*100 | F31: =(('2. Estado de Resultados'!G31-'2. Estado de Resultados'!F31)/'2. Estado de Resultados'!F31)*100

Sheet 7. Indicadores Financieros
A1: ISAGEN S.A. E.S.P.
A2: INDICADORES FINANCIEROS CLAVE
A3: Valores en millones de pesos colombianos (COP)
A5: INDICADOR | B5: 2020 | C5: 2021 | D5: 2022 | E5: 2023 | F5: 2024 | G5: 2025 (Sep)
A6: EBITDA | B6: ='2. Estado de Resultados'!B19 | C6: ='2. Estado de Resultados'!C19 | D6: ='2. Estado de Resultados'!D19 | E6: ='2. Estado de Resultados'!E19 | F6: ='2. Estado de Resultados'!F19 | G6: ='2. Estado de Resultados'!G19
A8: CAPITAL DE TRABAJO NETO OPERATIVO (KTNO)
A9: Activos Corrientes Operativos | B9: ='1. Balance General'!B25-'1. Balance General'!B24-'1. Balance General'!B23 | C9: ='1. Balance General'!C25-'1. Balance General'!C24-'1. Balance General'!C23 | D9: ='1. Balance General'!D25-'1. Balance General'!D24-'1. Balance General'!D23 | E9: ='1. Balance General'!E25-'1. Balance General'!E24-'1. Balance General'!E23 | F9: ='1. Balance General'!F25-'1. Balance General'!F24-'1. Balance General'!F23 | G9: ='1. Balance General'!G25-'1. Balance General'!G24-'1. Balance General'!G23
A10: Pasivos Corrientes Operativos | B10: ='1. Balance General'!B57-'1. Balance General'!B49-'1. Balance General'!B52-'1. Balance General'!B51 | C10: ='1. Balance General'!C57-'1. Balance General'!C49-'1. Balance General'!C52-'1. Balance General'!C51 | D10: ='1. Balance General'!D57-'1. Balance General'!D49-'1. Balance General'!D52-'1. Balance General'!D51 | E10: ='1. Balance General'!E57-'1. Balance General'!E49-'1. Balance General'!E52-'1. Balance General'!E51 | F10: ='1. Balance General'!F57-'1. Balance General'!F49-'1. Balance General'!F52-'1. Balance General'!F51 | G10: ='1. Balance General'!G57-'1. Balance General'!G49-'1. Balance General'!G52-'1. Balance General'!G51
A11: KTNO | B11: =B9-B10 | C11: =C9-C10 | D11: =D9-D10 | E11: =E9-E10 | F11: =F9-F10 | G11: =G9-G10
A13: ΔKTNO (Variación del KTNO) | B13: N/A | C13: =C11-B11 | D13: =D11-C11 | E13: =E11-D11 | F13: =F11-E11 | G13: =G11-F11
